Workbook

Sheet Dashboard
A1: YOUR OLD YOUTUBE CHANNEL — PERFORMANCE ASSESSMENT
A2: Data: YouTube Studio export (lifetime, Jul 2022 – Oct 2026) · 72 uploads · Built 19 Oct 2026. Start here, then follow the tabs left → right.
A4: CHANNEL AT A GLANCE (lifetime)
A5: Total views | C5: Watch time (hrs) | E5: Subscribers gained | G5: Thumbnail impressions | I5: Thumbnail CTR | K5: Videos uploaded
A6: 29044 | C6: 84.2106 | E6: 51 | G6: 231269 | I6: 0.0544 | K6: =COUNTA('All Videos'!$B$5:$B$76) -> 72
A7: Channel total from Studio | C7: Channel total from Studio | E7: Channel total from Studio | G7: Channel total from Studio | I7: Channel total. Reported gaming avg ≈ 8.5% (Focus Digital) | K7: Counted from All Videos
A9: Subs per 1,000 views | C9: Median views per video | E9: Share of views from #1 video | G9: Avg watch per view (sec) | I9: Videos with 1,000+ views | K9: Videos under 200 views
A10: =E6/A6*1000 -> 1.7559565 | C10: =MEDIAN('All Videos'!$J$5:$J$76) -> 129 | E10: =MAX('All Videos'!$J$5:$J$76)/SUM('All Videos'!$J$5:$J$76) -> 0.33009969 | G10: =C6*3600/A6 -> 10.437893 | I10: =COUNTIF('All Videos'!$U$5:$U$76,"HIT") -> 6 | K10: =COUNTIF('All Videos'!$U$5:$U$76,"LOW") -> 47
A11: Views → fans conversion | C11: Typical video (not skewed by 1 viral hit) | E11: Dependence on one viral clip | G11: Watch time ÷ views | I11: "HIT" tier | K11: "LOW" tier
A13: Red numbers = biggest weak spots · Blue = exported totals · Navy = calculated
A15: THE 6 THINGS THAT MATTER MOST
A16: STRENGTH | C16: You found a format that works: cricket-game "Umpire / Out-or-not-out?" drama. 26 such clips = about two-thirds of all video views, ~4x the views per video of your other cricket clips.
A17: STRENGTH | C17: Your long-form packaging works: long videos earned 7–16% thumbnail CTR on small samples, at or above the ~8.5% average reported for gaming. People WANT to click.
A18: WEAKNESS | C18: Views only happen while you upload. Bursts (Dec 22, Mar 24, Nov 25, Jun 26) are followed by near-zero months because uploads stop. No back-catalogue engine.
A19: WEAKNESS | C19: Viewers don't become fans: ~1.8 subs per 1,000 views and ~10 seconds watched per view. 3–5 sec clips with no voice, face, series name or call-to-action give nobody a reason to follow YOU.
A20: WEAKNESS | C20: Titles hurt you: hashtag-stuffed titles (often irrelevant: #minecraft, #nfl, #valve on cricket) averaged less than a quarter of the views of clean titles (~125 vs ~555). Profanity titles ("F***ing", "MOFOS") limit ads and reach.
A21: OPPORTUNITY | C21: Cricket is India's biggest streaming category (T20 WC 2026 ≈ 246M, IPL 2026 ≈ 228M viewers; Ormax). Real Cricket hit a record 3.5M downloads in Apr 2026. Ride the cricket calendar with a recognisable series and a real voice.
A23: TOP 5 VIDEOS (live from All Videos)
A24: # | B24: Title | G24: Views | H24: Length (s) | I24: Avg % viewed | J24: Subs | K24: Angle
A25: 1 | B25: ='All Videos'!C5 -> Umpire Caught Cheating In Cricket 07 | G25: ='All Videos'!J5 -> 8609 | H25: ='All Videos'!I5 -> 3 | I25: ='All Videos'!P5 -> 0.99311883 | J25: ='All Videos'!L5 -> 6 | K25: ='All Videos'!G5 -> Umpire / decision drama
A26: 2 | B26: ='All Videos'!C6 -> How Is That NOT OUT?! 😳 | G26: ='All Videos'!J6 -> 2006 | H26: ='All Videos'!I6 -> 5 | I26: ='All Videos'!P6 -> 0.43128215 | J26: ='All Videos'!L6 -> 1 | K26: ='All Videos'!G6 -> Umpire / decision drama
A27: 3 | B27: ='All Videos'!C7 -> counter strike condition zero#counterstrike#counterstrikeconditionzero#shorts | G27: ='All Videos'!J7 -> 1603 | H27: ='All Videos'!I7 -> 57 | I27: ='All Videos'!P7 -> 0.30577798 | J27: ='All Videos'!L7 -> 0 | K27: ='All Videos'!G7 -> Gameplay clip (other game)
A28: 4 | B28: ='All Videos'!C8 -> The Calm Before LBW | G28: ='All Videos'!J8 -> 1585 | H28: ='All Videos'!I8 -> 11 | I28: ='All Videos'!P8 -> 0.28265214 | J28: ='All Videos'!L8 -> 0 | K28: ='All Videos'!G8 -> Umpire / decision drama
A29: 5 | B29: ='All Videos'!C9 -> BLIND UMPIRE | G29: ='All Videos'!J9 -> 1523 | H29: ='All Videos'!I9 -> 4 | I29: ='All Videos'!P9 -> 0.66764281 | J29: ='All Videos'!L9 -> 0 | K29: ='All Videos'!G9 -> Umpire / decision drama
A31: CHARTS
A48: TAB GUIDE → All Videos (every stat) · Monthly Trend · Top 5 Trajectories · Breakdowns · Deep Analysis · Market Research 2026 · Action Plan · Content Playbook · Glossary & Missing Data

Sheet All Videos
A1: ALL VIDEOS — every upload, ranked by views
A2: Raw stats from your YouTube Studio export (blue = exported data) + calculated columns (black). Use the filter arrows on row 4 to slice by game, format, angle, tier.
A4: Rank | B4: Video ID | C4: Title | D4: Published | E4: Year | F4: Game | G4: Content angle | H4: Format | I4: Length (sec) | J4: Views | K4: Watch time (hrs) | L4: Subs gained | M4: Thumbnail impressions | N4: Thumbnail CTR | O4: Avg view duration (sec) | P4: Avg % viewed (est.) | Q4: Subs per 1k views | R4: # hashtags in title | S4: Title style | T4: Length bucket | U4: Performance tier
A5: 1 | B5: 9srtvMvNdHE | C5: Umpire Caught Cheating In Cricket 07 | D5: 45248 | E5: =YEAR(D5) -> 2023 | F5: Cricket 07 | G5: Umpire / decision drama | H5: Short | I5: 3 | J5: 8609 | K5: 7.1248 | L5: 6 | M5: 91238 | N5: 0.0829 | O5: =IF(OR(J5="",J5=0),"",K5*3600/J5) -> 2.9793565 | P5: =IF(OR(O5="",I5=0),"",O5/I5) -> 0.99311883 | Q5: =IF(OR(J5="",J5=0),"",L5/J5*1000) -> 0.69694506 | R5: 0 | S5: =IF(R5=0,"Clean title",IF(R5<=3,"Light hashtags","Hashtag-stuffed")) -> Clean title | T5: =IF(I5<=10,"0–10 sec",IF(I5<=60,"11–60 sec",IF(I5<=180,"61–180 sec","3 min +"))) -> 0–10 sec | U5: =IF(J5="","NO DATA",IF(J5>=1000,"HIT",IF(J5>=200,"OK","LOW"))) -> HIT
A6: 2 | B6: uhVoNiY4MBg | C6: How Is That NOT OUT?! 😳 | D6: 45989 | E6: =YEAR(D6) -> 2025 | F6: Cricket 07 | G6: Umpire / decision drama | H6: Short | I6: 5 | J6: 2006 | K6: 1.2016 | L6: 1 | M6: 80 | N6: 0.0125 | O6: =IF(OR(J6="",J6=0),"",K6*3600/J6) -> 2.1564108 | P6: =IF(OR(O6="",I6=0),"",O6/I6) -> 0.43128215 | Q6: =IF(OR(J6="",J6=0),"",L6/J6*1000) -> 0.49850449 | R6: 0 | S6: =IF(R6=0,"Clean title",IF(R6<=3,"Light hashtags","Hashtag-stuffed")) -> Clean title | T6: =IF(I6<=10,"0–10 sec",IF(I6<=60,"11–60 sec",IF(I6<=180,"61–180 sec","3 min +"))) -> 0–10 sec | U6: =IF(J6="","NO DATA",IF(J6>=1000,"HIT",IF(J6>=200,"OK","LOW"))) -> HIT
A7: 3 | B7: RAfXFnj14Vo | C7: counter strike condition zero#counterstrike#counterstrikeconditionzero#shorts | D7: 44901 | E7: =YEAR(D7) -> 2022 | F7: Counter-Strike CZ | G7: Gameplay clip (other game) | H7: Short | I7: 57 | J7: 1603 | K7: 7.7609 | L7: 0 | M7: 2171 | N7: 0.0088 | O7: =IF(OR(J7="",J7=0),"",K7*3600/J7) -> 17.429345 | P7: =IF(OR(O7="",I7=0),"",O7/I7) -> 0.30577798 | Q7: =IF(OR(J7="",J7=0),"",L7/J7*1000) -> 0 | R7: 3 | S7: =IF(R7=0,"Clean title",IF(R7<=3,"Light hashtags","Hashtag-stuffed")) -> Light hashtags | T7: =IF(I7<=10,"0–10 sec",IF(I7<=60,"11–60 sec",IF(I7<=180,"61–180 sec","3 min +"))) -> 11–60 sec | U7: =IF(J7="","NO DATA",IF(J7>=1000,"HIT",IF(J7>=200,"OK","LOW"))) -> HIT
A8: 4 | B8: ME765cmAuUY | C8: The Calm Before LBW | D8: 45970 | E8: =YEAR(D8) -> 2025 | F8: Cricket 07 | G8: Umpire / decision drama | H8: Short | I8: 11 | J8: 1585 | K8: 1.3689 | L8: 0 | M8: 25 | N8: 0 | O8: =IF(OR(J8="",J8=0),"",K8*3600/J8) -> 3.1091735 | P8: =IF(OR(O8="",I8=0),"",O8/I8) -> 0.28265214 | Q8: =IF(OR(J8="",J8=0),"",L8/J8*1000) -> 0 | R8: 0 | S8: =IF(R8=0,"Clean title",IF(R8<=3,"Light hashtags","Hashtag-stuffed")) -> Clean title | T8: =IF(I8<=10,"0–10 sec",IF(I8<=60,"11–60 sec",IF(I8<=180,"61–180 sec","3 min +"))) -> 11–60 sec | U8: =IF(J8="","NO DATA",IF(J8>=1000,"HIT",IF(J8>=200,"OK","LOW"))) -> HIT
A9: 5 | B9: JO21rkfLXIU | C9: BLIND UMPIRE | D9: 46187 | E9: =YEAR(D9) -> 2026 | F9: Cricket 07 | G9: Umpire / decision drama | H9: Short | I9: 4 | J9: 1523 | K9: 1.1298 | L9: 0 | M9: 116 | N9: 0 | O9: =IF(OR(J9="",J9=0),"",K9*3600/J9) -> 2.6705712 | P9: =IF(OR(O9="",I9=0),"",O9/I9) -> 0.66764281 | Q9: =IF(OR(J9="",J9=0),"",L9/J9*1000) -> 0 | R9: 0 | S9: =IF(R9=0,"Clean title",IF(R9<=3,"Light hashtags","Hashtag-stuffed")) -> Clean title | T9: =IF(I9<=10,"0–10 sec",IF(I9<=60,"11–60 sec",IF(I9<=180,"61–180 sec","3 min +"))) -> 0–10 sec | U9: =IF(J9="","NO DATA",IF(J9>=1000,"HIT",IF(J9>=200,"OK","LOW"))) -> HIT
A10: 6 | B10: QHivJyx-aYs | C10: Plum LBW As F***ing Hell #1 | D10: 46151 | E10: =YEAR(D10) -> 2026 | F10: Cricket 07 | G10: Umpire / decision drama | H10: Short | I10: 4 | J10: 1331 | K10: 1.5029 | L10: 1 | M10: 34946 | N10: 0.036 | O10: =IF(OR(J10="",J10=0),"",K10*3600/J10) -> 4.0649437 | P10: =IF(OR(O10="",I10=0),"",O10/I10) -> 1.0162359 | Q10: =IF(OR(J10="",J10=0),"",L10/J10*1000) -> 0.7513148 | R10: 1 | S10: =IF(R10=0,"Clean title",IF(R10<=3,"Light hashtags","Hashtag-stuffed")) -> Light hashtags | T10: =IF(I10<=10,"0–10 sec",IF(I10<=60,"11–60 sec",IF(I10<=180,"61–180 sec","3 min +"))) -> 0–10 sec | U10: =IF(J10="","NO DATA",IF(J10>=1000,"HIT",IF(J10>=200,"OK","LOW"))) -> HIT
A11: 7 | B11: iZzVJQU-c_g | C11: CRICKET 07 2011 THE TENTH WORLD WAR! | D11: 44817 | E11: =YEAR(D11) -> 2022 | F11: Cricket 07 | G11: Cricket moments & gameplay | H11: Long-form | I11: 211 | J11: 937 | K11: 9.8311 | L11: 2 | M11: 6067 | N11: 0.0786 | O11: =IF(OR(J11="",J11=0),"",K11*3600/J11) -> 37.771569 | P11: =IF(OR(O11="",I11=0),"",O11/I11) -> 0.17901217 | Q11: =IF(OR(J11="",J11=0),"",L11/J11*1000) -> 2.1344717 | R11: 0 | S11: =IF(R11=0,"Clean title",IF(R11<=3,"Light hashtags","Hashtag-stuffed")) -> Clean title | T11: =IF(I11<=10,"0–10 sec",IF(I11<=60,"11–60 sec",IF(I11<=180,"61–180 sec","3 min +"))) -> 3 min + | U11: =IF(J11="","NO DATA",IF(J11>=1000,"HIT",IF(J11>=200,"OK","LOW"))) -> OK
A12: 8 | B12: dG3Y_PJcRac | C12: Impossible CS: Condition Zero Shot – You Won’t Believe This! | D12: 44897 | E12: =YEAR(D12) -> 2022 | F12: Counter-Strike CZ | G12: Gameplay clip (other game) | H12: Short | I12: 35 | J12: 779 | K12: 2.6109 | L12: 2 | M12: 6579 | N12: 0.0084 | O12: =IF(OR(J12="",J12=0),"",K12*3600/J12) -> 12.065777 | P12: =IF(OR(O12="",I12=0),"",O12/I12) -> 0.34473648 | Q12: =IF(OR(J12="",J12=0),"",L12/J12*1000) -> 2.5673941 | R12: 0 | S12: =IF(R12=0,"Clean title",IF(R12<=3,"Light hashtags","Hashtag-stuffed")) -> Clean title | T12: =IF(I12<=10,"0–10 sec",IF(I12<=60,"11–60 sec",IF(I12<=180,"61–180 sec","3 min +"))) -> 11–60 sec | U12: =IF(J12="","NO DATA",IF(J12>=1000,"HIT",IF(J12>=200,"OK","LOW"))) -> OK
A13: 9 | B13: eDSHeMeqqRw | C13: Eventful First Over#shorts #ipl | D13: 46138 | E13: =YEAR(D13) -> 2026 | F13: Cricket 07 | G13: Cricket moments & gameplay | H13: Short | I13: 83 | J13: 719 | K13: 1.3292 | L13: 0 | M13: 78 | N13: 0.0385 | O13: =IF(OR(J13="",J13=0),"",K13*3600/J13) -> 6.6552434 | P13: =IF(OR(O13="",I13=0),"",O13/I13) -> 0.080183655 | Q13: =IF(OR(J13="",J13=0),"",L13/J13*1000) -> 0 | R13: 2 | S13: =IF(R13=0,"Clean title",IF(R13<=3,"Light hashtags","Hashtag-stuffed")) -> Light hashtags | T13: =IF(I13<=10,"0–10 sec",IF(I13<=60,"11–60 sec",IF(I13<=180,"61–180 sec","3 min +"))) -> 61–180 sec | U13: =IF(J13="","NO DATA",IF(J13>=1000,"HIT",IF(J13>=200,"OK","LOW"))) -> OK
A14: 10 | B14: Q5GFat6Xcrs | C14: EA SPORTS CRICKET 07 2011 world cup patch#wc2011#yt20 #easports #easportscricket07 #msdhoni#shorts | D14: 44873 | E14: =YEAR(D14) -> 2022 | F14: Cricket 07 | G14: Cricket moments & gameplay | H14: Short | I14: 50 | J14: 502 | K14: 4.0265 | L14: 1 | M14: 2482 | N14: 0.0488 | O14: =IF(OR(J14="",J14=0),"",K14*3600/J14) -> 28.875299 | P14: =IF(OR(O14="",I14=0),"",O14/I14) -> 0.57750598 | Q14: =IF(OR(J14="",J14=0),"",L14/J14*1000) -> 1.9920319 | R14: 6 | S14: =IF(R14=0,"Clean title",IF(R14<=3,"Light hashtags","Hashtag-stuffed")) -> Hashtag-stuffed | T14: =IF(I14<=10,"0–10 sec",IF(I14<=60,"11–60 sec",IF(I14<=180,"61–180 sec","3 min +"))) -> 11–60 sec | U14: =IF(J14="","NO DATA",IF(J14>=1000,"HIT",IF(J14>=200,"OK","LOW"))) -> OK
A15: 11 | B15: 9keTUQcwKD4 | C15: An Outstanding Collapse In Just 1 Over | D15: 46172 | E15: =YEAR(D15) -> 2026 | F15: Cricket 07 | G15: Cricket moments & gameplay | H15: Short | I15: 85 | J15: 441 | K15: 2.9524 | L15: 0 | M15: 10574 | N15: 0.0373 | O15: =IF(OR(J15="",J15=0),"",K15*3600/J15) -> 24.101224 | P15: =IF(OR(O15="",I15=0),"",O15/I15) -> 0.28354382 | Q15: =IF(OR(J15="",J15=0),"",L15/J15*1000) -> 0 | R15: 0 | S15: =IF(R15=0,"Clean title",IF(R15<=3,"Light hashtags","Hashtag-stuffed")) -> Clean title | T15: =IF(I15<=10,"0–10 sec",IF(I15<=60,"11–60 sec",IF(I15<=180,"61–180 sec","3 min +"))) -> 61–180 sec | U15: =IF(J15="","NO DATA",IF(J15>=1000,"HIT",IF(J15>=200,"OK","LOW"))) -> OK
A16: 12 | B16: JGX2UvOZuDM | C16: OUT GIVEN NOT OUT BY A VERY MUCH OF A BONEHEAD UMPIRE | D16: 46180 | E16: =YEAR(D16) -> 2026 | F16: Cricket 07 | G16: Umpire / decision drama | H16: Short | I16: 4 | J16: 343 | K16: 0.1939 | L16: 0 | M16: 12 | N16: 0 | O16: =IF(OR(J16="",J16=0),"",K16*3600/J16) -> 2.035102 | P16: =IF(OR(O16="",I16=0),"",O16/I16) -> 0.50877551 | Q16: =IF(OR(J16="",J16=0),"",L16/J16*1000) -> 0 | R16: 0 | S16: =IF(R16=0,"Clean title",IF(R16<=3,"Light hashtags","Hashtag-stuffed")) -> Clean title | T16: =IF(I16<=10,"0–10 sec",IF(I16<=60,"11–60 sec",IF(I16<=180,"61–180 sec","3 min +"))) -> 0–10 sec | U16: =IF(J16="","NO DATA",IF(J16>=1000,"HIT",IF(J16>=200,"OK","LOW"))) -> OK
... A68: 64 | B68: 9YoTDB33KBA | C68: I just want your attention MOFOS😅! | D68: 46208 | E68: =YEAR(D68) -> 2026 | F68: Cricket 07 | G68: Cricket moments & gameplay | H68: Short | I68: 2 | J68: 2 | K68: 0.0006 | L68: 0 | M68: 10 | N68: 0.1 | O68: =IF(OR(J68="",J68=0),"",K68*3600/J68) -> 1.08 | P68: =IF(OR(O68="",I68=0),"",O68/I68) -> 0.54 | Q68: =IF(OR(J68="",J68=0),"",L68/J68*1000) -> 0 | R68: 0 | S68: =IF(R68=0,"Clean title",IF(R68<=3,"Light hashtags","Hashtag-stuffed")) -> Clean title | T68: =IF(I68<=10,"0–10 sec",IF(I68<=60,"11–60 sec",IF(I68<=180,"61–180 sec","3 min +"))) -> 0–10 sec | U68: =IF(J68="","NO DATA",IF(J68>=1000,"HIT",IF(J68>=200,"OK","LOW"))) -> LOW
A69: 65 | B69: JoqXwqybq6s | C69: November 5, 2025 | D69: 45993 | E69: =YEAR(D69) -> 2025 | F69: Cricket 07 | G69: Cricket moments & gameplay | H69: Short | I69: 5 | J69: 2 | K69: 0.0003 | L69: 0 | M69: 0 | O69: =IF(OR(J69="",J69=0),"",K69*3600/J69) -> 0.54 | P69: =IF(OR(O69="",I69=0),"",O69/I69) -> 0.108 | Q69: =IF(OR(J69="",J69=0),"",L69/J69*1000) -> 0 | R69: 0 | S69: =IF(R69=0,"Clean title",IF(R69<=3,"Light hashtags","Hashtag-stuffed")) -> Clean title | T69: =IF(I69<=10,"0–10 sec",IF(I69<=60,"11–60 sec",IF(I69<=180,"61–180 sec","3 min +"))) -> 0–10 sec | U69: =IF(J69="","NO DATA",IF(J69>=1000,"HIT",IF(J69>=200,"OK","LOW"))) -> LOW
A70: 66 | B70: I0VmUmyhn74 | C70: How's the view😎? | D70: 46207 | E70: =YEAR(D70) -> 2026 | F70: Cricket 07 | G70: Cricket moments & gameplay | H70: Short | I70: 3 | J70: 1 | K70: 0.0006 | L70: 0 | M70: 3 | N70: 0.3333 | O70: =IF(OR(J70="",J70=0),"",K70*3600/J70) -> 2.16 | P70: =IF(OR(O70="",I70=0),"",O70/I70) -> 0.72 | Q70: =IF(OR(J70="",J70=0),"",L70/J70*1000) -> 0 | R70: 0 | S70: =IF(R70=0,"Clean title",IF(R70<=3,"Light hashtags","Hashtag-stuffed")) -> Clean title | T70: =IF(I70<=10,"0–10 sec",IF(I70<=60,"11–60 sec",IF(I70<=180,"61–180 sec","3 min +"))) -> 0–10 sec | U70: =IF(J70="","NO DATA",IF(J70>=1000,"HIT",IF(J70>=200,"OK","LOW"))) -> LOW
A71: 67 | B71: jMDByBDlfg4 | C71: Worst LBW Decision Ever 😭 #shorts #cricket07 #easports #cricket #sports #gaming | D71: 45446 | E71: =YEAR(D71) -> 2024 | F71: Cricket 07 | G71: Umpire / decision drama | H71: Short | I71: 2 | J71: 1 | K71: 0.0009 | L71: 0 | M71: 51 | N71: 0.0196 | O71: =IF(OR(J71="",J71=0),"",K71*3600/J71) -> 3.24 | P71: =IF(OR(O71="",I71=0),"",O71/I71) -> 1.62 | Q71: =IF(OR(J71="",J71=0),"",L71/J71*1000) -> 0 | R71: 6 | S71: =IF(R71=0,"Clean title",IF(R71<=3,"Light hashtags","Hashtag-stuffed")) -> Hashtag-stuffed | T71: =IF(I71<=10,"0–10 sec",IF(I71<=60,"11–60 sec",IF(I71<=180,"61–180 sec","3 min +"))) -> 0–10 sec | U71: =IF(J71="","NO DATA",IF(J71>=1000,"HIT",IF(J71>=200,"OK","LOW"))) -> LOW
A72: 68 | B72: rjWGpO8Tg3M | C72: MK ts_4 Live Stream | D72: 44757 | E72: =YEAR(D72) -> 2022 | F72: Live stream | G72: Gameplay clip (other game) | H72: Live | I72: 0 | M72: 5 | N72: 0 | O72: =IF(OR(J72="",J72=0),"",K72*3600/J72) | P72: =IF(OR(O72="",I72=0),"",O72/I72) | Q72: =IF(OR(J72="",J72=0),"",L72/J72*1000) | R72: 0 | S72: =IF(R72=0,"Clean title",IF(R72<=3,"Light hashtags","Hashtag-stuffed")) -> Clean title | T72: =IF(I72<=10,"0–10 sec",IF(I72<=60,"11–60 sec",IF(I72<=180,"61–180 sec","3 min +"))) -> 0–10 sec | U72: =IF(J72="","NO DATA",IF(J72>=1000,"HIT",IF(J72>=200,"OK","LOW"))) -> NO DATA
A73: 69 | B73: p9VLvAFslRY | C73: The Worst Shot Ever Played In Cricket 07😂 | D73: 46193 | E73: =YEAR(D73) -> 2026 | F73: Cricket 07 | G73: Cricket moments & gameplay | H73: Short | I73: 10 | M73: 5 | N73: 0 | O73: =IF(OR(J73="",J73=0),"",K73*3600/J73) | P73: =IF(OR(O73="",I73=0),"",O73/I73) | Q73: =IF(OR(J73="",J73=0),"",L73/J73*1000) | R73: 0 | S73: =IF(R73=0,"Clean title",IF(R73<=3,"Light hashtags","Hashtag-stuffed")) -> Clean title | T73: =IF(I73<=10,"0–10 sec",IF(I73<=60,"11–60 sec",IF(I73<=180,"61–180 sec","3 min +"))) -> 0–10 sec | U73: =IF(J73="","NO DATA",IF(J73>=1000,"HIT",IF(J73>=200,"OK","LOW"))) -> NO DATA
A74: 70 | B74: ON3H_GZQfcg | C74: Did it for views MOFOS!😎 | D74: 46215 | E74: =YEAR(D74) -> 2026 | F74: Cricket 07 | G74: Cricket moments & gameplay | H74: Short | I74: 3 | M74: 6 | N74: 0 | O74: =IF(OR(J74="",J74=0),"",K74*3600/J74) | P74: =IF(OR(O74="",I74=0),"",O74/I74) | Q74: =IF(OR(J74="",J74=0),"",L74/J74*1000) | R74: 0 | S74: =IF(R74=0,"Clean title",IF(R74<=3,"Light hashtags","Hashtag-stuffed")) -> Clean title | T74: =IF(I74<=10,"0–10 sec",IF(I74<=60,"11–60 sec",IF(I74<=180,"61–180 sec","3 min +"))) -> 0–10 sec | U74: =IF(J74="","NO DATA",IF(J74>=1000,"HIT",IF(J74>=200,"OK","LOW"))) -> NO DATA
A75: 71 | B75: 5xArjQWTUGk | C75: The most bonehead shot ever😅 | D75: 46200 | E75: =YEAR(D75) -> 2026 | F75: Cricket 07 | G75: Cricket moments & gameplay | H75: Short | I75: 10 | M75: 10 | N75: 0 | O75: =IF(OR(J75="",J75=0),"",K75*3600/J75) | P75: =IF(OR(O75="",I75=0),"",O75/I75) | Q75: =IF(OR(J75="",J75=0),"",L75/J75*1000) | R75: 0 | S75: =IF(R75=0,"Clean title",IF(R75<=3,"Light hashtags","Hashtag-stuffed")) -> Clean title | T75: =IF(I75<=10,"0–10 sec",IF(I75<=60,"11–60 sec",IF(I75<=180,"61–180 sec","3 min +"))) -> 0–10 sec | U75: =IF(J75="","NO DATA",IF(J75>=1000,"HIT",IF(J75>=200,"OK","LOW"))) -> NO DATA
A76: 72 | B76: q4TuG5CO8n4 | C76: A BIG SWING FOR NOTHING AND ENDED UP BEING CAUGHT BY THE KEEPER | D76: 46186 | E76: =YEAR(D76) -> 2026 | F76: Cricket 07 | G76: Cricket moments & gameplay | H76: Short | I76: 7 | M76: 8 | N76: 0 | O76: =IF(OR(J76="",J76=0),"",K76*3600/J76) | P76: =IF(OR(O76="",I76=0),"",O76/I76) | Q76: =IF(OR(J76="",J76=0),"",L76/J76*1000) | R76: 0 | S76: =IF(R76=0,"Clean title",IF(R76<=3,"Light hashtags","Hashtag-stuffed")) -> Clean title | T76: =IF(I76<=10,"0–10 sec",IF(I76<=60,"11–60 sec",IF(I76<=180,"61–180 sec","3 min +"))) -> 0–10 sec | U76: =IF(J76="","NO DATA",IF(J76>=1000,"HIT",IF(J76>=200,"OK","LOW"))) -> NO DATA
A78: HOW TO READ THIS SHEET
A79: Performance tier: HIT = 1,000+ views · OK = 200–999 · LOW = under 200 · NO DATA = YouTube exported no views (unlisted/brand-new/never surfaced).
A80: Avg % viewed (est.) = avg view duration ÷ length. Over 100% means people re-watched / looped the Short. It is an estimate from watch-time hours, not the exact Studio figure.
A81: Thumbnail CTR on Shorts is NOT meaningful: Shorts are mostly swiped to in the Shorts feed, not clicked from a thumbnail (e.g. "How Is That NOT OUT?!" got 2,006 views from just 80 thumbnail impressions). Judge Shorts by "Viewed vs swiped away" instead.
A82: Format: Short = 3 min or less (YouTube allows Shorts up to 3 min since Oct 2024). Game & Content angle were tagged from each title.
A83: Per-video totals sum to fewer views than the channel total (29,044) because YouTube keeps views from deleted/private videos and channel-page activity in the channel total only. Same for subscribers (51 channel vs per-video sum).
A84: Data quirks kept as-exported: one video titled "November 5, 2025" (no real title set), a 0-sec live stream, and a -1 subscriber value (someone unsubscribed after watching).

Sheet Monthly Trend
A1: MONTHLY TREND — views vs. uploads
A2: Views are summed from Daily Views (raw); uploads counted from All Videos. Notice: views only show up in the months you were uploading.
A4: Month | B4: Views | C4: Uploads that month | D4: Views per upload | E4: Phase | F4: What happened
A5: 44743 | B5: =SUMIFS('Daily Views (raw)'!$B$5:$B$1935,'Daily Views (raw)'!$A$5:$A$1935,">="&A5,'Daily Views (raw)'!$A$5:$A$1935,"<"&EDATE(A5,1)) -> 123 | C5: =COUNTIFS('All Videos'!$D$5:$D$76,">="&A5,'All Videos'!$D$5:$D$76,"<"&EDATE(A5,1)) -> 1 | D5: =IF(C5=0,"",B5/C5) -> 123 | E5: 2022: Multi-game start | F5: Channel goes live (first live stream)
A6: 44774 | B6: =SUMIFS('Daily Views (raw)'!$B$5:$B$1935,'Daily Views (raw)'!$A$5:$A$1935,">="&A6,'Daily Views (raw)'!$A$5:$A$1935,"<"&EDATE(A6,1)) -> 36 | C6: =COUNTIFS('All Videos'!$D$5:$D$76,">="&A6,'All Videos'!$D$5:$D$76,"<"&EDATE(A6,1)) -> 0 | D6: =IF(C6=0,"",B6/C6) | E6: 2022: Multi-game start
A7: 44805 | B7: =SUMIFS('Daily Views (raw)'!$B$5:$B$1935,'Daily Views (raw)'!$A$5:$A$1935,">="&A7,'Daily Views (raw)'!$A$5:$A$1935,"<"&EDATE(A7,1)) -> 84 | C7: =COUNTIFS('All Videos'!$D$5:$D$76,">="&A7,'All Videos'!$D$5:$D$76,"<"&EDATE(A7,1)) -> 1 | D7: =IF(C7=0,"",B7/C7) -> 84 | E7: 2022: Multi-game start
A8: 44835 | B8: =SUMIFS('Daily Views (raw)'!$B$5:$B$1935,'Daily Views (raw)'!$A$5:$A$1935,">="&A8,'Daily Views (raw)'!$A$5:$A$1935,"<"&EDATE(A8,1)) -> 53 | C8: =COUNTIFS('All Videos'!$D$5:$D$76,">="&A8,'All Videos'!$D$5:$D$76,"<"&EDATE(A8,1)) -> 0 | D8: =IF(C8=0,"",B8/C8) | E8: 2022: Multi-game start
A9: 44866 | B9: =SUMIFS('Daily Views (raw)'!$B$5:$B$1935,'Daily Views (raw)'!$A$5:$A$1935,">="&A9,'Daily Views (raw)'!$A$5:$A$1935,"<"&EDATE(A9,1)) -> 1202 | C9: =COUNTIFS('All Videos'!$D$5:$D$76,">="&A9,'All Videos'!$D$5:$D$76,"<"&EDATE(A9,1)) -> 3 | D9: =IF(C9=0,"",B9/C9) -> 400.66667 | E9: 2022: Multi-game start | F9: First Cricket 07 2011-WC-patch Shorts + MCOC
A10: 44896 | B10: =SUMIFS('Daily Views (raw)'!$B$5:$B$1935,'Daily Views (raw)'!$A$5:$A$1935,">="&A10,'Daily Views (raw)'!$A$5:$A$1935,"<"&EDATE(A10,1)) -> 3193 | C10: =COUNTIFS('All Videos'!$D$5:$D$76,">="&A10,'All Videos'!$D$5:$D$76,"<"&EDATE(A10,1)) -> 6 | D10: =IF(C10=0,"",B10/C10) -> 532.16667 | E10: 2022: Multi-game start | F10: Counter-Strike CZ Short hits 1,595 views in ONE day (Dec 6)
A11: 44927 | B11: =SUMIFS('Daily Views (raw)'!$B$5:$B$1935,'Daily Views (raw)'!$A$5:$A$1935,">="&A11,'Daily Views (raw)'!$A$5:$A$1935,"<"&EDATE(A11,1)) -> 840 | C11: =COUNTIFS('All Videos'!$D$5:$D$76,">="&A11,'All Videos'!$D$5:$D$76,"<"&EDATE(A11,1)) -> 4 | D11: =IF(C11=0,"",B11/C11) -> 210 | E11: 2023: Smash Hit / mixed | F11: Smash Hit Shorts batch — steady but small
A12: 44958 | B12: =SUMIFS('Daily Views (raw)'!$B$5:$B$1935,'Daily Views (raw)'!$A$5:$A$1935,">="&A12,'Daily Views (raw)'!$A$5:$A$1935,"<"&EDATE(A12,1)) -> 844 | C12: =COUNTIFS('All Videos'!$D$5:$D$76,">="&A12,'All Videos'!$D$5:$D$76,"<"&EDATE(A12,1)) -> 0 | D12: =IF(C12=0,"",B12/C12) | E12: 2023: Smash Hit / mixed
A13: 44986 | B13: =SUMIFS('Daily Views (raw)'!$B$5:$B$1935,'Daily Views (raw)'!$A$5:$A$1935,">="&A13,'Daily Views (raw)'!$A$5:$A$1935,"<"&EDATE(A13,1)) -> 731 | C13: =COUNTIFS('All Videos'!$D$5:$D$76,">="&A13,'All Videos'!$D$5:$D$76,"<"&EDATE(A13,1)) -> 2 | D13: =IF(C13=0,"",B13/C13) -> 365.5 | E13: 2023: Smash Hit / mixed
A14: 45017 | B14: =SUMIFS('Daily Views (raw)'!$B$5:$B$1935,'Daily Views (raw)'!$A$5:$A$1935,">="&A14,'Daily Views (raw)'!$A$5:$A$1935,"<"&EDATE(A14,1)) -> 675 | C14: =COUNTIFS('All Videos'!$D$5:$D$76,">="&A14,'All Videos'!$D$5:$D$76,"<"&EDATE(A14,1)) -> 3 | D14: =IF(C14=0,"",B14/C14) -> 225 | E14: 2023: Smash Hit / mixed | F14: Last Smash Hit batch; then uploads slow down
A15: 45047 | B15: =SUMIFS('Daily Views (raw)'!$B$5:$B$1935,'Daily Views (raw)'!$A$5:$A$1935,">="&A15,'Daily Views (raw)'!$A$5:$A$1935,"<"&EDATE(A15,1)) -> 453 | C15: =COUNTIFS('All Videos'!$D$5:$D$76,">="&A15,'All Videos'!$D$5:$D$76,"<"&EDATE(A15,1)) -> 2 | D15: =IF(C15=0,"",B15/C15) -> 226.5 | E15: 2023: Smash Hit / mixed
A16: 45078 | B16: =SUMIFS('Daily Views (raw)'!$B$5:$B$1935,'Daily Views (raw)'!$A$5:$A$1935,">="&A16,'Daily Views (raw)'!$A$5:$A$1935,"<"&EDATE(A16,1)) -> 89 | C16: =COUNTIFS('All Videos'!$D$5:$D$76,">="&A16,'All Videos'!$D$5:$D$76,"<"&EDATE(A16,1)) -> 0 | D16: =IF(C16=0,"",B16/C16) | E16: 2023: Smash Hit / mixed | F16: Upload gap → views collapse
A17: 45108 | B17: =SUMIFS('Daily Views (raw)'!$B$5:$B$1935,'Daily Views (raw)'!$A$5:$A$1935,">="&A17,'Daily Views (raw)'!$A$5:$A$1935,"<"&EDATE(A17,1)) -> 148 | C17: =COUNTIFS('All Videos'!$D$5:$D$76,">="&A17,'All Videos'!$D$5:$D$76,"<"&EDATE(A17,1)) -> 0 | D17: =IF(C17=0,"",B17/C17) | E17: 2023: Smash Hit / mixed
A18: 45139 | B18: =SUMIFS('Daily Views (raw)'!$B$5:$B$1935,'Daily Views (raw)'!$A$5:$A$1935,">="&A18,'Daily Views (raw)'!$A$5:$A$1935,"<"&EDATE(A18,1)) -> 176 | C18: =COUNTIFS('All Videos'!$D$5:$D$76,">="&A18,'All Videos'!$D$5:$D$76,"<"&EDATE(A18,1)) -> 0 | D18: =IF(C18=0,"",B18/C18) | E18: 2023: Smash Hit / mixed
A19: 45170 | B19: =SUMIFS('Daily Views (raw)'!$B$5:$B$1935,'Daily Views (raw)'!$A$5:$A$1935,">="&A19,'Daily Views (raw)'!$A$5:$A$1935,"<"&EDATE(A19,1)) -> 71 | C19: =COUNTIFS('All Videos'!$D$5:$D$76,">="&A19,'All Videos'!$D$5:$D$76,"<"&EDATE(A19,1)) -> 0 | D19: =IF(C19=0,"",B19/C19) | E19: 2023: Smash Hit / mixed
A20: 45200 | B20: =SUMIFS('Daily Views (raw)'!$B$5:$B$1935,'Daily Views (raw)'!$A$5:$A$1935,">="&A20,'Daily Views (raw)'!$A$5:$A$1935,"<"&EDATE(A20,1)) -> 488 | C20: =COUNTIFS('All Videos'!$D$5:$D$76,">="&A20,'All Videos'!$D$5:$D$76,"<"&EDATE(A20,1)) -> 3 | D20: =IF(C20=0,"",B20/C20) -> 162.66667 | E20: 2023: Smash Hit / mixed | F20: Back to Cricket 07 gameplay
A21: 45231 | B21: =SUMIFS('Daily Views (raw)'!$B$5:$B$1935,'Daily Views (raw)'!$A$5:$A$1935,">="&A21,'Daily Views (raw)'!$A$5:$A$1935,"<"&EDATE(A21,1)) -> 602 | C21: =COUNTIFS('All Videos'!$D$5:$D$76,">="&A21,'All Videos'!$D$5:$D$76,"<"&EDATE(A21,1)) -> 5 | D21: =IF(C21=0,"",B21/C21) -> 120.4 | E21: 2023: Smash Hit / mixed | F21: "Umpire Caught Cheating" (3-sec clip) uploaded
A22: 45261 | B22: =SUMIFS('Daily Views (raw)'!$B$5:$B$1935,'Daily Views (raw)'!$A$5:$A$1935,">="&A22,'Daily Views (raw)'!$A$5:$A$1935,"<"&EDATE(A22,1)) -> 357 | C22: =COUNTIFS('All Videos'!$D$5:$D$76,">="&A22,'All Videos'!$D$5:$D$76,"<"&EDATE(A22,1)) -> 1 | D22: =IF(C22=0,"",B22/C22) -> 357 | E22: 2023: Smash Hit / mixed
A23: 45292 | B23: =SUMIFS('Daily Views (raw)'!$B$5:$B$1935,'Daily Views (raw)'!$A$5:$A$1935,">="&A23,'Daily Views (raw)'!$A$5:$A$1935,"<"&EDATE(A23,1)) -> 1033 | C23: =COUNTIFS('All Videos'!$D$5:$D$76,">="&A23,'All Videos'!$D$5:$D$76,"<"&EDATE(A23,1)) -> 3 | D23: =IF(C23=0,"",B23/C23) -> 344.33333 | E23: 2024: Viral clip → silence | F23: That clip starts getting pushed by the Shorts feed
A24: 45323 | B24: =SUMIFS('Daily Views (raw)'!$B$5:$B$1935,'Daily Views (raw)'!$A$5:$A$1935,">="&A24,'Daily Views (raw)'!$A$5:$A$1935,"<"&EDATE(A24,1)) -> 2410 | C24: =COUNTIFS('All Videos'!$D$5:$D$76,">="&A24,'All Videos'!$D$5:$D$76,"<"&EDATE(A24,1)) -> 0 | D24: =IF(C24=0,"",B24/C24) | E24: 2024: Viral clip → silence | F24: Delayed viral wave continues
A25: 45352 | B25: =SUMIFS('Daily Views (raw)'!$B$5:$B$1935,'Daily Views (raw)'!$A$5:$A$1935,">="&A25,'Daily Views (raw)'!$A$5:$A$1935,"<"&EDATE(A25,1)) -> 4607 | C25: =COUNTIFS('All Videos'!$D$5:$D$76,">="&A25,'All Videos'!$D$5:$D$76,"<"&EDATE(A25,1)) -> 0 | D25: =IF(C25=0,"",B25/C25) | E25: 2024: Viral clip → silence | F25: Peak month: 4,607 views — almost all from one 3-sec clip, 4 months after upload
A26: 45383 | B26: =SUMIFS('Daily Views (raw)'!$B$5:$B$1935,'Daily Views (raw)'!$A$5:$A$1935,">="&A26,'Daily Views (raw)'!$A$5:$A$1935,"<"&EDATE(A26,1)) -> 510 | C26: =COUNTIFS('All Videos'!$D$5:$D$76,">="&A26,'All Videos'!$D$5:$D$76,"<"&EDATE(A26,1)) -> 0 | D26: =IF(C26=0,"",B26/C26) | E26: 2024: Viral clip → silence | F26: Wave ends; few new uploads to catch the traffic
A27: 45413 | B27: =SUMIFS('Daily Views (raw)'!$B$5:$B$1935,'Daily Views (raw)'!$A$5:$A$1935,">="&A27,'Daily Views (raw)'!$A$5:$A$1935,"<"&EDATE(A27,1)) -> 87 | C27: =COUNTIFS('All Videos'!$D$5:$D$76,">="&A27,'All Videos'!$D$5:$D$76,"<"&EDATE(A27,1)) -> 2 | D27: =IF(C27=0,"",B27/C27) -> 43.5 | E27: 2024: Viral clip → silence | F27: Long quiet period (~1 upload in 18 months)
A28: 45444 | B28: =SUMIFS('Daily Views (raw)'!$B$5:$B$1935,'Daily Views (raw)'!$A$5:$A$1935,">="&A28,'Daily Views (raw)'!$A$5:$A$1935,"<"&EDATE(A28,1)) -> 24 | C28: =COUNTIFS('All Videos'!$D$5:$D$76,">="&A28,'All Videos'!$D$5:$D$76,"<"&EDATE(A28,1)) -> 1 | D28: =IF(C28=0,"",B28/C28) -> 24 | E28: 2024: Viral clip → silence
A29: 45474 | B29: =SUMIFS('Daily Views (raw)'!$B$5:$B$1935,'Daily Views (raw)'!$A$5:$A$1935,">="&A29,'Daily Views (raw)'!$A$5:$A$1935,"<"&EDATE(A29,1)) -> 38 | C29: =COUNTIFS('All Videos'!$D$5:$D$76,">="&A29,'All Videos'!$D$5:$D$76,"<"&EDATE(A29,1)) -> 0 | D29: =IF(C29=0,"",B29/C29) | E29: 2024: Viral clip → silence
A30: 45505 | B30: =SUMIFS('Daily Views (raw)'!$B$5:$B$1935,'Daily Views (raw)'!$A$5:$A$1935,">="&A30,'Daily Views (raw)'!$A$5:$A$1935,"<"&EDATE(A30,1)) -> 23 | C30: =COUNTIFS('All Videos'!$D$5:$D$76,">="&A30,'All Videos'!$D$5:$D$76,"<"&EDATE(A30,1)) -> 0 | D30: =IF(C30=0,"",B30/C30) | E30: 2024: Viral clip → silence
A31: 45536 | B31: =SUMIFS('Daily Views (raw)'!$B$5:$B$1935,'Daily Views (raw)'!$A$5:$A$1935,">="&A31,'Daily Views (raw)'!$A$5:$A$1935,"<"&EDATE(A31,1)) -> 16 | C31: =COUNTIFS('All Videos'!$D$5:$D$76,">="&A31,'All Videos'!$D$5:$D$76,"<"&EDATE(A31,1)) -> 0 | D31: =IF(C31=0,"",B31/C31) | E31: 2024: Viral clip → silence
A32: 45566 | B32: =SUMIFS('Daily Views (raw)'!$B$5:$B$1935,'Daily Views (raw)'!$A$5:$A$1935,">="&A32,'Daily Views (raw)'!$A$5:$A$1935,"<"&EDATE(A32,1)) -> 157 | C32: =COUNTIFS('All Videos'!$D$5:$D$76,">="&A32,'All Videos'!$D$5:$D$76,"<"&EDATE(A32,1)) -> 1 | D32: =IF(C32=0,"",B32/C32) -> 157 | E32: 2024: Viral clip → silence | F32: Smash Hit long-form (27 min) — 145 views
A33: 45597 | B33: =SUMIFS('Daily Views (raw)'!$B$5:$B$1935,'Daily Views (raw)'!$A$5:$A$1935,">="&A33,'Daily Views (raw)'!$A$5:$A$1935,"<"&EDATE(A33,1)) -> 1 | C33: =COUNTIFS('All Videos'!$D$5:$D$76,">="&A33,'All Videos'!$D$5:$D$76,"<"&EDATE(A33,1)) -> 0 | D33: =IF(C33=0,"",B33/C33) | E33: 2024: Viral clip → silence
A34: 45627 | B34: =SUMIFS('Daily Views (raw)'!$B$5:$B$1935,'Daily Views (raw)'!$A$5:$A$1935,">="&A34,'Daily Views (raw)'!$A$5:$A$1935,"<"&EDATE(A34,1)) -> 9 | C34: =COUNTIFS('All Videos'!$D$5:$D$76,">="&A34,'All Videos'!$D$5:$D$76,"<"&EDATE(A34,1)) -> 0 | D34: =IF(C34=0,"",B34/C34) | E34: 2024: Viral clip → silence
A35: 45658 | B35: =SUMIFS('Daily Views (raw)'!$B$5:$B$1935,'Daily Views (raw)'!$A$5:$A$1935,">="&A35,'Daily Views (raw)'!$A$5:$A$1935,"<"&EDATE(A35,1)) -> 6 | C35: =COUNTIFS('All Videos'!$D$5:$D$76,">="&A35,'All Videos'!$D$5:$D$76,"<"&EDATE(A35,1)) -> 0 | D35: =IF(C35=0,"",B35/C35) | E35: 2025: Dormant → umpire comeback
A36: 45689 | B36: =SUMIFS('Daily Views (raw)'!$B$5:$B$1935,'Daily Views (raw)'!$A$5:$A$1935,">="&A36,'Daily Views (raw)'!$A$5:$A$1935,"<"&EDATE(A36,1)) -> 4 | C36: =COUNTIFS('All Videos'!$D$5:$D$76,">="&A36,'All Videos'!$D$5:$D$76,"<"&EDATE(A36,1)) -> 0 | D36: =IF(C36=0,"",B36/C36) | E36: 2025: Dormant → umpire comeback
A37: 45717 | B37: =SUMIFS('Daily Views (raw)'!$B$5:$B$1935,'Daily Views (raw)'!$A$5:$A$1935,">="&A37,'Daily Views (raw)'!$A$5:$A$1935,"<"&EDATE(A37,1)) -> 10 | C37: =COUNTIFS('All Videos'!$D$5:$D$76,">="&A37,'All Videos'!$D$5:$D$76,"<"&EDATE(A37,1)) -> 0 | D37: =IF(C37=0,"",B37/C37) | E37: 2025: Dormant → umpire comeback
A38: 45748 | B38: =SUMIFS('Daily Views (raw)'!$B$5:$B$1935,'Daily Views (raw)'!$A$5:$A$1935,">="&A38,'Daily Views (raw)'!$A$5:$A$1935,"<"&EDATE(A38,1)) -> 2 | C38: =COUNTIFS('All Videos'!$D$5:$D$76,">="&A38,'All Videos'!$D$5:$D$76,"<"&EDATE(A38,1)) -> 0 | D38: =IF(C38=0,"",B38/C38) | E38: 2025: Dormant → umpire comeback
A39: 45778 | B39: =SUMIFS('Daily Views (raw)'!$B$5:$B$1935,'Daily Views (raw)'!$A$5:$A$1935,">="&A39,'Daily Views (raw)'!$A$5:$A$1935,"<"&EDATE(A39,1)) -> 2 | C39: =COUNTIFS('All Videos'!$D$5:$D$76,">="&A39,'All Videos'!$D$5:$D$76,"<"&EDATE(A39,1)) -> 0 | D39: =IF(C39=0,"",B39/C39) | E39: 2025: Dormant → umpire comeback
A40: 45809 | B40: =SUMIFS('Daily Views (raw)'!$B$5:$B$1935,'Daily Views (raw)'!$A$5:$A$1935,">="&A40,'Daily Views (raw)'!$A$5:$A$1935,"<"&EDATE(A40,1)) -> 3 | C40: =COUNTIFS('All Videos'!$D$5:$D$76,">="&A40,'All Videos'!$D$5:$D$76,"<"&EDATE(A40,1)) -> 0 | D40: =IF(C40=0,"",B40/C40) | E40: 2025: Dormant → umpire comeback
A41: 45839 | B41: =SUMIFS('Daily Views (raw)'!$B$5:$B$1935,'Daily Views (raw)'!$A$5:$A$1935,">="&A41,'Daily Views (raw)'!$A$5:$A$1935,"<"&EDATE(A41,1)) -> 7 | C41: =COUNTIFS('All Videos'!$D$5:$D$76,">="&A41,'All Videos'!$D$5:$D$76,"<"&EDATE(A41,1)) -> 0 | D41: =IF(C41=0,"",B41/C41) | E41: 2025: Dormant → umpire comeback
...

Sheet Top 5 Trajectories
A1: TOP 5 VIDEOS — how their views arrived over time (weekly)
A2: Source: Chart_data.csv (YouTube exports daily views only for your top 5). Shows WHEN each hit was pushed — often months after upload.
A4: Week starting | B4: Umpire Caught Cheating In Cricket 07 | C4: How Is That NOT OUT?! 😳 | D4: counter strike condition zero#counterstrike#counterstrikeconditionzero#shorts | E4: The Calm Before LBW | F4: BLIND UMPIRE
A5: 44893 | B5: 0 | C5: 0 | D5: 0 | E5: 0 | F5: 0
A6: 44900 | B6: 0 | C6: 0 | D6: 1553 | E6: 0 | F6: 0
A7: 44907 | B7: 0 | C7: 0 | D7: 2 | E7: 0 | F7: 0
A8: 44914 | B8: 0 | C8: 0 | D8: 0 | E8: 0 | F8: 0
A9: 44921 | B9: 0 | C9: 0 | D9: 0 | E9: 0 | F9: 0
A10: 44928 | B10: 0 | C10: 0 | D10: 1 | E10: 0 | F10: 0
A11: 44935 | B11: 0 | C11: 0 | D11: 0 | E11: 0 | F11: 0
A12: 44942 | B12: 0 | C12: 0 | D12: 0 | E12: 0 | F12: 0
A13: 44949 | B13: 0 | C13: 0 | D13: 1 | E13: 0 | F13: 0
A14: 44956 | B14: 0 | C14: 0 | D14: 0 | E14: 0 | F14: 0
A15: 44963 | B15: 0 | C15: 0 | D15: 0 | E15: 0 | F15: 0
A16: 44970 | B16: 0 | C16: 0 | D16: 0 | E16: 0 | F16: 0
... A25: 45033 | B25: 0 | C25: 0 | D25: 0 | E25: 0 | F25: 0
A26: 45040 | B26: 0 | C26: 0 | D26: 0 | E26: 0 | F26: 0 | H26: What this shows
A27: 45047 | B27: 0 | C27: 0 | D27: 0 | E27: 0 | F27: 0 | H27: • "Umpire Caught Cheating In Cricket 07" was uploaded 18 Nov 2023 but got ~89% of its 8,609 views between mid-Jan and early-Apr 2024. The Shorts feed re-tested it weeks later and it took off.
A28: 45054 | B28: 0 | C28: 0 | D28: 0 | E28: 0 | F28: 0 | H28: • Every other top video peaked within 1–3 days of upload and then flat-lined. That is normal Shorts behaviour: one push, then done, unless the clip gets re-tested.
A29: 45061 | B29: 0 | C29: 0 | D29: 0 | E29: 0 | F29: 0 | H29: • Lesson: Shorts can go viral late. Don't delete "flops" early, and keep uploading so a viral moment has more videos for new viewers to binge.
A30: 45068 | B30: 0 | C30: 0 | D30: 0 | E30: 0 | F30: 0
A31: 45075 | B31: 0 | C31: 0 | D31: 0 | E31: 0 | F31: 0
A32: 45082 | B32: 0 | C32: 0 | D32: 0 | E32: 0 | F32: 0
A33: 45089 | B33: 0 | C33: 0 | D33: 0 | E33: 0 | F33: 0
A34: 45096 | B34: 0 | C34: 0 | D34: 0 | E34: 0 | F34: 0
A35: 45103 | B35: 0 | C35: 0 | D35: 0 | E35: 0 | F35: 0
A36: 45110 | B36: 0 | C36: 0 | D36: 0 | E36: 0 | F36: 0
A37: 45117 | B37: 0 | C37: 0 | D37: 0 | E37: 0 | F37: 0
A38: 45124 | B38: 0 | C38: 0 | D38: 0 | E38: 0 | F38: 0
A39: 45131 | B39: 0 | C39: 0 | D39: 0 | E39: 0 | F39: 0
A40: 45138 | B40: 0 | C40: 0 | D40: 1 | E40: 0 | F40: 0
A41: 45145 | B41: 0 | C41: 0 | D41: 0 | E41: 0 | F41: 0
... A207: 46307 | B207: 1 | C207: 0 | D207: 0 | E207: 0 | F207: 0

Sheet Breakdowns
A1: BREAKDOWNS — what kind of content actually worked
A2: All numbers are live formulas over the All Videos sheet. Green = best in table, red = worst.
A4: 1) BY GAME
A5: Group | B5: # videos | C5: Total views | D5: Share of views | E5: Avg views / video | F5: Watch time (hrs) | G5: Subs gained | H5: Subs per 1k views | I5: Weighted thumbnail CTR | J5: Verdict
A6: Cricket 07 | B6: =COUNTIFS('All Videos'!$F$5:$F$76,A6) -> 50 | C6: =SUMIFS('All Videos'!$J$5:$J$76,'All Videos'!$F$5:$F$76,A6) -> 21011 | D6: =IF(SUM('All Videos'!$J$5:$J$76)=0,0,C6/SUM('All Videos'!$J$5:$J$76)) -> 0.8056365 | E6: =IF(B6=0,0,C6/B6) -> 420.22 | F6: =SUMIFS('All Videos'!$K$5:$K$76,'All Videos'!$F$5:$F$76,A6) -> 40.222 | G6: =SUMIFS('All Videos'!$L$5:$L$76,'All Videos'!$F$5:$F$76,A6) -> 14 | H6: =IF(C6=0,0,G6/C6*1000) -> 0.66631764 | I6: =IFERROR(SUMPRODUCT(('All Videos'!$F$5:$F$76=A6)*'All Videos'!$M$5:$M$76*'All Videos'!$N$5:$N$76)/SUMIFS('All Videos'!$M$5:$M$76,'All Videos'!$F$5:$F$76,A6),0) -> 0.063836427 | J6: WINNER — 4 in 5 of your views. This is your niche.
A7: Counter-Strike CZ | B7: =COUNTIFS('All Videos'!$F$5:$F$76,A7) -> 4 | C7: =SUMIFS('All Videos'!$J$5:$J$76,'All Videos'!$F$5:$F$76,A7) -> 2696 | D7: =IF(SUM('All Videos'!$J$5:$J$76)=0,0,C7/SUM('All Videos'!$J$5:$J$76)) -> 0.10337423 | E7: =IF(B7=0,0,C7/B7) -> 674 | F7: =SUMIFS('All Videos'!$K$5:$K$76,'All Videos'!$F$5:$F$76,A7) -> 11.2559 | G7: =SUMIFS('All Videos'!$L$5:$L$76,'All Videos'!$F$5:$F$76,A7) -> 2 | H7: =IF(C7=0,0,G7/C7*1000) -> 0.74183976 | I7: =IFERROR(SUMPRODUCT(('All Videos'!$F$5:$F$76=A7)*'All Videos'!$M$5:$M$76*'All Videos'!$N$5:$N$76)/SUMIFS('All Videos'!$M$5:$M$76,'All Videos'!$F$5:$F$76,A7),0) -> 0.0086900779 | J7: Few uploads but one 1,600-view Short. A clip-friendly game, but off-niche.
A8: Smash Hit | B8: =COUNTIFS('All Videos'!$F$5:$F$76,A8) -> 14 | C8: =SUMIFS('All Videos'!$J$5:$J$76,'All Videos'!$F$5:$F$76,A8) -> 1963 | D8: =IF(SUM('All Videos'!$J$5:$J$76)=0,0,C8/SUM('All Videos'!$J$5:$J$76)) -> 0.075268405 | E8: =IF(B8=0,0,C8/B8) -> 140.21429 | F8: =SUMIFS('All Videos'!$K$5:$K$76,'All Videos'!$F$5:$F$76,A8) -> 12.1717 | G8: =SUMIFS('All Videos'!$L$5:$L$76,'All Videos'!$F$5:$F$76,A8) -> 3 | H8: =IF(C8=0,0,G8/C8*1000) -> 1.5282731 | I8: =IFERROR(SUMPRODUCT(('All Videos'!$F$5:$F$76=A8)*'All Videos'!$M$5:$M$76*'All Videos'!$N$5:$N$76)/SUMIFS('All Videos'!$M$5:$M$76,'All Videos'!$F$5:$F$76,A8),0) -> 0.045240681 | J8: 14 uploads, low ceiling (≈140 views each). Drop it.
A9: Marvel Contest of Champions | B9: =COUNTIFS('All Videos'!$F$5:$F$76,A9) -> 3 | C9: =SUMIFS('All Videos'!$J$5:$J$76,'All Videos'!$F$5:$F$76,A9) -> 410 | D9: =IF(SUM('All Videos'!$J$5:$J$76)=0,0,C9/SUM('All Videos'!$J$5:$J$76)) -> 0.015720859 | E9: =IF(B9=0,0,C9/B9) -> 136.66667 | F9: =SUMIFS('All Videos'!$K$5:$K$76,'All Videos'!$F$5:$F$76,A9) -> 0.9662 | G9: =SUMIFS('All Videos'!$L$5:$L$76,'All Videos'!$F$5:$F$76,A9) -> 1 | H9: =IF(C9=0,0,G9/C9*1000) -> 2.4390244 | I9: =IFERROR(SUMPRODUCT(('All Videos'!$F$5:$F$76=A9)*'All Videos'!$M$5:$M$76*'All Videos'!$N$5:$N$76)/SUMIFS('All Videos'!$M$5:$M$76,'All Videos'!$F$5:$F$76,A9),0) -> 0.018961095 | J9: Weakest. Generic gameplay with no hook.
A10: Live stream | B10: =COUNTIFS('All Videos'!$F$5:$F$76,A10) -> 1 | C10: =SUMIFS('All Videos'!$J$5:$J$76,'All Videos'!$F$5:$F$76,A10) -> 0 | D10: =IF(SUM('All Videos'!$J$5:$J$76)=0,0,C10/SUM('All Videos'!$J$5:$J$76)) -> 0 | E10: =IF(B10=0,0,C10/B10) -> 0 | F10: =SUMIFS('All Videos'!$K$5:$K$76,'All Videos'!$F$5:$F$76,A10) -> 0 | G10: =SUMIFS('All Videos'!$L$5:$L$76,'All Videos'!$F$5:$F$76,A10) -> 0 | H10: =IF(C10=0,0,G10/C10*1000) -> 0 | I10: =IFERROR(SUMPRODUCT(('All Videos'!$F$5:$F$76=A10)*'All Videos'!$M$5:$M$76*'All Videos'!$N$5:$N$76)/SUMIFS('All Videos'!$M$5:$M$76,'All Videos'!$F$5:$F$76,A10),0) -> 0 | J10: One stream, no views.
A12: 2) BY CONTENT ANGLE
A13: Group | B13: # videos | C13: Total views | D13: Share of views | E13: Avg views / video | F13: Watch time (hrs) | G13: Subs gained | H13: Subs per 1k views | I13: Weighted thumbnail CTR | J13: Verdict
A14: Umpire / decision drama | B14: =COUNTIFS('All Videos'!$G$5:$G$76,A14) -> 26 | C14: =SUMIFS('All Videos'!$J$5:$J$76,'All Videos'!$G$5:$G$76,A14) -> 17191 | D14: =IF(SUM('All Videos'!$J$5:$J$76)=0,0,C14/SUM('All Videos'!$J$5:$J$76)) -> 0.65916411 | E14: =IF(B14=0,0,C14/B14) -> 661.19231 | F14: =SUMIFS('All Videos'!$K$5:$K$76,'All Videos'!$G$5:$G$76,A14) -> 13.5495 | G14: =SUMIFS('All Videos'!$L$5:$L$76,'All Videos'!$G$5:$G$76,A14) -> 8 | H14: =IF(C14=0,0,G14/C14*1000) -> 0.46535978 | I14: =IFERROR(SUMPRODUCT(('All Videos'!$G$5:$G$76=A14)*'All Videos'!$M$5:$M$76*'All Videos'!$N$5:$N$76)/SUMIFS('All Videos'!$M$5:$M$76,'All Videos'!$G$5:$G$76,A14),0) -> 0.069376093 | J14: YOUR SIGNATURE: about 4x the views per video of other cricket clips. Controversy + "was it out?" invites debate.
A15: Cricket moments & gameplay | B15: =COUNTIFS('All Videos'!$G$5:$G$76,A15) -> 24 | C15: =SUMIFS('All Videos'!$J$5:$J$76,'All Videos'!$G$5:$G$76,A15) -> 3820 | D15: =IF(SUM('All Videos'!$J$5:$J$76)=0,0,C15/SUM('All Videos'!$J$5:$J$76)) -> 0.14647239 | E15: =IF(B15=0,0,C15/B15) -> 159.16667 | F15: =SUMIFS('All Videos'!$K$5:$K$76,'All Videos'!$G$5:$G$76,A15) -> 26.6725 | G15: =SUMIFS('All Videos'!$L$5:$L$76,'All Videos'!$G$5:$G$76,A15) -> 6 | H15: =IF(C15=0,0,G15/C15*1000) -> 1.5706806 | I15: =IFERROR(SUMPRODUCT(('All Videos'!$G$5:$G$76=A15)*'All Videos'!$M$5:$M$76*'All Videos'!$N$5:$N$76)/SUMIFS('All Videos'!$M$5:$M$76,'All Videos'!$G$5:$G$76,A15),0) -> 0.046341223 | J15: Decent when there is a story (collapse, hat-trick); weak as plain gameplay.
A16: Gameplay clip (other game) | B16: =COUNTIFS('All Videos'!$G$5:$G$76,A16) -> 22 | C16: =SUMIFS('All Videos'!$J$5:$J$76,'All Videos'!$G$5:$G$76,A16) -> 5069 | D16: =IF(SUM('All Videos'!$J$5:$J$76)=0,0,C16/SUM('All Videos'!$J$5:$J$76)) -> 0.1943635 | E16: =IF(B16=0,0,C16/B16) -> 230.40909 | F16: =SUMIFS('All Videos'!$K$5:$K$76,'All Videos'!$G$5:$G$76,A16) -> 24.3938 | G16: =SUMIFS('All Videos'!$L$5:$L$76,'All Videos'!$G$5:$G$76,A16) -> 6 | H16: =IF(C16=0,0,G16/C16*1000) -> 1.1836654 | I16: =IFERROR(SUMPRODUCT(('All Videos'!$G$5:$G$76=A16)*'All Videos'!$M$5:$M$76*'All Videos'!$N$5:$N$76)/SUMIFS('All Videos'!$M$5:$M$76,'All Videos'!$G$5:$G$76,A16),0) -> 0.025697521 | J16: Spread too thin across games; no identity.
A18: 3) BY FORMAT
A19: Group | B19: # videos | C19: Total views | D19: Share of views | E19: Avg views / video | F19: Watch time (hrs) | G19: Subs gained | H19: Subs per 1k views | I19: Weighted thumbnail CTR | J19: Verdict
A20: Short | B20: =COUNTIFS('All Videos'!$H$5:$H$76,A20) -> 66 | C20: =SUMIFS('All Videos'!$J$5:$J$76,'All Videos'!$H$5:$H$76,A20) -> 24562 | D20: =IF(SUM('All Videos'!$J$5:$J$76)=0,0,C20/SUM('All Videos'!$J$5:$J$76)) -> 0.94179448 | E20: =IF(B20=0,0,C20/B20) -> 372.15152 | F20: =SUMIFS('All Videos'!$K$5:$K$76,'All Videos'!$H$5:$H$76,A20) -> 45.3527 | G20: =SUMIFS('All Videos'!$L$5:$L$76,'All Videos'!$H$5:$H$76,A20) -> 18 | H20: =IF(C20=0,0,G20/C20*1000) -> 0.73283935 | I20: =IFERROR(SUMPRODUCT(('All Videos'!$H$5:$H$76=A20)*'All Videos'!$M$5:$M$76*'All Videos'!$N$5:$N$76)/SUMIFS('All Videos'!$M$5:$M$76,'All Videos'!$H$5:$H$76,A20),0) -> 0.057657011 | J20: Shorts brought nearly all your reach.
A21: Long-form | B21: =COUNTIFS('All Videos'!$H$5:$H$76,A21) -> 5 | C21: =SUMIFS('All Videos'!$J$5:$J$76,'All Videos'!$H$5:$H$76,A21) -> 1518 | D21: =IF(SUM('All Videos'!$J$5:$J$76)=0,0,C21/SUM('All Videos'!$J$5:$J$76)) -> 0.058205521 | E21: =IF(B21=0,0,C21/B21) -> 303.6 | F21: =SUMIFS('All Videos'!$K$5:$K$76,'All Videos'!$H$5:$H$76,A21) -> 19.2631 | G21: =SUMIFS('All Videos'!$L$5:$L$76,'All Videos'!$H$5:$H$76,A21) -> 2 | H21: =IF(C21=0,0,G21/C21*1000) -> 1.3175231 | I21: =IFERROR(SUMPRODUCT(('All Videos'!$H$5:$H$76=A21)*'All Videos'!$M$5:$M$76*'All Videos'!$N$5:$N$76)/SUMIFS('All Videos'!$M$5:$M$76,'All Videos'!$H$5:$H$76,A21),0) -> 0.064951792 | J21: Best thumbnail CTR on the channel, but viewers leave fast (4–18% watched).
A22: Live | B22: =COUNTIFS('All Videos'!$H$5:$H$76,A22) -> 1 | C22: =SUMIFS('All Videos'!$J$5:$J$76,'All Videos'!$H$5:$H$76,A22) -> 0 | D22: =IF(SUM('All Videos'!$J$5:$J$76)=0,0,C22/SUM('All Videos'!$J$5:$J$76)) -> 0 | E22: =IF(B22=0,0,C22/B22) -> 0 | F22: =SUMIFS('All Videos'!$K$5:$K$76,'All Videos'!$H$5:$H$76,A22) -> 0 | G22: =SUMIFS('All Videos'!$L$5:$L$76,'All Videos'!$H$5:$H$76,A22) -> 0 | H22: =IF(C22=0,0,G22/C22*1000) -> 0 | I22: =IFERROR(SUMPRODUCT(('All Videos'!$H$5:$H$76=A22)*'All Videos'!$M$5:$M$76*'All Videos'!$N$5:$N$76)/SUMIFS('All Videos'!$M$5:$M$76,'All Videos'!$H$5:$H$76,A22),0) -> 0 | J22: Untested.
A24: 4) BY LENGTH
A25: Group | B25: # videos | C25: Total views | D25: Share of views | E25: Avg views / video | F25: Watch time (hrs) | G25: Subs gained | H25: Subs per 1k views | I25: Weighted thumbnail CTR | J25: Verdict
A26: 0–10 sec | B26: =COUNTIFS('All Videos'!$T$5:$T$76,A26) -> 41 | C26: =SUMIFS('All Videos'!$J$5:$J$76,'All Videos'!$T$5:$T$76,A26) -> 16037 | D26: =IF(SUM('All Videos'!$J$5:$J$76)=0,0,C26/SUM('All Videos'!$J$5:$J$76)) -> 0.61491564 | E26: =IF(B26=0,0,C26/B26) -> 391.14634 | F26: =SUMIFS('All Videos'!$K$5:$K$76,'All Videos'!$T$5:$T$76,A26) -> 13.6303 | G26: =SUMIFS('All Videos'!$L$5:$L$76,'All Videos'!$T$5:$T$76,A26) -> 8 | H26: =IF(C26=0,0,G26/C26*1000) -> 0.49884642 | I26: =IFERROR(SUMPRODUCT(('All Videos'!$T$5:$T$76=A26)*'All Videos'!$M$5:$M$76*'All Videos'!$N$5:$N$76)/SUMIFS('All Videos'!$M$5:$M$76,'All Videos'!$T$5:$T$76,A26),0) -> 0.067077851 | J26: Ultra-short clips loop; the biggest hits are here. But each view is worth ~2 sec of watch time and almost no subs.
A27: 11–60 sec | B27: =COUNTIFS('All Videos'!$T$5:$T$76,A27) -> 19 | C27: =SUMIFS('All Videos'!$J$5:$J$76,'All Videos'!$T$5:$T$76,A27) -> 6643 | D27: =IF(SUM('All Videos'!$J$5:$J$76)=0,0,C27/SUM('All Videos'!$J$5:$J$76)) -> 0.25471626 | E27: =IF(B27=0,0,C27/B27) -> 349.63158 | F27: =SUMIFS('All Videos'!$K$5:$K$76,'All Videos'!$T$5:$T$76,A27) -> 24.3112 | G27: =SUMIFS('All Videos'!$L$5:$L$76,'All Videos'!$T$5:$T$76,A27) -> 7 | H27: =IF(C27=0,0,G27/C27*1000) -> 1.0537408 | I27: =IFERROR(SUMPRODUCT(('All Videos'!$T$5:$T$76=A27)*'All Videos'!$M$5:$M$76*'All Videos'!$N$5:$N$76)/SUMIFS('All Videos'!$M$5:$M$76,'All Videos'!$T$5:$T$76,A27),0) -> 0.026791016 | J27: The sweet spot for adding a hook, context and a call-to-action.
A28: 61–180 sec | B28: =COUNTIFS('All Videos'!$T$5:$T$76,A28) -> 7 | C28: =SUMIFS('All Videos'!$J$5:$J$76,'All Videos'!$T$5:$T$76,A28) -> 1882 | D28: =IF(SUM('All Videos'!$J$5:$J$76)=0,0,C28/SUM('All Videos'!$J$5:$J$76)) -> 0.072162577 | E28: =IF(B28=0,0,C28/B28) -> 268.85714 | F28: =SUMIFS('All Videos'!$K$5:$K$76,'All Videos'!$T$5:$T$76,A28) -> 7.4112 | G28: =SUMIFS('All Videos'!$L$5:$L$76,'All Videos'!$T$5:$T$76,A28) -> 3 | H28: =IF(C28=0,0,G28/C28*1000) -> 1.5940489 | I28: =IFERROR(SUMPRODUCT(('All Videos'!$T$5:$T$76=A28)*'All Videos'!$M$5:$M$76*'All Videos'!$N$5:$N$76)/SUMIFS('All Videos'!$M$5:$M$76,'All Videos'!$T$5:$T$76,A28),0) -> 0.037465465 | J28: Fine for over/match recaps with a story.
A29: 3 min + | B29: =COUNTIFS('All Videos'!$T$5:$T$76,A29) -> 5 | C29: =SUMIFS('All Videos'!$J$5:$J$76,'All Videos'!$T$5:$T$76,A29) -> 1518 | D29: =IF(SUM('All Videos'!$J$5:$J$76)=0,0,C29/SUM('All Videos'!$J$5:$J$76)) -> 0.058205521 | E29: =IF(B29=0,0,C29/B29) -> 303.6 | F29: =SUMIFS('All Videos'!$K$5:$K$76,'All Videos'!$T$5:$T$76,A29) -> 19.2631 | G29: =SUMIFS('All Videos'!$L$5:$L$76,'All Videos'!$T$5:$T$76,A29) -> 2 | H29: =IF(C29=0,0,G29/C29*1000) -> 1.3175231 | I29: =IFERROR(SUMPRODUCT(('All Videos'!$T$5:$T$76=A29)*'All Videos'!$M$5:$M$76*'All Videos'!$N$5:$N$76)/SUMIFS('All Videos'!$M$5:$M$76,'All Videos'!$T$5:$T$76,A29),0) -> 0.064951792 | J29: Needs much stronger editing and structure to hold people.
A31: 5) BY TITLE STYLE
A32: Group | B32: # videos | C32: Total views | D32: Share of views | E32: Avg views / video | F32: Watch time (hrs) | G32: Subs gained | H32: Subs per 1k views | I32: Weighted thumbnail CTR | J32: Verdict
A33: Clean title | B33: =COUNTIFS('All Videos'!$S$5:$S$76,A33) -> 32 | C33: =SUMIFS('All Videos'!$J$5:$J$76,'All Videos'!$S$5:$S$76,A33) -> 17787 | D33: =IF(SUM('All Videos'!$J$5:$J$76)=0,0,C33/SUM('All Videos'!$J$5:$J$76)) -> 0.68201687 | E33: =IF(B33=0,0,C33/B33) -> 555.84375 | F33: =SUMIFS('All Videos'!$K$5:$K$76,'All Videos'!$S$5:$S$76,A33) -> 31.4594 | G33: =SUMIFS('All Videos'!$L$5:$L$76,'All Videos'!$S$5:$S$76,A33) -> 11 | H33: =IF(C33=0,0,G33/C33*1000) -> 0.61842919 | I33: =IFERROR(SUMPRODUCT(('All Videos'!$S$5:$S$76=A33)*'All Videos'!$M$5:$M$76*'All Videos'!$N$5:$N$76)/SUMIFS('All Videos'!$M$5:$M$76,'All Videos'!$S$5:$S$76,A33),0) -> 0.072755775 | J33: Clean, human titles got the most views per video.
A34: Light hashtags | B34: =COUNTIFS('All Videos'!$S$5:$S$76,A34) -> 8 | C34: =SUMIFS('All Videos'!$J$5:$J$76,'All Videos'!$S$5:$S$76,A34) -> 4282 | D34: =IF(SUM('All Videos'!$J$5:$J$76)=0,0,C34/SUM('All Videos'!$J$5:$J$76)) -> 0.16418712 | E34: =IF(B34=0,0,C34/B34) -> 535.25 | F34: =SUMIFS('All Videos'!$K$5:$K$76,'All Videos'!$S$5:$S$76,A34) -> 13.2776 | G34: =SUMIFS('All Videos'!$L$5:$L$76,'All Videos'!$S$5:$S$76,A34) -> 1 | H34: =IF(C34=0,0,G34/C34*1000) -> 0.23353573 | I34: =IFERROR(SUMPRODUCT(('All Videos'!$S$5:$S$76=A34)*'All Videos'!$M$5:$M$76*'All Videos'!$N$5:$N$76)/SUMIFS('All Videos'!$M$5:$M$76,'All Videos'!$S$5:$S$76,A34),0) -> 0.033738494 | J34: OK when 1–3 relevant tags.
A35: Hashtag-stuffed | B35: =COUNTIFS('All Videos'!$S$5:$S$76,A35) -> 32 | C35: =SUMIFS('All Videos'!$J$5:$J$76,'All Videos'!$S$5:$S$76,A35) -> 4011 | D35: =IF(SUM('All Videos'!$J$5:$J$76)=0,0,C35/SUM('All Videos'!$J$5:$J$76)) -> 0.15379601 | E35: =IF(B35=0,0,C35/B35) -> 125.34375 | F35: =SUMIFS('All Videos'!$K$5:$K$76,'All Videos'!$S$5:$S$76,A35) -> 19.8788 | G35: =SUMIFS('All Videos'!$L$5:$L$76,'All Videos'!$S$5:$S$76,A35) -> 8 | H35: =IF(C35=0,0,G35/C35*1000) -> 1.9945151 | I35: =IFERROR(SUMPRODUCT(('All Videos'!$S$5:$S$76=A35)*'All Videos'!$M$5:$M$76*'All Videos'!$N$5:$N$76)/SUMIFS('All Videos'!$M$5:$M$76,'All Videos'!$S$5:$S$76,A35),0) -> 0.037273388 | J35: 4+ tags (often irrelevant: #minecraft #nfl #valve on cricket) ≈ 125 views per video vs ~555 for clean titles.
A37: 6) BY UPLOAD YEAR
A38: Group | B38: # videos | C38: Total views | D38: Share of views | E38: Avg views / video | F38: Watch time (hrs) | G38: Subs gained | H38: Subs per 1k views | I38: Weighted thumbnail CTR | J38: Verdict
A39: 2022 | B39: =COUNTIFS('All Videos'!$E$5:$E$76,A39) -> 11 | C39: =SUMIFS('All Videos'!$J$5:$J$76,'All Videos'!$E$5:$E$76,A39) -> 4910 | D39: =IF(SUM('All Videos'!$J$5:$J$76)=0,0,C39/SUM('All Videos'!$J$5:$J$76)) -> 0.18826687 | E39: =IF(B39=0,0,C39/B39) -> 446.36364 | F39: =SUMIFS('All Videos'!$K$5:$K$76,'All Videos'!$E$5:$E$76,A39) -> 29.0008 | G39: =SUMIFS('All Videos'!$L$5:$L$76,'All Videos'!$E$5:$E$76,A39) -> 6 | H39: =IF(C39=0,0,G39/C39*1000) -> 1.2219959 | I39: =IFERROR(SUMPRODUCT(('All Videos'!$E$5:$E$76=A39)*'All Videos'!$M$5:$M$76*'All Videos'!$N$5:$N$76)/SUMIFS('All Videos'!$M$5:$M$76,'All Videos'!$E$5:$E$76,A39),0) -> 0.035395053 | J39: Multi-game experimenting.
A40: 2023 | B40: =COUNTIFS('All Videos'!$E$5:$E$76,A40) -> 20 | C40: =SUMIFS('All Videos'!$J$5:$J$76,'All Videos'!$E$5:$E$76,A40) -> 10940 | D40: =IF(SUM('All Videos'!$J$5:$J$76)=0,0,C40/SUM('All Videos'!$J$5:$J$76)) -> 0.41947853 | E40: =IF(B40=0,0,C40/B40) -> 547 | F40: =SUMIFS('All Videos'!$K$5:$K$76,'All Videos'!$E$5:$E$76,A40) -> 20.0777 | G40: =SUMIFS('All Videos'!$L$5:$L$76,'All Videos'!$E$5:$E$76,A40) -> 12 | H40: =IF(C40=0,0,G40/C40*1000) -> 1.0968921 | I40: =IFERROR(SUMPRODUCT(('All Videos'!$E$5:$E$76=A40)*'All Videos'!$M$5:$M$76*'All Videos'!$N$5:$N$76)/SUMIFS('All Videos'!$M$5:$M$76,'All Videos'!$E$5:$E$76,A40),0) -> 0.073926454 | J40: Most uploads; one 8.6k-view outlier.
A41: 2024 | B41: =COUNTIFS('All Videos'!$E$5:$E$76,A41) -> 7 | C41: =SUMIFS('All Videos'!$J$5:$J$76,'All Videos'!$E$5:$E$76,A41) -> 451 | D41: =IF(SUM('All Videos'!$J$5:$J$76)=0,0,C41/SUM('All Videos'!$J$5:$J$76)) -> 0.017292945 | E41: =IF(B41=0,0,C41/B41) -> 64.428571 | F41: =SUMIFS('All Videos'!$K$5:$K$76,'All Videos'!$E$5:$E$76,A41) -> 3.4654 | G41: =SUMIFS('All Videos'!$L$5:$L$76,'All Videos'!$E$5:$E$76,A41) -> -1 | H41: =IF(C41=0,0,G41/C41*1000) -> -2.2172949 | I41: =IFERROR(SUMPRODUCT(('All Videos'!$E$5:$E$76=A41)*'All Videos'!$M$5:$M$76*'All Videos'!$N$5:$N$76)/SUMIFS('All Videos'!$M$5:$M$76,'All Videos'!$E$5:$E$76,A41),0) -> 0.053600993 | J41: Only 7 uploads — momentum lost right after the viral wave.
A42: 2025 | B42: =COUNTIFS('All Videos'!$E$5:$E$76,A42) -> 14 | C42: =SUMIFS('All Videos'!$J$5:$J$76,'All Videos'!$E$5:$E$76,A42) -> 4984 | D42: =IF(SUM('All Videos'!$J$5:$J$76)=0,0,C42/SUM('All Videos'!$J$5:$J$76)) -> 0.19110429 | E42: =IF(B42=0,0,C42/B42) -> 356 | F42: =SUMIFS('All Videos'!$K$5:$K$76,'All Videos'!$E$5:$E$76,A42) -> 3.2001 | G42: =SUMIFS('All Videos'!$L$5:$L$76,'All Videos'!$E$5:$E$76,A42) -> 1 | H42: =IF(C42=0,0,G42/C42*1000) -> 0.20064205 | I42: =IFERROR(SUMPRODUCT(('All Videos'!$E$5:$E$76=A42)*'All Videos'!$M$5:$M$76*'All Videos'!$N$5:$N$76)/SUMIFS('All Videos'!$M$5:$M$76,'All Videos'!$E$5:$E$76,A42),0) -> 0.0045298643 | J42: Comeback with the umpire format.
A43: 2026 | B43: =COUNTIFS('All Videos'!$E$5:$E$76,A43) -> 20 | C43: =SUMIFS('All Videos'!$J$5:$J$76,'All Videos'!$E$5:$E$76,A43) -> 4795 | D43: =IF(SUM('All Videos'!$J$5:$J$76)=0,0,C43/SUM('All Videos'!$J$5:$J$76)) -> 0.18385736 | E43: =IF(B43=0,0,C43/B43) -> 239.75 | F43: =SUMIFS('All Videos'!$K$5:$K$76,'All Videos'!$E$5:$E$76,A43) -> 8.8718 | G43: =SUMIFS('All Videos'!$L$5:$L$76,'All Videos'!$E$5:$E$76,A43) -> 2 | H43: =IF(C43=0,0,G43/C43*1000) -> 0.41710115 | I43: =IFERROR(SUMPRODUCT(('All Videos'!$E$5:$E$76=A43)*'All Videos'!$M$5:$M$76*'All Videos'!$N$5:$N$76)/SUMIFS('All Videos'!$M$5:$M$76,'All Videos'!$E$5:$E$76,A43),0) -> 0.036672306 | J43: Consistent in May–June, then stopped.
A44: Weighted thumbnail CTR = clicks ÷ impressions for the whole group, so videos with more impressions count more. For Shorts it is not meaningful (see All Videos notes).

Sheet Deep Analysis
A1: DEEP ANALYSIS — what your data is really saying
A2: Each finding: the evidence from YOUR numbers → why it matters → what to change on the new channel.
A4: # | B4: Type | C4: Finding | D4: Evidence (your data) | E4: Why it matters | F4: What to do on the new channel
A5: 1 | B5: STRENGTH | C5: You already found a winning angle: the umpire / "Out or Not Out?" debate | D5: 26 umpire/decision clips = 17,191 views (~66% of all per-video views), avg ~660 views each vs ~160 for other cricket clips. 4 of your top 5 videos are this angle. | E5: A debatable moment makes people re-watch, judge and argue. That is exactly what the Shorts feed rewards: re-watches and engagement. | F5: Make it an official, named SERIES (e.g. "OUT or NOT OUT? #12"). Same opening frame, same verdict sticker, ask viewers to vote in comments every time.
A6: 2 | B6: STRENGTH | C6: Ultra-short clips get near-100% completion and loops | D6: "Umpire Caught Cheating" (3 sec): ~99% avg viewed, 8,609 views. 0–10 sec clips are your highest views-per-video bucket. | E6: Completion and re-watch rate are the strongest Shorts signals, so tiny loops get distributed. | F6: Keep the loop-able payoff, but wrap it in 12–25 sec: 1-sec hook text → replay → slow-mo → your verdict. More context = more watch time + more reason to subscribe.
A7: 3 | B7: WEAKNESS | C7: Reach does not turn into fans | D7: 51 subs from 29,044 views (≈1.8 per 1,000 views). Avg ≈10 sec watched per view. Most top clips gained 0–1 subs. | E7: Shorts viewers subscribe to a PERSON or SERIES, not a random clip. Without a voice, face, channel identity or call-to-action there is nothing to follow. | F7: Add your voice (live commentary or a 2-word reaction), consistent branding, a pinned comment, and link every Short to a related long video (Related Video feature).
A8: 4 | B8: WEAKNESS | C8: Inconsistent uploading = views drop to zero | D8: Views jump in upload months then crash: Nov 2025 4,781 → Dec 201 → Jan 14. 2025 Jan–Oct: under 15 views/month with no uploads. | E8: The algorithm tests each new video. Stop uploading and you stop getting tests. After a viral spike, new viewers found almost nothing new to watch. | F8: Batch-record and schedule. Minimum 3 Shorts + 1 long video per week for 90 days. Keep a backlog of 10 clips so a viral moment is never wasted.
A9: 5 | B9: WEAKNESS | C9: Titles were hurting discovery | D9: Clean titles: 32 videos, avg ~555 views. Hashtag-stuffed titles (4+ tags): 32 videos, avg ~125, less than a quarter. Many tags were irrelevant (#minecraft, #nfl, #valve, #mcoc on cricket clips). | E9: Irrelevant tags confuse who YouTube shows the video to, and clutter the title people read. Unrelated tags can also count as misleading metadata. | F9: Title = one punchy human sentence + max 1–2 RELEVANT tags (#cricket, #shorts). Put extra keywords in the description.
A10: 6 | B10: WEAKNESS | C10: Long-form loses viewers fast | D10: 5 long videos: estimated avg viewed 4–18% (27-min Smash Hit video: 145 views, ~70 sec watched). | E10: Low retention tells YouTube not to recommend the video further. Raw unedited gameplay rarely holds strangers. | F10: Long-form must have a STORY: challenge, career mode arc, "I simulated…", top-10 compilations. Cut dead time hard; target 8–12 min, 35%+ avg viewed.
A11: 7 | B11: STRENGTH | C11: Your packaging can earn clicks | D11: Long-form CTR: 15.6%, 7.9%, 7.4% on small impression counts; the Shorts winner "Umpire Caught Cheating" had 8.3%. Reported gaming organic average ≈ 8.5%. | E11: CTR is half the battle. You know how to make people curious ("Skill or Luck?", "THE TENTH WORLD WAR!"). | F11: Keep curiosity titles. Add readable thumbnails: 1 big face/emotion or the key frame + 3 words max.
A12: 8 | B12: RISK | C12: Profanity and "for views" titles | D12: "Plum LBW As F***ing Hell #2" 18 views, "Did it for views MOFOS" ~0, "I just want your attention MOFOS" 2 views. | E12: Profanity in titles/first seconds limits ads and can shrink the audience YouTube will test you with. "For views" titles signal low effort. | F12: Keep the attitude, drop the swearing in titles and thumbnails. Edgy-but-clean ("Umpire needs glasses 👓") travels further.
A13: 9 | B13: WEAKNESS | C13: Too many games, no identity (2022–23) | D13: Smash Hit (14 uploads, avg ≈140 views), MCOC (3, ≈137), CS:CZ (4, ≈670 but driven by one clip) vs Cricket 07 (50 uploads, 81% of views). | E13: YouTube needs to know who to show you to. Jumping between games resets your audience every time. | F13: Pick ONE pillar (cricket gaming) for the first 90 days. Other games only as a clearly separate playlist, if at all.
A14: 10 | B14: OPPORTUNITY | C14: Viral hits can come late and be re-tested | D14: "Umpire Caught Cheating": uploaded 18 Nov 2023, ~89% of its views came 2–5 months later. | E14: Shorts get re-tested with new audiences. A good clip is an asset, not a one-day lottery ticket. | F14: Never delete under-performers early. Re-cut winners into new versions (different hook text, different length) after 30–60 days.
A15: 11 | B15: OPPORTUNITY | C15: Ride the cricket calendar | D15: Your May–Jun 2026 run was your most consistent and overlapped the IPL season; "Eventful First Over #ipl" got 730 views in a day. | E15: Search and feed interest in cricket spikes around the IPL, World Cups and big India series. | F15: Plan content around fixtures: recreate real controversial decisions in-game within 24 hrs ("We replayed last night's LBW in Cricket 07").
A16: 12 | B16: WEAKNESS | C16: Data you never tracked: comments, likes, shares, swipe rate | D16: The export has no likes, comments, shares, traffic sources or "viewed vs swiped away". | E16: Comments are the strongest sign of a community and they help you get recommended. You can't improve what you don't measure. | F16: See the Glossary & Missing Data tab for how to export these from Studio. Track them weekly on the new channel.

Sheet Market Research 2026
A1: MARKET RESEARCH — content creation, gaming & AI in 2026
A2: Research done Oct 2026. Many YouTube "benchmarks" come from tool vendors — treat numbers as directional, and trust your own analytics most.
A4: Area | B4: What the research says | C4: What it means for you | D4: Source
