Workbook

Sheet Start Here
A1: YouTube Channel Assessment & New-Channel Strategy
A2: Prepared October 2026 from your YouTube Studio export: 67 videos, 29,044 views, daily data Jul 2021 – Oct 2026.
B4: How to use this workbook
B5: Tab | C5: What you'll find | D5: Read it if you want to…
B6: Dashboard | C6: Headline stats, scorecard vs benchmarks, top 10 videos, 10 key findings, charts. | D6: Get the whole story in 2 minutes.
B7: Action Plan | C7: 17 prioritised actions, a 90-day plan, KPI targets, and a status tracker. | D7: Know exactly what to do next.
B8: Content Themes | C8: Which topics worked, with a verdict for each (Double down / Keep / Stop). | D8: Decide what to make.
B9: Format & Packaging | C9: Shorts vs long-form, titles, hashtags, emoji, video length, upload day. | D9: Improve titles, length and clicks.
B10: Timeline | C10: Views and uploads month by month, plus year-by-year. | D10: See how consistency affected views.
B11: Launch Velocity | C11: How fast your top videos got their views: feed spike vs evergreen. | D11: Understand why your #1 video was different.
B12: Video Data | C12: Every video with 29 columns of stats and calculations, filterable. | D12: Dig into any single video.
B13: Market Research | C13: 14 research findings on Shorts, CTR, AI, gaming and monetization in 2026, with sources. | D13: Understand the 2026 landscape.
B14: Data Gaps & How-To | C14: Metrics missing from the export (comments, retention…) and how to get them. | D14: Make the next analysis even sharper.
B15: Daily Views (raw) | C15: Raw daily views from YouTube. | D15: Check the source data.
B18: Colour legend
B19: Sample | C19: Green = strong / on track / double down
B20: Sample | C20: Yellow = average / close / be careful
B21: Sample | C21: Red = weak / fix / stop
B22: Sample | C22: Light blue = keep but repackage
B23: Sample | C23: Yellow cell + blue text = editable input or target
B24: Sample | C24: Navy header = raw data from YouTube
B25: Sample | C25: Blue header = calculated column
B27: Glossary
B28: Impressions | C28: How many times YouTube showed your thumbnail (home, suggested, search). Shorts-feed swipes are NOT counted.
B29: CTR | C29: Click-through rate = clicks ÷ impressions. Measures how good your title + thumbnail are.
B30: Avg view duration | C30: Watch time ÷ views. How long a typical viewer stayed.
B31: Avg % watched | C31: Avg view duration ÷ video length. Over 100% = people looped the Short.
B32: Subs per 1K views | C32: How well a video turns viewers into subscribers.
B33: Feed / swipe views | C33: Views that did not come from someone clicking a thumbnail, mostly the Shorts feed.
B34: Evergreen | C34: A video that keeps getting views for months, not just launch week.
B36: Method note: data was pulled from the YouTube Studio export you shared via Google Sheets (Table data, Chart data, Totals). Comments, likes and retention were not in that export; see "Data Gaps & How-To".

Sheet Dashboard
A1: Old Channel Performance: Dashboard
A2: Data: your YouTube Studio export (lifetime, Jul 2021 – Oct 2026). Every number below is a live formula linked to the other tabs.
B4: Headline numbers | F4: Scorecard vs 2026 benchmarks
B5: Metric | C5: Value | D5: What it means | F5: Metric | G5: You | H5: Benchmark | I5: Status
B6: Total views (channel) | C6: 29044 | D6: Lifetime views per YouTube's channel total. | F6: Thumbnail CTR | G6: =C11 -> 0.0544 | H6: 0.06 | I6: =IF(G6>=H6,"✅ On track",IF(G6>=0.04,"🟡 Close","🔴 Fix")) -> 🟡 Close
B7: Watch time (hours) | C7: 84.2106 | D7: Far from the 4,000-hour YPP threshold; long-form is the fix. | F7: Subs per 1K views | G7: =C13 -> 1.7559565 | H7: 2.27 | I7: =IF(G7>=H7,"✅ On track",IF(G7>=1.69,"🟡 Close","🔴 Fix")) -> 🟡 Close
B8: Subscribers gained | C8: 51 | D8: Net subscribers gained over the channel's life. | F8: Avg view duration, Shorts (sec) | G8: ='Format & Packaging'!F6 -> 6.6472486 | H8: 15 | I8: =IF(G8>=H8,"✅ On track",IF(G8>=8,"🟡 Close","🔴 Fix")) -> 🔴 Fix
B9: Videos analysed | C9: =COUNTA('Video Data'!$B$5:$B$71) -> 67 | D9: 62 Shorts + 5 long-form. | F9: % of views from top video | G9: =C16 -> 0.29641234 | H9: 0.15 | I9: =IF(G9<=H9,"✅ On track",IF(G9<=0.3,"🟡 Close","🔴 Fix")) -> 🟡 Close
B10: Thumbnail impressions | C10: 231269 | D10: Times YouTube showed your thumbnail (mainly browse/suggested; Shorts-feed views are not counted). | F10: Uploads in last 90 days | G10: =COUNTIF('Video Data'!$D$5:$D$71,">="&(DATE(2026,10,17)-90)) -> 0 | H10: 12 | I10: =IF(G10>=H10,"✅ On track",IF(G10>=4,"🟡 Close","🔴 Fix")) -> 🔴 Fix
B11: Thumbnail CTR | C11: 0.0544 | D11: Average range 4–6%; gaming norm ~8.5%. Your hit did 8.3%. | F11: On-niche share of views | G11: ='Content Themes'!D5+'Content Themes'!D6 -> 0.80544479 | H11: 0.9 | I11: =IF(G11>=H11,"✅ On track",IF(G11>=0.7,"🟡 Close","🔴 Fix")) -> 🟡 Close
B12: Avg views per video | C12: =AVERAGE('Video Data'!$K$5:$K$71) -> 389.25373 | D12: Skewed by one hit; see median. | F12: Benchmarks: CTR 6% = solid (typical 4–6%, gaming ~8.5%, focus-digital/subsub 2026). Subs/1K: long-form 2.27, Shorts 1.69 (Galloway). Shorts AVD 15s = a well-held 15–35s Short. Top-video share 15% = a healthy, non-hit-dependent channel. Uploads: ~1 per week minimum. Blue numbers are editable benchmarks.
B13: Subs per 1K views | C13: =C8/C6*1000 -> 1.7559565 | D13: About the Shorts benchmark (1.7). Long-form benchmark is ~2.3.
B14: Median views per video | C14: =MEDIAN('Video Data'!$K$5:$K$71) -> 129 | D14: The "typical" video. Half did worse than this.
B15: Avg view duration (sec) | C15: =C7*3600/C6 -> 10.437893 | D15: People watched for only seconds. Retention is the biggest gap.
B16: Share of views from #1 video | C16: ='Video Data'!K5/C6 -> 0.29641234 | D16: Extremely hit-driven: one video carried the channel.
B17: Share of views from top 6 videos | C17: =SUM('Video Data'!K5:K10)/C6 -> 0.57350916 | D17: Six videos = most of your views. The other 61 = the rest.
B19: Top 10 videos
B20: # | C20: Title | D20: Views | E20: CTR | F20: Theme
B21: 1 | C21: ='Video Data'!C5 -> Umpire Caught Cheating In Cricket 07 | D21: ='Video Data'!K5 -> 8609 | E21: =IF(ISNUMBER('Video Data'!R5),'Video Data'!R5,"–") -> 0.0829 | F21: ='Video Data'!H5 -> Cricket: Umpire/Decision Drama
B22: 2 | C22: ='Video Data'!C6 -> How Is That NOT OUT?! 😳 | D22: ='Video Data'!K6 -> 2006 | E22: =IF(ISNUMBER('Video Data'!R6),'Video Data'!R6,"–") -> 0.0125 | F22: ='Video Data'!H6 -> Cricket: Umpire/Decision Drama
B23: 3 | C23: ='Video Data'!C7 -> counter strike condition zero#counterstrike#counterstrikeconditionzero#shorts | D23: ='Video Data'!K7 -> 1603 | E23: =IF(ISNUMBER('Video Data'!R7),'Video Data'!R7,"–") -> 0.0088 | F23: ='Video Data'!H7 -> Counter-Strike: CZ
B24: 4 | C24: ='Video Data'!C8 -> The Calm Before LBW | D24: ='Video Data'!K8 -> 1585 | E24: =IF(ISNUMBER('Video Data'!R8),'Video Data'!R8,"–") -> 0 | F24: ='Video Data'!H8 -> Cricket: Umpire/Decision Drama
B25: 5 | C25: ='Video Data'!C9 -> BLIND UMPIRE | D25: ='Video Data'!K9 -> 1523 | E25: =IF(ISNUMBER('Video Data'!R9),'Video Data'!R9,"–") -> 0 | F25: ='Video Data'!H9 -> Cricket: Umpire/Decision Drama
B26: 6 | C26: ='Video Data'!C10 -> Plum LBW As F***ing Hell #1 | D26: ='Video Data'!K10 -> 1331 | E26: =IF(ISNUMBER('Video Data'!R10),'Video Data'!R10,"–") -> 0.036 | F26: ='Video Data'!H10 -> Cricket: Umpire/Decision Drama
B27: 7 | C27: ='Video Data'!C11 -> CRICKET 07 2011 THE TENTH WORLD WAR! | D27: ='Video Data'!K11 -> 937 | E27: =IF(ISNUMBER('Video Data'!R11),'Video Data'!R11,"–") -> 0.0786 | F27: ='Video Data'!H11 -> Cricket: Gameplay & Moments
B28: 8 | C28: ='Video Data'!C12 -> Impossible CS: Condition Zero Shot – You Won’t Believe This! | D28: ='Video Data'!K12 -> 779 | E28: =IF(ISNUMBER('Video Data'!R12),'Video Data'!R12,"–") -> 0.0084 | F28: ='Video Data'!H12 -> Counter-Strike: CZ
B29: 9 | C29: ='Video Data'!C13 -> Eventful First Over#shorts #ipl | D29: ='Video Data'!K13 -> 719 | E29: =IF(ISNUMBER('Video Data'!R13),'Video Data'!R13,"–") -> 0.0385 | F29: ='Video Data'!H13 -> Cricket: Gameplay & Moments
B30: 10 | C30: ='Video Data'!C14 -> EA SPORTS CRICKET 07 2011 world cup patch#wc2011#yt20 #easports #easportscricket07 #msdhoni#shorts | D30: ='Video Data'!K14 -> 502 | E30: =IF(ISNUMBER('Video Data'!R14),'Video Data'!R14,"–") -> 0.0488 | F30: ='Video Data'!H14 -> Cricket: Gameplay & Moments
B33: 10 key findings (the "so what")
B34: 1. Hit-driven channel | C34: One video ("Umpire Caught Cheating In Cricket 07", 8.6K views) = ~30% of all views. The top 6 = ~57%. You found a winning format but never built on it with follow-ups.
B35: 2. Your niche is cricket umpire drama | C35: Umpire/decision videos = 27 uploads and ~66% of video views, with the best CTR (6.9%). Game-hopping into Smash Hit, MCOC and Counter-Strike averaged ~140 views.
B36: 3. The evergreen hit worked differently | C36: Your #1 video got just 267 views in week 1, then grew for months (peaking in Mar 2024 with zero new uploads), from 91K impressions at an 8.3% CTR. Your other top Shorts died after 7 days.
B37: 4. Retention is the biggest gap | C37: Average view duration was only ~6.6 seconds on Shorts. Recent clips are 3–5 seconds long. Raw views look fine, but watch time (84 hours lifetime) and subscribers barely moved.
B38: 5. Clean titles beat hashtag titles about 5x | C38: Clean titles averaged 659 views at 7.3% CTR. Titles with 6+ hashtags averaged 135 views at 3.7% CTR. Question and outrage titles won ("How Is That NOT OUT?!").
B39: 6. Long-form = watch-time engine | C39: 5 long-form videos (7% of uploads) made ~30% of watch hours, with 46-second average views. "The Tenth World War" is your top watch-time video (9.8 hours).
B40: 7. Consistency = views | C40: Monthly uploads and views correlate at 0.67. Your best active month (Nov 2025, 4.8K views) had 13 uploads. Every quiet month fell to near zero.
B41: 8. CTR is average, not great | C41: 5.44% overall vs a ~8.5% gaming norm. Many Shorts show 0% CTR because their views came from swipes, not thumbnail clicks.
B42: 9. Subscriber conversion is weak | C42: About 1.8 subs per 1K views (51 subs from 29K views). Viewers had no reason to subscribe: no series, no voice, no recurring promise.
B43: 10. Monetization rules now reward long-form | C43: 2027 YPP rules: 1,000 subs plus 8,000 long-form watch hours (or 20M Shorts views in 90 days). Your old pace would never get there, so the new channel needs long-form from day one.
B45: ➡ See the "Action Plan" tab for exactly what to do on the new channel.

Sheet Action Plan
A1: Action Plan for Your New Channel
A2: Every action is tied to evidence from your old channel and/or the 2026 research. Do the P1s first. Use the Status column to track progress.
A4: # | B4: Priority | C4: Area | D4: Action (do this) | E4: Why: the evidence | F4: Target / KPI to track | G4: When | H4: Status
A5: 1 | B5: P1 | C5: Niche | D5: Pick ONE lane and stay in it for the first 30 videos: cricket gaming (umpire drama, wild moments, Cricket 26 + EA Cricket 07 nostalgia), with AI as an angle, not a separate topic. | E5: Cricket umpire/decision content was 66% of your views. Smash Hit, MCOC and off-topic posts averaged 11–140 views. Game-hopping confused the algorithm. | F5: ≥90% of uploads on-niche | G5: Week 0 | H5: Not started
A6: 2 | B6: P1 | C6: Hook | D6: Open every Short on the most shocking frame (the decision, the appeal, the replay) within 0.5 seconds. No intro, no run-up. | E6: In the Shorts feed the first frame works like a thumbnail. Swipe-away rate is the main Shorts signal. Your top Shorts got 90%+ of their views from the feed, not thumbnails. | F6: Viewed (vs swiped away) ≥ 70% | G6: Every Short | H6: Not started
A7: 3 | B7: P1 | C7: Length | D7: Make Shorts 15–35 seconds with a setup, the moment, a replay or reaction, and a payoff. Stop posting 3–5 second clips. | E7: Your 2025–26 clips averaged 4.4 seconds of watch per view. Watch time fell about 75% vs the old era and subs per 1K views collapsed. Ultra-short loops inflate raw views but build nothing. | F7: Avg view duration ≥ 12 seconds; avg % watched ≥ 80% | G7: Next 10 Shorts | H7: Not started
A8: 4 | B8: P1 | C8: Long-form | D8: Publish 1 long-form video per week (8–15 minutes): full matches with commentary, "Top 10 worst umpire calls", and Cricket 26 career-mode series. | E8: Your 5 long-form uploads (7% of videos) made ~30% of watch hours and converted ~1.8x more subs per view than your Shorts. The 2027 YPP rules need 8,000 long-form watch hours. Long-form converts ~35% more subs per view. | F8: 1/week; 4,000 watch hours in 12 months | G8: Weekly | H8: Not started
A9: 5 | B9: P1 | C9: Titles | D9: Write clean 30–50 character titles that open a curiosity loop or ask a question ("How Is That NOT OUT?!"). No hashtags in titles. Put 3 hashtags in the description. | E9: Clean titles averaged 659 views vs 135 for 6+-hashtag titles, and CTR was 7.3% vs 3.7%. Your best title is a question with outrage. | F9: Long-form CTR ≥ 7% | G9: Every upload | H9: Not started
A10: 6 | B10: P1 | C10: Consistency | D10: Commit to a fixed schedule: 4–5 Shorts plus 1 long-form per week, every week. Batch-record on weekends. | E10: Uploads and monthly views correlate at 0.67. Every quiet month dropped to near-zero views (Jul 2026: 32 views after a 2,358-view June). | F10: Zero missed weeks for 12 weeks | G10: Weekly | H10: Not started
A11: 7 | B11: P2 | C11: Series | D11: Turn your winners into named, numbered series: "Worst Umpire Decisions #1, #2…", "Cricket 07 Chaos", "AI Umpire vs Me". | E11: Your "Plum LBW #1" got 1,331 views. Series give viewers a reason to subscribe and come back, which feeds the satisfaction signal. | F11: ≥ 3 subs per 1K views | G11: Month 1 | H11: Not started
A12: 8 | B12: P2 | C12: Thumbnails | D12: For long-form, design 3 thumbnail variants per video (AI-assisted in Canva or Nano Banana) and use YouTube's Test & Compare. Use a big face or reaction, a red arrow on the moment, and 3 words max. | E12: Your evergreen hit won on CTR (8.3% at 91K impressions). Gaming niche CTR is about 8.5%. Your channel average is 5.4%. | F12: CTR ≥ 7%; winner kept after test | G12: Every long-form | H12: Not started
A13: 9 | B13: P2 | C13: Evergreen | D13: Make 1 in 4 videos evergreen: searchable topics people look up any time ("Cricket 07 2026 patch install", "best Cricket 26 settings", "funniest umpire bugs"). | E13: Your #1 video got only 267 views in week 1, then 8.3K more over months via browse and suggested. Feed-spike Shorts died within a week. | F13: ≥ 30% of monthly views from videos older than 30 days | G13: Month 1–3 | H13: Not started
A14: 10 | B14: P2 | C14: Voice / identity | D14: Add your voice: commentary, reactions or text callouts. Be a person viewers recognise, not an anonymous clip channel. | E14: YouTube's 2025/2026 inauthentic-content policy targets templated, low-effort content. Your clip uploads had no persona, so few viewers subscribed. | F14: Comments per 1K views ≥ 5 | G14: Month 1 | H14: Not started
A15: 11 | B15: P2 | C15: Engagement | D15: End every Short with a question ("OUT or NOT OUT? Comment 👇") and pin a comment. Reply to every comment in the first hour. | E15: Your outrage and question titles were your best performers. Comments and replies are satisfaction signals. | F15: Comments per 1K views ≥ 5 | G15: Every upload | H15: Not started
A16: 12 | B16: P2 | C16: AI workflow | D16: Run an AI pipeline: record a session, edit one long-form, use Opus Clip or CapCut to cut 3–5 Shorts with auto-captions, then AI-draft the title and thumbnail options. You make the final call. | E16: Turns 1 recording into 6 uploads and makes the consistent schedule realistic for a solo creator. Keep human judgment to stay clear of the "mass-produced" policy. | F16: 6 uploads per recording session | G16: Month 1 | H16: Not started
... A21: 17 | B21: P3 | C21: Kill rule | D21: If a theme gets 5 uploads below the channel median, drop it. If a video beats 2x the median, make 3 follow-ups within 2 weeks. | E21: You posted 14 Smash Hit videos with no traction, and you never followed up your 8.6K hit with a series. | F21: Applied monthly | G21: Monthly | H21: Not started
A24: Your first 90 days
B25: Days 1–30: Foundation | D25: Channel name, banner and trailer around ONE promise ("the funniest moments in cricket gaming"). 20 Shorts (15–35s) + 4 long-form. Launch 2 named series. Set up the AI editing pipeline.
B26: Days 31–60: Find the winners | D26: Double down on the top 20% of videos by CTR and retention. Make 3 follow-ups to any video above 2x the median. Start A/B thumbnail tests on every long-form. Try 2 AI-angle experiments.
B27: Days 61–90: Scale what works | D27: Drop the bottom themes (kill rule). Lock the schedule. Start cross-posting. Aim for 300+ subscribers and 500+ watch hours. Review the KPI targets below and reset goals.
A29: KPI targets: old channel vs new-channel goal
B30: Metric | D30: Old channel | E30: New-channel target | F30: Why this target
B31: Thumbnail CTR (all) | D31: =Dashboard!C11 -> 0.0544 | E31: 0.07 | F31: Gaming niche averages about 8.5%. Your hit did 8.3%.
B32: Avg view duration, Shorts (sec) | D32: ='Format & Packaging'!F6 -> 6.6472486 | E32: 12 | F32: Your Shorts averaged ~6.6s. 15–35s Shorts should hold 12s+.
B33: Subs per 1K views | D33: =Dashboard!C13 -> 1.7559565 | E33: 3 | F33: Old channel ~1.8. Long-form plus series should roughly double the Shorts benchmark.
B34: Uploads per month | D34: =ROUND(Dashboard!C9/51,1) -> 1.3 | E34: 20 | F34: Old: 67 uploads over ~51 months. New: 4–5 Shorts + 1 long-form per week.
B35: Watch hours per year | D35: =Dashboard!C7/4 -> 21.05265 | E35: 4000 | F35: Old: lifetime watch hours ÷ ~4 active years. Target is the full YPP threshold; 2027 rules need 8,000.
B36: % uploads on-niche | D36: ='Content Themes'!D5+'Content Themes'!D6 -> 0.80544479 | E36: 0.9 | F36: Focus trains the algorithm on your audience.
B38: Yellow cells with blue text are targets you can edit. "% uploads on-niche" for the old channel is approximated by the share of views from cricket themes.

Sheet Content Themes
A1: What Topics Worked?
A2: Every video is tagged with a theme. These numbers are live formulas over the Video Data tab. Green = strong, yellow = OK, red = weak.
A4: Content theme | B4: Videos | C4: Total views | D4: % of all views | E4: Avg views / video | F4: Best video views | G4: Watch hours | H4: Avg view duration (sec) | I4: Subs gained | J4: Subs per 1K views | K4: Impressions | L4: Weighted CTR | M4: Verdict | N4: Why (analyst notes)
A5: Cricket: Umpire/Decision Drama | B5: =COUNTIF('Video Data'!$H$5:$H$71,A5) -> 27 | C5: =SUMIF('Video Data'!$H$5:$H$71,A5,'Video Data'!$K$5:$K$71) -> 17230 | D5: =IFERROR(C5/$C$11,0) -> 0.66065951 | E5: =IFERROR(C5/B5,0) -> 638.14815 | F5: =_xlfn.MAXIFS('Video Data'!$K$5:$K$71,'Video Data'!$H$5:$H$71,A5) -> 8609 | G5: =SUMIF('Video Data'!$H$5:$H$71,A5,'Video Data'!$L$5:$L$71) -> 13.5866 | H5: =IFERROR(G5*3600/C5,0) -> 2.8387557 | I5: =SUMIF('Video Data'!$H$5:$H$71,A5,'Video Data'!$O$5:$O$71) -> 8 | J5: =IFERROR(I5/C5*1000,0) -> 0.46430644 | K5: =SUMIF('Video Data'!$H$5:$H$71,A5,'Video Data'!$Q$5:$Q$71) -> 128587 | L5: =IFERROR(SUMIF('Video Data'!$H$5:$H$71,A5,'Video Data'!$S$5:$S$71)/K5,0) -> 0.06906608 | M5: DOUBLE DOWN | N5: Your proven format. 4 of your 5 biggest videos. Outrage + a question ("How is that NOT OUT?!") earns the click and the comments. But the median is low: most uploads got under 100 views. The winners had a clear "wait, what?!" moment in the first second.
A6: Cricket: Gameplay & Moments | B6: =COUNTIF('Video Data'!$H$5:$H$71,A6) -> 16 | C6: =SUMIF('Video Data'!$H$5:$H$71,A6,'Video Data'!$K$5:$K$71) -> 3776 | D6: =IFERROR(C6/$C$11,0) -> 0.14478528 | E6: =IFERROR(C6/B6,0) -> 236 | F6: =_xlfn.MAXIFS('Video Data'!$K$5:$K$71,'Video Data'!$H$5:$H$71,A6) -> 937 | G6: =SUMIF('Video Data'!$H$5:$H$71,A6,'Video Data'!$L$5:$L$71) -> 26.6339 | H6: =IFERROR(G6*3600/C6,0) -> 25.392489 | I6: =SUMIF('Video Data'!$H$5:$H$71,A6,'Video Data'!$O$5:$O$71) -> 6 | J6: =IFERROR(I6/C6*1000,0) -> 1.5889831 | K6: =SUMIF('Video Data'!$H$5:$H$71,A6,'Video Data'!$Q$5:$Q$71) -> 39228 | L6: =IFERROR(SUMIF('Video Data'!$H$5:$H$71,A6,'Video Data'!$S$5:$S$71)/K6,0) -> 0.046701336 | M6: KEEP, REPACKAGE | N6: Gets your highest watch time per view, and the long-form "Tenth World War" video is your #1 watch-time video. Plain labels like "EA Cricket 07 Gameplay" did badly; story titles like "An Outstanding Collapse In Just 1 Over" did better.
A7: Counter-Strike: CZ | B7: =COUNTIF('Video Data'!$H$5:$H$71,A7) -> 4 | C7: =SUMIF('Video Data'!$H$5:$H$71,A7,'Video Data'!$K$5:$K$71) -> 2696 | D7: =IFERROR(C7/$C$11,0) -> 0.10337423 | E7: =IFERROR(C7/B7,0) -> 674 | F7: =_xlfn.MAXIFS('Video Data'!$K$5:$K$71,'Video Data'!$H$5:$H$71,A7) -> 1603 | G7: =SUMIF('Video Data'!$H$5:$H$71,A7,'Video Data'!$L$5:$L$71) -> 11.2559 | H7: =IFERROR(G7*3600/C7,0) -> 15.030134 | I7: =SUMIF('Video Data'!$H$5:$H$71,A7,'Video Data'!$O$5:$O$71) -> 2 | J7: =IFERROR(I7/C7*1000,0) -> 0.74183976 | K7: =SUMIF('Video Data'!$H$5:$H$71,A7,'Video Data'!$Q$5:$Q$71) -> 10401 | L7: =IFERROR(SUMIF('Video Data'!$H$5:$H$71,A7,'Video Data'!$S$5:$S$71)/K7,0) -> 0.0086530141 | M7: ONE-OFF SPIKE | N7: Strong average, but it is one Short (1,603 views in its first 2 days). CTR of 0.9% means people who saw the thumbnail did not click, so the views came from the feed. Not a repeatable pillar.
A8: Smash Hit | B8: =COUNTIF('Video Data'!$H$5:$H$71,A8) -> 14 | C8: =SUMIF('Video Data'!$H$5:$H$71,A8,'Video Data'!$K$5:$K$71) -> 1963 | D8: =IFERROR(C8/$C$11,0) -> 0.075268405 | E8: =IFERROR(C8/B8,0) -> 140.21429 | F8: =_xlfn.MAXIFS('Video Data'!$K$5:$K$71,'Video Data'!$H$5:$H$71,A8) -> 272 | G8: =SUMIF('Video Data'!$H$5:$H$71,A8,'Video Data'!$L$5:$L$71) -> 12.1717 | H8: =IFERROR(G8*3600/C8,0) -> 22.322017 | I8: =SUMIF('Video Data'!$H$5:$H$71,A8,'Video Data'!$O$5:$O$71) -> 3 | J8: =IFERROR(I8/C8*1000,0) -> 1.5282731 | K8: =SUMIF('Video Data'!$H$5:$H$71,A8,'Video Data'!$Q$5:$Q$71) -> 11514 | L8: =IFERROR(SUMIF('Video Data'!$H$5:$H$71,A8,'Video Data'!$S$5:$S$71)/K8,0) -> 0.045249262 | M8: STOP | N8: 14 uploads for ~140 views each: the most effort for the least return. Generic titles ("smash hit #smashhit…") give nobody a reason to click.
A9: Marvel Contest of Champions | B9: =COUNTIF('Video Data'!$H$5:$H$71,A9) -> 3 | C9: =SUMIF('Video Data'!$H$5:$H$71,A9,'Video Data'!$K$5:$K$71) -> 410 | D9: =IFERROR(C9/$C$11,0) -> 0.015720859 | E9: =IFERROR(C9/B9,0) -> 136.66667 | F9: =_xlfn.MAXIFS('Video Data'!$K$5:$K$71,'Video Data'!$H$5:$H$71,A9) -> 152 | G9: =SUMIF('Video Data'!$H$5:$H$71,A9,'Video Data'!$L$5:$L$71) -> 0.9662 | H9: =IFERROR(G9*3600/C9,0) -> 8.4837073 | I9: =SUMIF('Video Data'!$H$5:$H$71,A9,'Video Data'!$O$5:$O$71) -> 1 | J9: =IFERROR(I9/C9*1000,0) -> 2.4390244 | K9: =SUMIF('Video Data'!$H$5:$H$71,A9,'Video Data'!$Q$5:$Q$71) -> 7125 | L9: =IFERROR(SUMIF('Video Data'!$H$5:$H$71,A9,'Video Data'!$S$5:$S$71)/K9,0) -> 0.018947368 | M9: STOP | N9: Only 3 tests, no traction, CTR under 2%. It also splits the audience away from cricket.
A10: Other / Off-topic | B10: =COUNTIF('Video Data'!$H$5:$H$71,A10) -> 3 | C10: =SUMIF('Video Data'!$H$5:$H$71,A10,'Video Data'!$K$5:$K$71) -> 5 | D10: =IFERROR(C10/$C$11,0) -> 0.00019171779 | E10: =IFERROR(C10/B10,0) -> 1.6666667 | F10: =_xlfn.MAXIFS('Video Data'!$K$5:$K$71,'Video Data'!$H$5:$H$71,A10) -> 2 | G10: =SUMIF('Video Data'!$H$5:$H$71,A10,'Video Data'!$L$5:$L$71) -> 0.0015 | H10: =IFERROR(G10*3600/C10,0) -> 1.08 | I10: =SUMIF('Video Data'!$H$5:$H$71,A10,'Video Data'!$O$5:$O$71) -> 0 | J10: =IFERROR(I10/C10*1000,0) -> 0 | K10: =SUMIF('Video Data'!$H$5:$H$71,A10,'Video Data'!$Q$5:$Q$71) -> 13 | L10: =IFERROR(SUMIF('Video Data'!$H$5:$H$71,A10,'Video Data'!$S$5:$S$71)/K10,0) -> 0.15384615 | M10: AVOID | N10: Off-topic or untitled uploads ("November 5, 2025", "How's the view") average under 5 views. Every upload trains the algorithm on who your viewers are, so off-topic posts confuse it.
A11: ALL VIDEOS | B11: =SUM(B5:B10) -> 67 | C11: =SUM(C5:C10) -> 26080 | D11: =SUM(D5:D10) -> 1 | E11: =IFERROR(C11/B11,0) -> 389.25373 | F11: =MAX(F5:F10) -> 8609 | G11: =SUM(G5:G10) -> 64.6158 | H11: =IFERROR(G11*3600/C11,0) -> 8.9193589 | I11: =SUM(I5:I10) -> 20 | J11: =IFERROR(I11/C11*1000,0) -> 0.76687117 | K11: =SUM(K5:K10) -> 196868 | L11: =IFERROR(SUM('Video Data'!$S$5:$S$71)/K11,0) -> 0.058216673

Sheet Format & Packaging
A1: Format, Titles & Packaging: What Got Clicks?
A2: Each table groups your videos one way. Live formulas over Video Data. Small groups (n<5) are flagged; treat them as hints, not proof.
A4: 1. Shorts vs long-form
A5: Group | B5: Videos | C5: Total views | D5: Avg views / video | E5: Watch hours | F5: Avg view duration (sec) | G5: Subs per 1K views | H5: Impressions | I5: Weighted CTR | J5: Sample size
A6: Short | B6: =COUNTIF('Video Data'!$G$5:$G$71,A6) -> 62 | C6: =SUMIF('Video Data'!$G$5:$G$71,A6,'Video Data'!$K$5:$K$71) -> 24562 | D6: =IFERROR(C6/B6,0) -> 396.16129 | E6: =SUMIF('Video Data'!$G$5:$G$71,A6,'Video Data'!$L$5:$L$71) -> 45.3527 | F6: =IFERROR(E6*3600/C6,0) -> 6.6472486 | G6: =IFERROR(SUMIF('Video Data'!$G$5:$G$71,A6,'Video Data'!$O$5:$O$71)/C6*1000,0) -> 0.73283935 | H6: =SUMIF('Video Data'!$G$5:$G$71,A6,'Video Data'!$Q$5:$Q$71) -> 181887 | I6: =IFERROR(SUMIF('Video Data'!$G$5:$G$71,A6,'Video Data'!$S$5:$S$71)/H6,0) -> 0.057662175 | J6: =IF(B6<5,"⚠ small sample","OK") -> OK
A7: Long-form | B7: =COUNTIF('Video Data'!$G$5:$G$71,A7) -> 5 | C7: =SUMIF('Video Data'!$G$5:$G$71,A7,'Video Data'!$K$5:$K$71) -> 1518 | D7: =IFERROR(C7/B7,0) -> 303.6 | E7: =SUMIF('Video Data'!$G$5:$G$71,A7,'Video Data'!$L$5:$L$71) -> 19.2631 | F7: =IFERROR(E7*3600/C7,0) -> 45.683241 | G7: =IFERROR(SUMIF('Video Data'!$G$5:$G$71,A7,'Video Data'!$O$5:$O$71)/C7*1000,0) -> 1.3175231 | H7: =SUMIF('Video Data'!$G$5:$G$71,A7,'Video Data'!$Q$5:$Q$71) -> 14981 | I7: =IFERROR(SUMIF('Video Data'!$G$5:$G$71,A7,'Video Data'!$S$5:$S$71)/H7,0) -> 0.064948935 | J7: =IF(B7<5,"⚠ small sample","OK") -> OK
A8: 💡 Shorts brought the reach (most of your views), but people watched them for only ~6 seconds on average. Your 5 long-form videos averaged ~46 seconds per view and produced ~30% of your total watch hours from just 7% of uploads. Shorts get discovered; long-form builds watch time (the 4,000-hour monetization path).
A10: 2. Old era vs new era
A11: Group | B11: Videos | C11: Total views | D11: Avg views / video | E11: Watch hours | F11: Avg view duration (sec) | G11: Subs per 1K views | H11: Impressions | I11: Weighted CTR | J11: Sample size
A12: 2022–24: mixed games, hashtag titles | B12: =COUNTIF('Video Data'!$I$5:$I$71,A12) -> 37 | C12: =SUMIF('Video Data'!$I$5:$I$71,A12,'Video Data'!$K$5:$K$71) -> 16301 | D12: =IFERROR(C12/B12,0) -> 440.56757 | E12: =SUMIF('Video Data'!$I$5:$I$71,A12,'Video Data'!$L$5:$L$71) -> 52.5439 | F12: =IFERROR(E12*3600/C12,0) -> 11.604076 | G12: =IFERROR(SUMIF('Video Data'!$I$5:$I$71,A12,'Video Data'!$O$5:$O$71)/C12*1000,0) -> 1.0428808 | H12: =SUMIF('Video Data'!$I$5:$I$71,A12,'Video Data'!$Q$5:$Q$71) -> 147736 | I12: =IFERROR(SUMIF('Video Data'!$I$5:$I$71,A12,'Video Data'!$S$5:$S$71)/H12,0) -> 0.065522283 | J12: =IF(B12<5,"⚠ small sample","OK") -> OK
A13: 2025–26: cricket focus, clean titles | B13: =COUNTIF('Video Data'!$I$5:$I$71,A13) -> 30 | C13: =SUMIF('Video Data'!$I$5:$I$71,A13,'Video Data'!$K$5:$K$71) -> 9779 | D13: =IFERROR(C13/B13,0) -> 325.96667 | E13: =SUMIF('Video Data'!$I$5:$I$71,A13,'Video Data'!$L$5:$L$71) -> 12.0719 | F13: =IFERROR(E13*3600/C13,0) -> 4.4440986 | G13: =IFERROR(SUMIF('Video Data'!$I$5:$I$71,A13,'Video Data'!$O$5:$O$71)/C13*1000,0) -> 0.30677983 | H13: =SUMIF('Video Data'!$I$5:$I$71,A13,'Video Data'!$Q$5:$Q$71) -> 49132 | I13: =IFERROR(SUMIF('Video Data'!$I$5:$I$71,A13,'Video Data'!$S$5:$S$71)/H13,0) -> 0.036249288 | J13: =IF(B13<5,"⚠ small sample","OK") -> OK
A14: 💡 Your 2025–26 videos are more focused, but they are also extremely short (often 3–5 seconds), so watch time dropped about 75% and subscriber conversion collapsed. Focus was the right move. The clips themselves need to be longer and give people a reason to stay.
A16: 3. Hashtags in the title
A17: Group | B17: Videos | C17: Total views | D17: Avg views / video | E17: Watch hours | F17: Avg view duration (sec) | G17: Subs per 1K views | H17: Impressions | I17: Weighted CTR | J17: Sample size
A18: 0 (clean title) | B18: =COUNTIF('Video Data'!$Y$5:$Y$71,A18) -> 27 | C18: =SUMIF('Video Data'!$Y$5:$Y$71,A18,'Video Data'!$K$5:$K$71) -> 17787 | D18: =IFERROR(C18/B18,0) -> 658.77778 | E18: =SUMIF('Video Data'!$Y$5:$Y$71,A18,'Video Data'!$L$5:$L$71) -> 31.4594 | F18: =IFERROR(E18*3600/C18,0) -> 6.3672255 | G18: =IFERROR(SUMIF('Video Data'!$Y$5:$Y$71,A18,'Video Data'!$O$5:$O$71)/C18*1000,0) -> 0.61842919 | H18: =SUMIF('Video Data'!$Y$5:$Y$71,A18,'Video Data'!$Q$5:$Q$71) -> 120234 | I18: =IFERROR(SUMIF('Video Data'!$Y$5:$Y$71,A18,'Video Data'!$S$5:$S$71)/H18,0) -> 0.072774756 | J18: =IF(B18<5,"⚠ small sample","OK") -> OK
A19: 1–2 | B19: =COUNTIF('Video Data'!$Y$5:$Y$71,A19) -> 5 | C19: =SUMIF('Video Data'!$Y$5:$Y$71,A19,'Video Data'!$K$5:$K$71) -> 2362 | D19: =IFERROR(C19/B19,0) -> 472.4 | E19: =SUMIF('Video Data'!$Y$5:$Y$71,A19,'Video Data'!$L$5:$L$71) -> 2.9638 | F19: =IFERROR(E19*3600/C19,0) -> 4.5172227 | G19: =IFERROR(SUMIF('Video Data'!$Y$5:$Y$71,A19,'Video Data'!$O$5:$O$71)/C19*1000,0) -> 0.42337003 | H19: =SUMIF('Video Data'!$Y$5:$Y$71,A19,'Video Data'!$Q$5:$Q$71) -> 35224 | I19: =IFERROR(SUMIF('Video Data'!$Y$5:$Y$71,A19,'Video Data'!$S$5:$S$71)/H19,0) -> 0.036168521 | J19: =IF(B19<5,"⚠ small sample","OK") -> OK
A20: 3–5 | B20: =COUNTIF('Video Data'!$Y$5:$Y$71,A20) -> 7 | C20: =SUMIF('Video Data'!$Y$5:$Y$71,A20,'Video Data'!$K$5:$K$71) -> 2138 | D20: =IFERROR(C20/B20,0) -> 305.42857 | E20: =SUMIF('Video Data'!$Y$5:$Y$71,A20,'Video Data'!$L$5:$L$71) -> 10.8371 | F20: =IFERROR(E20*3600/C20,0) -> 18.247689 | G20: =IFERROR(SUMIF('Video Data'!$Y$5:$Y$71,A20,'Video Data'!$O$5:$O$71)/C20*1000,0) -> 0 | H20: =SUMIF('Video Data'!$Y$5:$Y$71,A20,'Video Data'!$Q$5:$Q$71) -> 7889 | I20: =IFERROR(SUMIF('Video Data'!$Y$5:$Y$71,A20,'Video Data'!$S$5:$S$71)/H20,0) -> 0.024717962 | J20: =IF(B20<5,"⚠ small sample","OK") -> OK
A21: 6+ | B21: =COUNTIF('Video Data'!$Y$5:$Y$71,A21) -> 28 | C21: =SUMIF('Video Data'!$Y$5:$Y$71,A21,'Video Data'!$K$5:$K$71) -> 3793 | D21: =IFERROR(C21/B21,0) -> 135.46429 | E21: =SUMIF('Video Data'!$Y$5:$Y$71,A21,'Video Data'!$L$5:$L$71) -> 19.3555 | F21: =IFERROR(E21*3600/C21,0) -> 18.37063 | G21: =IFERROR(SUMIF('Video Data'!$Y$5:$Y$71,A21,'Video Data'!$O$5:$O$71)/C21*1000,0) -> 2.1091484 | H21: =SUMIF('Video Data'!$Y$5:$Y$71,A21,'Video Data'!$Q$5:$Q$71) -> 33521 | I21: =IFERROR(SUMIF('Video Data'!$Y$5:$Y$71,A21,'Video Data'!$S$5:$S$71)/H21,0) -> 0.037051401 | J21: =IF(B21<5,"⚠ small sample","OK") -> OK
A22: 💡 Clean, readable titles beat hashtag-stuffed ones by about 5x on average views and roughly doubled CTR. The 28 titles with 6+ hashtags ("smash hit #smashhit #mediocre #yt20…") are your weakest group. Put 2–3 hashtags in the description instead.
A24: 4. Emoji in the title
A25: Group | B25: Videos | C25: Total views | D25: Avg views / video | E25: Watch hours | F25: Avg view duration (sec) | G25: Subs per 1K views | H25: Impressions | I25: Weighted CTR | J25: Sample size
A26: Yes | B26: =COUNTIF('Video Data'!$W$5:$W$71,A26) -> 16 | C26: =SUMIF('Video Data'!$W$5:$W$71,A26,'Video Data'!$K$5:$K$71) -> 3053 | D26: =IFERROR(C26/B26,0) -> 190.8125 | E26: =SUMIF('Video Data'!$W$5:$W$71,A26,'Video Data'!$L$5:$L$71) -> 1.8361 | F26: =IFERROR(E26*3600/C26,0) -> 2.1650704 | G26: =IFERROR(SUMIF('Video Data'!$W$5:$W$71,A26,'Video Data'!$O$5:$O$71)/C26*1000,0) -> 0.32754668 | H26: =SUMIF('Video Data'!$W$5:$W$71,A26,'Video Data'!$Q$5:$Q$71) -> 1847 | I26: =IFERROR(SUMIF('Video Data'!$W$5:$W$71,A26,'Video Data'!$S$5:$S$71)/H26,0) -> 0.027612344 | J26: =IF(B26<5,"⚠ small sample","OK") -> OK
A27: No | B27: =COUNTIF('Video Data'!$W$5:$W$71,A27) -> 51 | C27: =SUMIF('Video Data'!$W$5:$W$71,A27,'Video Data'!$K$5:$K$71) -> 23027 | D27: =IFERROR(C27/B27,0) -> 451.5098 | E27: =SUMIF('Video Data'!$W$5:$W$71,A27,'Video Data'!$L$5:$L$71) -> 62.7797 | F27: =IFERROR(E27*3600/C27,0) -> 9.814866 | G27: =IFERROR(SUMIF('Video Data'!$W$5:$W$71,A27,'Video Data'!$O$5:$O$71)/C27*1000,0) -> 0.82511834 | H27: =SUMIF('Video Data'!$W$5:$W$71,A27,'Video Data'!$Q$5:$Q$71) -> 195021 | I27: =IFERROR(SUMIF('Video Data'!$W$5:$W$71,A27,'Video Data'!$S$5:$S$71)/H27,0) -> 0.05850652 | J27: =IF(B27<5,"⚠ small sample","OK") -> OK
A28: 💡 Titles with emoji averaged less than half the views. This is partly an era effect (most emoji titles are from late 2025), so treat it as "emoji don't replace a real hook", not "never use emoji".
A30: 5. Title length
A31: Group | B31: Videos | C31: Total views | D31: Avg views / video | E31: Watch hours | F31: Avg view duration (sec) | G31: Subs per 1K views | H31: Impressions | I31: Weighted CTR | J31: Sample size
A32: Short (≤30) | B32: =COUNTIF('Video Data'!$Z$5:$Z$71,A32) -> 15 | C32: =SUMIF('Video Data'!$Z$5:$Z$71,A32,'Video Data'!$K$5:$K$71) -> 7077 | D32: =IFERROR(C32/B32,0) -> 471.8 | E32: =SUMIF('Video Data'!$Z$5:$Z$71,A32,'Video Data'!$L$5:$L$71) -> 5.6074 | F32: =IFERROR(E32*3600/C32,0) -> 2.852429 | G32: =IFERROR(SUMIF('Video Data'!$Z$5:$Z$71,A32,'Video Data'!$O$5:$O$71)/C32*1000,0) -> 0.28260562 | H32: =SUMIF('Video Data'!$Z$5:$Z$71,A32,'Video Data'!$Q$5:$Q$71) -> 35744 | I32: =IFERROR(SUMIF('Video Data'!$Z$5:$Z$71,A32,'Video Data'!$S$5:$S$71)/H32,0) -> 0.035866159 | J32: =IF(B32<5,"⚠ small sample","OK") -> OK
A33: Medium (31–50) | B33: =COUNTIF('Video Data'!$Z$5:$Z$71,A33) -> 17 | C33: =SUMIF('Video Data'!$Z$5:$Z$71,A33,'Video Data'!$K$5:$K$71) -> 12190 | D33: =IFERROR(C33/B33,0) -> 717.05882 | E33: =SUMIF('Video Data'!$Z$5:$Z$71,A33,'Video Data'!$L$5:$L$71) -> 27.1465 | F33: =IFERROR(E33*3600/C33,0) -> 8.0170139 | G33: =IFERROR(SUMIF('Video Data'!$Z$5:$Z$71,A33,'Video Data'!$O$5:$O$71)/C33*1000,0) -> 0.57424118 | H33: =SUMIF('Video Data'!$Z$5:$Z$71,A33,'Video Data'!$Q$5:$Q$71) -> 114499 | I33: =IFERROR(SUMIF('Video Data'!$Z$5:$Z$71,A33,'Video Data'!$S$5:$S$71)/H33,0) -> 0.07582599 | J33: =IF(B33<5,"⚠ small sample","OK") -> OK
A34: Long (51+) | B34: =COUNTIF('Video Data'!$Z$5:$Z$71,A34) -> 35 | C34: =SUMIF('Video Data'!$Z$5:$Z$71,A34,'Video Data'!$K$5:$K$71) -> 6813 | D34: =IFERROR(C34/B34,0) -> 194.65714 | E34: =SUMIF('Video Data'!$Z$5:$Z$71,A34,'Video Data'!$L$5:$L$71) -> 31.8619 | F34: =IFERROR(E34*3600/C34,0) -> 16.835878 | G34: =IFERROR(SUMIF('Video Data'!$Z$5:$Z$71,A34,'Video Data'!$O$5:$O$71)/C34*1000,0) -> 1.6145604 | H34: =SUMIF('Video Data'!$Z$5:$Z$71,A34,'Video Data'!$Q$5:$Q$71) -> 46625 | I34: =IFERROR(SUMIF('Video Data'!$Z$5:$Z$71,A34,'Video Data'!$S$5:$S$71)/H34,0) -> 0.032107239 | J34: =IF(B34<5,"⚠ small sample","OK") -> OK
A35: 💡 Medium-length titles (31–50 characters) won clearly: highest average views and an 8% CTR. Very short titles ("BLIND UMPIRE") lacked context, and long ones were almost all hashtag-stuffed. Aim for 30–50 characters with the hook first.
A37: 6. Video length
A38: Group | B38: Videos | C38: Total views | D38: Avg views / video | E38: Watch hours | F38: Avg view duration (sec) | G38: Subs per 1K views | H38: Impressions | I38: Weighted CTR | J38: Sample size
A39: a) ≤10s | B39: =COUNTIF('Video Data'!$AA$5:$AA$71,A39) -> 36 | C39: =SUMIF('Video Data'!$AA$5:$AA$71,A39,'Video Data'!$K$5:$K$71) -> 16037 | D39: =IFERROR(C39/B39,0) -> 445.47222 | E39: =SUMIF('Video Data'!$AA$5:$AA$71,A39,'Video Data'!$L$5:$L$71) -> 13.6303 | F39: =IFERROR(E39*3600/C39,0) -> 3.0597418 | G39: =IFERROR(SUMIF('Video Data'!$AA$5:$AA$71,A39,'Video Data'!$O$5:$O$71)/C39*1000,0) -> 0.49884642 | H39: =SUMIF('Video Data'!$AA$5:$AA$71,A39,'Video Data'!$Q$5:$Q$71) -> 134598 | I39: =IFERROR(SUMIF('Video Data'!$AA$5:$AA$71,A39,'Video Data'!$S$5:$S$71)/H39,0) -> 0.067096094 | J39: =IF(B39<5,"⚠ small sample","OK") -> OK
A40: b) 11–30s | B40: =COUNTIF('Video Data'!$AA$5:$AA$71,A40) -> 8 | C40: =SUMIF('Video Data'!$AA$5:$AA$71,A40,'Video Data'!$K$5:$K$71) -> 2589 | D40: =IFERROR(C40/B40,0) -> 323.625 | E40: =SUMIF('Video Data'!$AA$5:$AA$71,A40,'Video Data'!$L$5:$L$71) -> 3.4755 | F40: =IFERROR(E40*3600/C40,0) -> 4.8326767 | G40: =IFERROR(SUMIF('Video Data'!$AA$5:$AA$71,A40,'Video Data'!$O$5:$O$71)/C40*1000,0) -> 1.1587486 | H40: =SUMIF('Video Data'!$AA$5:$AA$71,A40,'Video Data'!$Q$5:$Q$71) -> 12163 | I40: =IFERROR(SUMIF('Video Data'!$AA$5:$AA$71,A40,'Video Data'!$S$5:$S$71)/H40,0) -> 0.028446929 | J40: =IF(B40<5,"⚠ small sample","OK") -> OK
A41: c) 31–60s | B41: =COUNTIF('Video Data'!$AA$5:$AA$71,A41) -> 11 | C41: =SUMIF('Video Data'!$AA$5:$AA$71,A41,'Video Data'!$K$5:$K$71) -> 4054 | D41: =IFERROR(C41/B41,0) -> 368.54545 | E41: =SUMIF('Video Data'!$AA$5:$AA$71,A41,'Video Data'!$L$5:$L$71) -> 20.8357 | F41: =IFERROR(E41*3600/C41,0) -> 18.502348 | G41: =IFERROR(SUMIF('Video Data'!$AA$5:$AA$71,A41,'Video Data'!$O$5:$O$71)/C41*1000,0) -> 0.98667982 | H41: =SUMIF('Video Data'!$AA$5:$AA$71,A41,'Video Data'!$Q$5:$Q$71) -> 17234 | I41: =IFERROR(SUMIF('Video Data'!$AA$5:$AA$71,A41,'Video Data'!$S$5:$S$71)/H41,0) -> 0.025588952 | J41: =IF(B41<5,"⚠ small sample","OK") -> OK
A42: d) 61–180s | B42: =COUNTIF('Video Data'!$AA$5:$AA$71,A42) -> 7 | C42: =SUMIF('Video Data'!$AA$5:$AA$71,A42,'Video Data'!$K$5:$K$71) -> 1882 | D42: =IFERROR(C42/B42,0) -> 268.85714 | E42: =SUMIF('Video Data'!$AA$5:$AA$71,A42,'Video Data'!$L$5:$L$71) -> 7.4112 | F42: =IFERROR(E42*3600/C42,0) -> 14.176578 | G42: =IFERROR(SUMIF('Video Data'!$AA$5:$AA$71,A42,'Video Data'!$O$5:$O$71)/C42*1000,0) -> 1.5940489 | H42: =SUMIF('Video Data'!$AA$5:$AA$71,A42,'Video Data'!$Q$5:$Q$71) -> 17892 | I42: =IFERROR(SUMIF('Video Data'!$AA$5:$AA$71,A42,'Video Data'!$S$5:$S$71)/H42,0) -> 0.037446904 | J42: =IF(B42<5,"⚠ small sample","OK") -> OK
A43: e) Long-form 3m+ | B43: =COUNTIF('Video Data'!$AA$5:$AA$71,A43) -> 5 | C43: =SUMIF('Video Data'!$AA$5:$AA$71,A43,'Video Data'!$K$5:$K$71) -> 1518 | D43: =IFERROR(C43/B43,0) -> 303.6 | E43: =SUMIF('Video Data'!$AA$5:$AA$71,A43,'Video Data'!$L$5:$L$71) -> 19.2631 | F43: =IFERROR(E43*3600/C43,0) -> 45.683241 | G43: =IFERROR(SUMIF('Video Data'!$AA$5:$AA$71,A43,'Video Data'!$O$5:$O$71)/C43*1000,0) -> 1.3175231 | H43: =SUMIF('Video Data'!$AA$5:$AA$71,A43,'Video Data'!$Q$5:$Q$71) -> 14981 | I43: =IFERROR(SUMIF('Video Data'!$AA$5:$AA$71,A43,'Video Data'!$S$5:$S$71)/H43,0) -> 0.064948935 | J43: =IF(B43<5,"⚠ small sample","OK") -> OK
A44: 💡 ≤10-second clips have the highest average views (mostly thanks to your 3-second viral hit) because they loop. But viewers stayed only ~3 seconds and subs per 1K views were lowest. 11–60 second clips earned 2x the subscribers per view. Test 15–35 second Shorts with a setup, the moment, and a payoff or reaction.
A46: 7. Upload weekday (low confidence)
A47: Group | B47: Videos | C47: Total views | D47: Avg views / video | E47: Watch hours | F47: Avg view duration (sec) | G47: Subs per 1K views | H47: Impressions | I47: Weighted CTR | J47: Sample size
...

Sheet Timeline
A1: Channel Timeline: Views & Uploads by Month
A2: Monthly views come from your daily export; uploads are counted from Video Data. Look at how views follow upload bursts.
A4: Month | B4: Views | C4: Uploads | D4: Views per upload that month | E4: Note
A5: 44774 | B5: =SUMIFS('Daily Views (raw)'!$B$5:$B$1935,'Daily Views (raw)'!$A$5:$A$1935,">="&A5,'Daily Views (raw)'!$A$5:$A$1935,"<"&EDATE(A5,1)) -> 36 | C5: =COUNTIFS('Video Data'!$D$5:$D$71,">="&A5,'Video Data'!$D$5:$D$71,"<"&EDATE(A5,1)) -> 0 | D5: =IF(C5>0,B5/C5,"–") -> –
A6: 44805 | B6: =SUMIFS('Daily Views (raw)'!$B$5:$B$1935,'Daily Views (raw)'!$A$5:$A$1935,">="&A6,'Daily Views (raw)'!$A$5:$A$1935,"<"&EDATE(A6,1)) -> 84 | C6: =COUNTIFS('Video Data'!$D$5:$D$71,">="&A6,'Video Data'!$D$5:$D$71,"<"&EDATE(A6,1)) -> 1 | D6: =IF(C6>0,B6/C6,"–") -> 84
A7: 44835 | B7: =SUMIFS('Daily Views (raw)'!$B$5:$B$1935,'Daily Views (raw)'!$A$5:$A$1935,">="&A7,'Daily Views (raw)'!$A$5:$A$1935,"<"&EDATE(A7,1)) -> 53 | C7: =COUNTIFS('Video Data'!$D$5:$D$71,">="&A7,'Video Data'!$D$5:$D$71,"<"&EDATE(A7,1)) -> 0 | D7: =IF(C7>0,B7/C7,"–") -> –
A8: 44866 | B8: =SUMIFS('Daily Views (raw)'!$B$5:$B$1935,'Daily Views (raw)'!$A$5:$A$1935,">="&A8,'Daily Views (raw)'!$A$5:$A$1935,"<"&EDATE(A8,1)) -> 1202 | C8: =COUNTIFS('Video Data'!$D$5:$D$71,">="&A8,'Video Data'!$D$5:$D$71,"<"&EDATE(A8,1)) -> 3 | D8: =IF(C8>0,B8/C8,"–") -> 400.66667
A9: 44896 | B9: =SUMIFS('Daily Views (raw)'!$B$5:$B$1935,'Daily Views (raw)'!$A$5:$A$1935,">="&A9,'Daily Views (raw)'!$A$5:$A$1935,"<"&EDATE(A9,1)) -> 3193 | C9: =COUNTIFS('Video Data'!$D$5:$D$71,">="&A9,'Video Data'!$D$5:$D$71,"<"&EDATE(A9,1)) -> 6 | D9: =IF(C9>0,B9/C9,"–") -> 532.16667 | E9: Counter-Strike Short spike (1.5K views in 2 days)
A10: 44927 | B10: =SUMIFS('Daily Views (raw)'!$B$5:$B$1935,'Daily Views (raw)'!$A$5:$A$1935,">="&A10,'Daily Views (raw)'!$A$5:$A$1935,"<"&EDATE(A10,1)) -> 840 | C10: =COUNTIFS('Video Data'!$D$5:$D$71,">="&A10,'Video Data'!$D$5:$D$71,"<"&EDATE(A10,1)) -> 4 | D10: =IF(C10>0,B10/C10,"–") -> 210
A11: 44958 | B11: =SUMIFS('Daily Views (raw)'!$B$5:$B$1935,'Daily Views (raw)'!$A$5:$A$1935,">="&A11,'Daily Views (raw)'!$A$5:$A$1935,"<"&EDATE(A11,1)) -> 844 | C11: =COUNTIFS('Video Data'!$D$5:$D$71,">="&A11,'Video Data'!$D$5:$D$71,"<"&EDATE(A11,1)) -> 0 | D11: =IF(C11>0,B11/C11,"–") -> –
A12: 44986 | B12: =SUMIFS('Daily Views (raw)'!$B$5:$B$1935,'Daily Views (raw)'!$A$5:$A$1935,">="&A12,'Daily Views (raw)'!$A$5:$A$1935,"<"&EDATE(A12,1)) -> 731 | C12: =COUNTIFS('Video Data'!$D$5:$D$71,">="&A12,'Video Data'!$D$5:$D$71,"<"&EDATE(A12,1)) -> 2 | D12: =IF(C12>0,B12/C12,"–") -> 365.5
A13: 45017 | B13: =SUMIFS('Daily Views (raw)'!$B$5:$B$1935,'Daily Views (raw)'!$A$5:$A$1935,">="&A13,'Daily Views (raw)'!$A$5:$A$1935,"<"&EDATE(A13,1)) -> 675 | C13: =COUNTIFS('Video Data'!$D$5:$D$71,">="&A13,'Video Data'!$D$5:$D$71,"<"&EDATE(A13,1)) -> 3 | D13: =IF(C13>0,B13/C13,"–") -> 225
A14: 45047 | B14: =SUMIFS('Daily Views (raw)'!$B$5:$B$1935,'Daily Views (raw)'!$A$5:$A$1935,">="&A14,'Daily Views (raw)'!$A$5:$A$1935,"<"&EDATE(A14,1)) -> 453 | C14: =COUNTIFS('Video Data'!$D$5:$D$71,">="&A14,'Video Data'!$D$5:$D$71,"<"&EDATE(A14,1)) -> 2 | D14: =IF(C14>0,B14/C14,"–") -> 226.5
A15: 45078 | B15: =SUMIFS('Daily Views (raw)'!$B$5:$B$1935,'Daily Views (raw)'!$A$5:$A$1935,">="&A15,'Daily Views (raw)'!$A$5:$A$1935,"<"&EDATE(A15,1)) -> 89 | C15: =COUNTIFS('Video Data'!$D$5:$D$71,">="&A15,'Video Data'!$D$5:$D$71,"<"&EDATE(A15,1)) -> 0 | D15: =IF(C15>0,B15/C15,"–") -> –
A16: 45108 | B16: =SUMIFS('Daily Views (raw)'!$B$5:$B$1935,'Daily Views (raw)'!$A$5:$A$1935,">="&A16,'Daily Views (raw)'!$A$5:$A$1935,"<"&EDATE(A16,1)) -> 148 | C16: =COUNTIFS('Video Data'!$D$5:$D$71,">="&A16,'Video Data'!$D$5:$D$71,"<"&EDATE(A16,1)) -> 0 | D16: =IF(C16>0,B16/C16,"–") -> –
A17: 45139 | B17: =SUMIFS('Daily Views (raw)'!$B$5:$B$1935,'Daily Views (raw)'!$A$5:$A$1935,">="&A17,'Daily Views (raw)'!$A$5:$A$1935,"<"&EDATE(A17,1)) -> 176 | C17: =COUNTIFS('Video Data'!$D$5:$D$71,">="&A17,'Video Data'!$D$5:$D$71,"<"&EDATE(A17,1)) -> 0 | D17: =IF(C17>0,B17/C17,"–") -> –
A18: 45170 | B18: =SUMIFS('Daily Views (raw)'!$B$5:$B$1935,'Daily Views (raw)'!$A$5:$A$1935,">="&A18,'Daily Views (raw)'!$A$5:$A$1935,"<"&EDATE(A18,1)) -> 71 | C18: =COUNTIFS('Video Data'!$D$5:$D$71,">="&A18,'Video Data'!$D$5:$D$71,"<"&EDATE(A18,1)) -> 0 | D18: =IF(C18>0,B18/C18,"–") -> –
A19: 45200 | B19: =SUMIFS('Daily Views (raw)'!$B$5:$B$1935,'Daily Views (raw)'!$A$5:$A$1935,">="&A19,'Daily Views (raw)'!$A$5:$A$1935,"<"&EDATE(A19,1)) -> 488 | C19: =COUNTIFS('Video Data'!$D$5:$D$71,">="&A19,'Video Data'!$D$5:$D$71,"<"&EDATE(A19,1)) -> 3 | D19: =IF(C19>0,B19/C19,"–") -> 162.66667
A20: 45231 | B20: =SUMIFS('Daily Views (raw)'!$B$5:$B$1935,'Daily Views (raw)'!$A$5:$A$1935,">="&A20,'Daily Views (raw)'!$A$5:$A$1935,"<"&EDATE(A20,1)) -> 602 | C20: =COUNTIFS('Video Data'!$D$5:$D$71,">="&A20,'Video Data'!$D$5:$D$71,"<"&EDATE(A20,1)) -> 5 | D20: =IF(C20>0,B20/C20,"–") -> 120.4
A21: 45261 | B21: =SUMIFS('Daily Views (raw)'!$B$5:$B$1935,'Daily Views (raw)'!$A$5:$A$1935,">="&A21,'Daily Views (raw)'!$A$5:$A$1935,"<"&EDATE(A21,1)) -> 357 | C21: =COUNTIFS('Video Data'!$D$5:$D$71,">="&A21,'Video Data'!$D$5:$D$71,"<"&EDATE(A21,1)) -> 1 | D21: =IF(C21>0,B21/C21,"–") -> 357
A22: 45292 | B22: =SUMIFS('Daily Views (raw)'!$B$5:$B$1935,'Daily Views (raw)'!$A$5:$A$1935,">="&A22,'Daily Views (raw)'!$A$5:$A$1935,"<"&EDATE(A22,1)) -> 1033 | C22: =COUNTIFS('Video Data'!$D$5:$D$71,">="&A22,'Video Data'!$D$5:$D$71,"<"&EDATE(A22,1)) -> 3 | D22: =IF(C22>0,B22/C22,"–") -> 344.33333
A23: 45323 | B23: =SUMIFS('Daily Views (raw)'!$B$5:$B$1935,'Daily Views (raw)'!$A$5:$A$1935,">="&A23,'Daily Views (raw)'!$A$5:$A$1935,"<"&EDATE(A23,1)) -> 2410 | C23: =COUNTIFS('Video Data'!$D$5:$D$71,">="&A23,'Video Data'!$D$5:$D$71,"<"&EDATE(A23,1)) -> 0 | D23: =IF(C23>0,B23/C23,"–") -> – | E23: No uploads, but "Umpire Caught Cheating" took off in browse/suggested
A24: 45352 | B24: =SUMIFS('Daily Views (raw)'!$B$5:$B$1935,'Daily Views (raw)'!$A$5:$A$1935,">="&A24,'Daily Views (raw)'!$A$5:$A$1935,"<"&EDATE(A24,1)) -> 4607 | C24: =COUNTIFS('Video Data'!$D$5:$D$71,">="&A24,'Video Data'!$D$5:$D$71,"<"&EDATE(A24,1)) -> 0 | D24: =IF(C24>0,B24/C24,"–") -> – | E24: Best month ever, driven by the evergreen umpire video
A25: 45383 | B25: =SUMIFS('Daily Views (raw)'!$B$5:$B$1935,'Daily Views (raw)'!$A$5:$A$1935,">="&A25,'Daily Views (raw)'!$A$5:$A$1935,"<"&EDATE(A25,1)) -> 510 | C25: =COUNTIFS('Video Data'!$D$5:$D$71,">="&A25,'Video Data'!$D$5:$D$71,"<"&EDATE(A25,1)) -> 0 | D25: =IF(C25>0,B25/C25,"–") -> –
A26: 45413 | B26: =SUMIFS('Daily Views (raw)'!$B$5:$B$1935,'Daily Views (raw)'!$A$5:$A$1935,">="&A26,'Daily Views (raw)'!$A$5:$A$1935,"<"&EDATE(A26,1)) -> 87 | C26: =COUNTIFS('Video Data'!$D$5:$D$71,">="&A26,'Video Data'!$D$5:$D$71,"<"&EDATE(A26,1)) -> 2 | D26: =IF(C26>0,B26/C26,"–") -> 43.5
A27: 45444 | B27: =SUMIFS('Daily Views (raw)'!$B$5:$B$1935,'Daily Views (raw)'!$A$5:$A$1935,">="&A27,'Daily Views (raw)'!$A$5:$A$1935,"<"&EDATE(A27,1)) -> 24 | C27: =COUNTIFS('Video Data'!$D$5:$D$71,">="&A27,'Video Data'!$D$5:$D$71,"<"&EDATE(A27,1)) -> 1 | D27: =IF(C27>0,B27/C27,"–") -> 24
A28: 45474 | B28: =SUMIFS('Daily Views (raw)'!$B$5:$B$1935,'Daily Views (raw)'!$A$5:$A$1935,">="&A28,'Daily Views (raw)'!$A$5:$A$1935,"<"&EDATE(A28,1)) -> 38 | C28: =COUNTIFS('Video Data'!$D$5:$D$71,">="&A28,'Video Data'!$D$5:$D$71,"<"&EDATE(A28,1)) -> 0 | D28: =IF(C28>0,B28/C28,"–") -> –
A29: 45505 | B29: =SUMIFS('Daily Views (raw)'!$B$5:$B$1935,'Daily Views (raw)'!$A$5:$A$1935,">="&A29,'Daily Views (raw)'!$A$5:$A$1935,"<"&EDATE(A29,1)) -> 23 | C29: =COUNTIFS('Video Data'!$D$5:$D$71,">="&A29,'Video Data'!$D$5:$D$71,"<"&EDATE(A29,1)) -> 0 | D29: =IF(C29>0,B29/C29,"–") -> –
A30: 45536 | B30: =SUMIFS('Daily Views (raw)'!$B$5:$B$1935,'Daily Views (raw)'!$A$5:$A$1935,">="&A30,'Daily Views (raw)'!$A$5:$A$1935,"<"&EDATE(A30,1)) -> 16 | C30: =COUNTIFS('Video Data'!$D$5:$D$71,">="&A30,'Video Data'!$D$5:$D$71,"<"&EDATE(A30,1)) -> 0 | D30: =IF(C30>0,B30/C30,"–") -> –
A31: 45566 | B31: =SUMIFS('Daily Views (raw)'!$B$5:$B$1935,'Daily Views (raw)'!$A$5:$A$1935,">="&A31,'Daily Views (raw)'!$A$5:$A$1935,"<"&EDATE(A31,1)) -> 157 | C31: =COUNTIFS('Video Data'!$D$5:$D$71,">="&A31,'Video Data'!$D$5:$D$71,"<"&EDATE(A31,1)) -> 1 | D31: =IF(C31>0,B31/C31,"–") -> 157
A32: 45597 | B32: =SUMIFS('Daily Views (raw)'!$B$5:$B$1935,'Daily Views (raw)'!$A$5:$A$1935,">="&A32,'Daily Views (raw)'!$A$5:$A$1935,"<"&EDATE(A32,1)) -> 1 | C32: =COUNTIFS('Video Data'!$D$5:$D$71,">="&A32,'Video Data'!$D$5:$D$71,"<"&EDATE(A32,1)) -> 0 | D32: =IF(C32>0,B32/C32,"–") -> –
A33: 45627 | B33: =SUMIFS('Daily Views (raw)'!$B$5:$B$1935,'Daily Views (raw)'!$A$5:$A$1935,">="&A33,'Daily Views (raw)'!$A$5:$A$1935,"<"&EDATE(A33,1)) -> 9 | C33: =COUNTIFS('Video Data'!$D$5:$D$71,">="&A33,'Video Data'!$D$5:$D$71,"<"&EDATE(A33,1)) -> 0 | D33: =IF(C33>0,B33/C33,"–") -> –
A34: 45658 | B34: =SUMIFS('Daily Views (raw)'!$B$5:$B$1935,'Daily Views (raw)'!$A$5:$A$1935,">="&A34,'Daily Views (raw)'!$A$5:$A$1935,"<"&EDATE(A34,1)) -> 6 | C34: =COUNTIFS('Video Data'!$D$5:$D$71,">="&A34,'Video Data'!$D$5:$D$71,"<"&EDATE(A34,1)) -> 0 | D34: =IF(C34>0,B34/C34,"–") -> –
A35: 45689 | B35: =SUMIFS('Daily Views (raw)'!$B$5:$B$1935,'Daily Views (raw)'!$A$5:$A$1935,">="&A35,'Daily Views (raw)'!$A$5:$A$1935,"<"&EDATE(A35,1)) -> 4 | C35: =COUNTIFS('Video Data'!$D$5:$D$71,">="&A35,'Video Data'!$D$5:$D$71,"<"&EDATE(A35,1)) -> 0 | D35: =IF(C35>0,B35/C35,"–") -> –
A36: 45717 | B36: =SUMIFS('Daily Views (raw)'!$B$5:$B$1935,'Daily Views (raw)'!$A$5:$A$1935,">="&A36,'Daily Views (raw)'!$A$5:$A$1935,"<"&EDATE(A36,1)) -> 10 | C36: =COUNTIFS('Video Data'!$D$5:$D$71,">="&A36,'Video Data'!$D$5:$D$71,"<"&EDATE(A36,1)) -> 0 | D36: =IF(C36>0,B36/C36,"–") -> –
... A43: 45931 | B43: =SUMIFS('Daily Views (raw)'!$B$5:$B$1935,'Daily Views (raw)'!$A$5:$A$1935,">="&A43,'Daily Views (raw)'!$A$5:$A$1935,"<"&EDATE(A43,1)) -> 14 | C43: =COUNTIFS('Video Data'!$D$5:$D$71,">="&A43,'Video Data'!$D$5:$D$71,"<"&EDATE(A43,1)) -> 0 | D43: =IF(C43>0,B43/C43,"–") -> –
A44: 45962 | B44: =SUMIFS('Daily Views (raw)'!$B$5:$B$1935,'Daily Views (raw)'!$A$5:$A$1935,">="&A44,'Daily Views (raw)'!$A$5:$A$1935,"<"&EDATE(A44,1)) -> 4781 | C44: =COUNTIFS('Video Data'!$D$5:$D$71,">="&A44,'Video Data'!$D$5:$D$71,"<"&EDATE(A44,1)) -> 13 | D44: =IF(C44>0,B44/C44,"–") -> 367.76923 | E44: 13 uploads (cricket umpire burst): your best active month
A45: 45992 | B45: =SUMIFS('Daily Views (raw)'!$B$5:$B$1935,'Daily Views (raw)'!$A$5:$A$1935,">="&A45,'Daily Views (raw)'!$A$5:$A$1935,"<"&EDATE(A45,1)) -> 201 | C45: =COUNTIFS('Video Data'!$D$5:$D$71,">="&A45,'Video Data'!$D$5:$D$71,"<"&EDATE(A45,1)) -> 1 | D45: =IF(C45>0,B45/C45,"–") -> 201
A46: 46023 | B46: =SUMIFS('Daily Views (raw)'!$B$5:$B$1935,'Daily Views (raw)'!$A$5:$A$1935,">="&A46,'Daily Views (raw)'!$A$5:$A$1935,"<"&EDATE(A46,1)) -> 14 | C46: =COUNTIFS('Video Data'!$D$5:$D$71,">="&A46,'Video Data'!$D$5:$D$71,"<"&EDATE(A46,1)) -> 0 | D46: =IF(C46>0,B46/C46,"–") -> –
A47: 46054 | B47: =SUMIFS('Daily Views (raw)'!$B$5:$B$1935,'Daily Views (raw)'!$A$5:$A$1935,">="&A47,'Daily Views (raw)'!$A$5:$A$1935,"<"&EDATE(A47,1)) -> 7 | C47: =COUNTIFS('Video Data'!$D$5:$D$71,">="&A47,'Video Data'!$D$5:$D$71,"<"&EDATE(A47,1)) -> 0 | D47: =IF(C47>0,B47/C47,"–") -> –
...

Sheet Launch Velocity
A1: Launch Velocity: Spike vs Slow-Burn
A2: YouTube's export includes day-by-day views for your top 5 videos. This shows how fast each one got its views. Values come from the "Chart data" tab of your export.
A4: Video | B4: Published | C4: Lifetime views | D4: Views in first 7 days | E4: Views in first 30 days | F4: % of views in week 1 | G4: Peak day | H4: Peak-day views | I4: Pattern
A5: Umpire Caught Cheating In Cricket 07 | B5: 45248 | C5: 8609 | D5: 267 | E5: 426 | F5: =IFERROR(D5/C5,0) -> 0.031014055 | G5: 403 | I5: =IF(F5>=0.8,"⚡ Feed spike: got its views in days, then stopped","🌱 Evergreen slow-burn: kept growing for months") -> 🌱 Evergreen slow-burn: kept growing for months
A6: How Is That NOT OUT?! 😳 | B6: 45989 | C6: 2006 | D6: 2004 | E6: 2004 | F6: =IFERROR(D6/C6,0) -> 0.99900299 | G6: 1063 | I6: =IF(F6>=0.8,"⚡ Feed spike: got its views in days, then stopped","🌱 Evergreen slow-burn: kept growing for months") -> ⚡ Feed spike: got its views in days, then stopped
A7: counter strike condition zero#counterstrike#counterstrikeconditionzero#shorts | B7: 44901 | C7: 1603 | D7: 1553 | E7: 1555 | F7: =IFERROR(D7/C7,0) -> 0.96880848 | G7: 1549 | I7: =IF(F7>=0.8,"⚡ Feed spike: got its views in days, then stopped","🌱 Evergreen slow-burn: kept growing for months") -> ⚡ Feed spike: got its views in days, then stopped
A8: The Calm Before LBW | B8: 45970 | C8: 1585 | D8: 1585 | E8: 1585 | F8: =IFERROR(D8/C8,0) -> 1 | G8: 748 | I8: =IF(F8>=0.8,"⚡ Feed spike: got its views in days, then stopped","🌱 Evergreen slow-burn: kept growing for months") -> ⚡ Feed spike: got its views in days, then stopped
A9: BLIND UMPIRE | B9: 46187 | C9: 1523 | D9: 1523 | E9: 1523 | F9: =IFERROR(D9/C9,0) -> 1 | G9: 912 | I9: =IF(F9>=0.8,"⚡ Feed spike: got its views in days, then stopped","🌱 Evergreen slow-burn: kept growing for months") -> ⚡ Feed spike: got its views in days, then stopped
A11: 💡 The big lesson: 4 of your top 5 got nearly 100% of their views in the first week through the Shorts feed, then died. Your #1 video ("Umpire Caught Cheating") got only 267 views in week 1, then kept getting recommended for months. It peaked 4 months after upload and pulled 91K thumbnail impressions at an 8.3% CTR, the best click-through of any video with real reach. It had a clear, curiosity-driven title and a thumbnail people clicked. Build some videos to be evergreen: searchable titles, strong thumbnails, and a moment people want to see again.
A13: Monthly views: "Umpire Caught Cheating In Cricket 07" (the slow-burn)
A14: Month | B14: Views
A15: 45231 | B15: 330
A16: 45261 | B16: 243
A17: 45292 | B17: 636
A18: 45323 | B18: 2361
A19: 45352 | B19: 4520
A20: 45383 | B20: 481
A21: 45413 | B21: 0
A22: 45444 | B22: 2
A23: 45474 | B23: 0
A24: 45505 | B24: 1
A25: 45536 | B25: 0
A26: 45566 | B26: 5
... A34: 45809 | B34: 0

Sheet Video Data
A1: Every Video — Full Stats
A2: All 67 videos from your YouTube Studio export, sorted by views. Grey columns are raw data from YouTube; blue-header columns are calculated. Use the filter arrows to sort or slice.
A4: Rank | B4: Video ID | C4: Title | D4: Published | E4: Year | F4: Weekday | G4: Format | H4: Content theme | I4: Era | J4: Duration (sec) | K4: Views | L4: Watch time (hrs) | M4: Avg view duration (sec) | N4: Avg % of video watched | O4: Subs gained | P4: Subs per 1K views | Q4: Thumbnail impressions | R4: Thumbnail CTR | S4: Clicks from thumbnails | T4: Views NOT from thumbnail clicks (feed/swipe/other) | U4: % of views from feed/other | V4: Hashtags in title | W4: Emoji in title? | X4: Title length (chars) | Y4: Hashtag group | Z4: Title-length group | AA4: Length group | AB4: Performance tier | AC4: Watch
A5: 1 | B5: 9srtvMvNdHE | C5: Umpire Caught Cheating In Cricket 07 | D5: 45248 | E5: =YEAR(D5) -> 2023 | F5: =TEXT(D5,"ddd") -> Sat | G5: Short | H5: Cricket: Umpire/Decision Drama | I5: 2022–24: mixed games, hashtag titles | J5: 3 | K5: 8609 | L5: 7.1248 | M5: =IFERROR(L5*3600/K5,0) -> 2.9793565 | N5: =IFERROR(M5/J5,0) -> 0.99311883 | O5: 6 | P5: =IFERROR(O5/K5*1000,0) -> 0.69694506 | Q5: 91238 | R5: 0.0829 | S5: =IF(ISNUMBER(R5),ROUND(R5*Q5,0),0) -> 7564 | T5: =MAX(K5-S5,0) -> 1045 | U5: =IFERROR(T5/K5,0) -> 0.1213846 | V5: 0 | W5: No | X5: =LEN(C5) -> 36 | Y5: =IF(V5=0,"0 (clean title)",IF(V5<=2,"1–2",IF(V5<=5,"3–5","6+"))) -> 0 (clean title) | Z5: =IF(X5<=30,"Short (≤30)",IF(X5<=50,"Medium (31–50)","Long (51+)")) -> Medium (31–50) | AA5: =IF(J5<=10,"a) ≤10s",IF(J5<=30,"b) 11–30s",IF(J5<=60,"c) 31–60s",IF(J5<=180,"d) 61–180s","e) Long-form 3m+")))) -> a) ≤10s | AB5: =IF(K5>=1000,"Breakout (1K+)",IF(K5>=250,"Solid (250–999)",IF(K5>=100,"Average (100–249)","Low (<100)"))) -> Breakout (1K+) | AC5: =HYPERLINK("https://youtu.be/"&B5,"▶ Watch") -> ▶ Watch
A6: 2 | B6: uhVoNiY4MBg | C6: How Is That NOT OUT?! 😳 | D6: 45989 | E6: =YEAR(D6) -> 2025 | F6: =TEXT(D6,"ddd") -> Fri | G6: Short | H6: Cricket: Umpire/Decision Drama | I6: 2025–26: cricket focus, clean titles | J6: 5 | K6: 2006 | L6: 1.2016 | M6: =IFERROR(L6*3600/K6,0) -> 2.1564108 | N6: =IFERROR(M6/J6,0) -> 0.43128215 | O6: 1 | P6: =IFERROR(O6/K6*1000,0) -> 0.49850449 | Q6: 80 | R6: 0.0125 | S6: =IF(ISNUMBER(R6),ROUND(R6*Q6,0),0) -> 1 | T6: =MAX(K6-S6,0) -> 2005 | U6: =IFERROR(T6/K6,0) -> 0.9995015 | V6: 0 | W6: Yes | X6: =LEN(C6) -> 23 | Y6: =IF(V6=0,"0 (clean title)",IF(V6<=2,"1–2",IF(V6<=5,"3–5","6+"))) -> 0 (clean title) | Z6: =IF(X6<=30,"Short (≤30)",IF(X6<=50,"Medium (31–50)","Long (51+)")) -> Short (≤30) | AA6: =IF(J6<=10,"a) ≤10s",IF(J6<=30,"b) 11–30s",IF(J6<=60,"c) 31–60s",IF(J6<=180,"d) 61–180s","e) Long-form 3m+")))) -> a) ≤10s | AB6: =IF(K6>=1000,"Breakout (1K+)",IF(K6>=250,"Solid (250–999)",IF(K6>=100,"Average (100–249)","Low (<100)"))) -> Breakout (1K+) | AC6: =HYPERLINK("https://youtu.be/"&B6,"▶ Watch") -> ▶ Watch
A7: 3 | B7: RAfXFnj14Vo | C7: counter strike condition zero#counterstrike#counterstrikeconditionzero#shorts | D7: 44901 | E7: =YEAR(D7) -> 2022 | F7: =TEXT(D7,"ddd") -> Tue | G7: Short | H7: Counter-Strike: CZ | I7: 2022–24: mixed games, hashtag titles | J7: 57 | K7: 1603 | L7: 7.7609 | M7: =IFERROR(L7*3600/K7,0) -> 17.429345 | N7: =IFERROR(M7/J7,0) -> 0.30577798 | O7: 0 | P7: =IFERROR(O7/K7*1000,0) -> 0 | Q7: 2171 | R7: 0.0088 | S7: =IF(ISNUMBER(R7),ROUND(R7*Q7,0),0) -> 19 | T7: =MAX(K7-S7,0) -> 1584 | U7: =IFERROR(T7/K7,0) -> 0.98814722 | V7: 3 | W7: No | X7: =LEN(C7) -> 77 | Y7: =IF(V7=0,"0 (clean title)",IF(V7<=2,"1–2",IF(V7<=5,"3–5","6+"))) -> 3–5 | Z7: =IF(X7<=30,"Short (≤30)",IF(X7<=50,"Medium (31–50)","Long (51+)")) -> Long (51+) | AA7: =IF(J7<=10,"a) ≤10s",IF(J7<=30,"b) 11–30s",IF(J7<=60,"c) 31–60s",IF(J7<=180,"d) 61–180s","e) Long-form 3m+")))) -> c) 31–60s | AB7: =IF(K7>=1000,"Breakout (1K+)",IF(K7>=250,"Solid (250–999)",IF(K7>=100,"Average (100–249)","Low (<100)"))) -> Breakout (1K+) | AC7: =HYPERLINK("https://youtu.be/"&B7,"▶ Watch") -> ▶ Watch
A8: 4 | B8: ME765cmAuUY | C8: The Calm Before LBW | D8: 45970 | E8: =YEAR(D8) -> 2025 | F8: =TEXT(D8,"ddd") -> Sun | G8: Short | H8: Cricket: Umpire/Decision Drama | I8: 2025–26: cricket focus, clean titles | J8: 11 | K8: 1585 | L8: 1.3689 | M8: =IFERROR(L8*3600/K8,0) -> 3.1091735 | N8: =IFERROR(M8/J8,0) -> 0.28265214 | O8: 0 | P8: =IFERROR(O8/K8*1000,0) -> 0 | Q8: 25 | R8: 0 | S8: =IF(ISNUMBER(R8),ROUND(R8*Q8,0),0) -> 0 | T8: =MAX(K8-S8,0) -> 1585 | U8: =IFERROR(T8/K8,0) -> 1 | V8: 0 | W8: No | X8: =LEN(C8) -> 19 | Y8: =IF(V8=0,"0 (clean title)",IF(V8<=2,"1–2",IF(V8<=5,"3–5","6+"))) -> 0 (clean title) | Z8: =IF(X8<=30,"Short (≤30)",IF(X8<=50,"Medium (31–50)","Long (51+)")) -> Short (≤30) | AA8: =IF(J8<=10,"a) ≤10s",IF(J8<=30,"b) 11–30s",IF(J8<=60,"c) 31–60s",IF(J8<=180,"d) 61–180s","e) Long-form 3m+")))) -> b) 11–30s | AB8: =IF(K8>=1000,"Breakout (1K+)",IF(K8>=250,"Solid (250–999)",IF(K8>=100,"Average (100–249)","Low (<100)"))) -> Breakout (1K+) | AC8: =HYPERLINK("https://youtu.be/"&B8,"▶ Watch") -> ▶ Watch
A9: 5 | B9: JO21rkfLXIU | C9: BLIND UMPIRE | D9: 46187 | E9: =YEAR(D9) -> 2026 | F9: =TEXT(D9,"ddd") -> Sun | G9: Short | H9: Cricket: Umpire/Decision Drama | I9: 2025–26: cricket focus, clean titles | J9: 4 | K9: 1523 | L9: 1.1298 | M9: =IFERROR(L9*3600/K9,0) -> 2.6705712 | N9: =IFERROR(M9/J9,0) -> 0.66764281 | O9: 0 | P9: =IFERROR(O9/K9*1000,0) -> 0 | Q9: 116 | R9: 0 | S9: =IF(ISNUMBER(R9),ROUND(R9*Q9,0),0) -> 0 | T9: =MAX(K9-S9,0) -> 1523 | U9: =IFERROR(T9/K9,0) -> 1 | V9: 0 | W9: No | X9: =LEN(C9) -> 12 | Y9: =IF(V9=0,"0 (clean title)",IF(V9<=2,"1–2",IF(V9<=5,"3–5","6+"))) -> 0 (clean title) | Z9: =IF(X9<=30,"Short (≤30)",IF(X9<=50,"Medium (31–50)","Long (51+)")) -> Short (≤30) | AA9: =IF(J9<=10,"a) ≤10s",IF(J9<=30,"b) 11–30s",IF(J9<=60,"c) 31–60s",IF(J9<=180,"d) 61–180s","e) Long-form 3m+")))) -> a) ≤10s | AB9: =IF(K9>=1000,"Breakout (1K+)",IF(K9>=250,"Solid (250–999)",IF(K9>=100,"Average (100–249)","Low (<100)"))) -> Breakout (1K+) | AC9: =HYPERLINK("https://youtu.be/"&B9,"▶ Watch") -> ▶ Watch
