Workbook

Sheet Start Here
B1: Q2 2026 YouTube Performance Review · Apr 1 – Jun 30, 2026
B2: Built as a living workbook: paste your YouTube Studio numbers into the yellow cells and every chart, grade, colour and takeaway updates automatically.
B5: Data status | C5: =IF(COUNTA('Video Data'!$A$5:$A$204)=0,"No video data yet — follow Step 1 below.","✔ "&COUNTA('Video Data'!$A$5:$A$204)&" videos loaded. Open the Dashboard tab.") -> No video data yet — follow Step 1 below.
B7: How to use this workbook (about 15 minutes)
B8: STEP 1 — Per-video data (most important) | C8: YouTube Studio → Analytics → ADVANCED MODE → 'Content' tab → date range: Custom, Apr 1 2026 – Jun 30 2026. Click the '+' / metrics picker and add: Impressions, Impressions click-through rate, Average view duration, Average percentage viewed, Watch time (hours), Likes, Comments added, Shares, Subscribers gained, Subscribers lost, Estimated revenue (if monetised). Click the download icon (top right) → 'Comma-separated values (.csv)'.
B9: STEP 1b — Load it | C9: Easiest: run python import_studio_export.py YouTube_Q2_2026_Review.xlsx "Table data.csv" (maps columns automatically). Or copy each column from the CSV into the matching yellow column on the 'Video Data' tab (headers use YouTube's own names). Format column: type Long or Short, or leave blank (videos ≤ 3 min are treated as Shorts).
B10: STEP 2 — Monthly totals | C10: Studio → Analytics → Overview. Set the date range to April 2026 and copy the channel totals into the 'Monthly Trend' tab; repeat for May and June. Optional but recommended: also enter Q1 2026 (Jan 1 – Mar 31) to see quarter-over-quarter growth.
B11: STEP 3 — Traffic & audience | C11: Advanced mode, Apr 1 – Jun 30 2026: 'Traffic source' tab → views per source; Audience → New / Casual / Regular viewers; 'Device type' and 'Viewer age' tabs → views. Enter them in the 'Traffic & Audience' tab.
B12: STEP 4 — Read & act | C12: Dashboard → your Q2 story at a glance. Video Data → every video graded and diagnosed. Insights & Research → what's changing on YouTube and in AI. Q3 Action Plan → what to do. Q3 Scorecard → targets to track.
B13: Timing note | C13: Today Q3 (Jul–Sep 2026) has already closed. Use the Q3 Scorecard now to grade Q3 against Q2, then carry the open action items into Q4.
B15: Colour legend
B16: Yellow cell, blue text | C16: You type or paste here. These are the ONLY cells you need to edit.
B17: Grey header | C17: Calculated automatically — please don't type over these.
B18: Needs work | C18: Below typical creators — a priority for Q3.
B19: Average | C19: In the normal range — room to grow.
B20: Strong | C20: Above typical — protect and repeat what's working.
B21: Elite | C21: Top-tier — this is a signature strength.
B23: Example of one row on the Video Data tab (format guide only — not real data)
B24: Video title | C24: Publish date | D24: Format | E24: Duration (sec) | F24: Views | G24: Impressions | H24: CTR (%) | I24: Avg view duration | J24: Avg % viewed
B25: I tested 5 AI agents for a week | C25: 46126 | D25: Long | E25: 754 | F25: 18432 | G25: 241000 | H25: 5.8 | I25: 0.0026736111 | J25: 30.6
B26: Percentages are typed exactly as YouTube shows them: 5.8 means 5.8% (not 0.058). Average view duration can be pasted as 3:51 or 0:03:51.
B28: Tabs in this workbook
B29: Dashboard | C29: One-page Q2 summary: KPI tiles, auto-written takeaways, benchmark health check, long vs Shorts, top & bottom videos, timing patterns, charts.
B30: Video Data | C30: One row per video. Paste here. Each video gets graded on CTR, retention and engagement, scored 1–4 and diagnosed.
B31: Monthly Trend | C31: April / May / June channel totals, month-over-month change and Q2 vs Q1.
B32: Traffic & Audience | C32: Where views came from and who watched (new vs returning, device, age).
B33: Benchmarks | C33: The thresholds behind every grade, with sources. Edit them if your niche differs.
B34: Insights & Research | C34: Research on YouTube's 2026 changes, the creator economy and the AI space — and what each means for you.
B35: Q3 Action Plan | C35: Prioritised action items with owners, timing, KPI and status tracking.
B36: Q3 Scorecard | C36: Q2 baseline → Q3 targets → Q3 actuals, colour-coded on/off track.

Sheet Dashboard
B1: Q2 2026 YouTube Performance Dashboard · Apr 1 – Jun 30
B2: =IF(COUNTA('Video Data'!$A$5:$A$204)=0,"⚠ NO DATA YET — open the Start Here tab to load your YouTube Studio export. Everything on this page fills in automatically.","✔ "&COUNTA('Video Data'!$A$5:$A$204)&" videos analysed · "&COUNTIF('Video Data'!$S$5:$S$204,"Yes")&" published in Q2 · "&COUNTIF('Video Data'!$Q$5:$Q$204,"Long")&" long-form, "&COUNTIF('Video Data'!$Q$5:$Q$204,"Short")&" Shorts") -> ⚠ NO DATA YET — open the Start Here tab to load your YouTube Studio export. Everything on this page fills in automatically.
B4: Q2 at a glance
B5: VIEWS | E5: WATCH TIME (HOURS) | H5: NET SUBSCRIBERS | K5: EST. REVENUE (USD)
B6: =IF(N('Monthly Trend'!B8)>0,'Monthly Trend'!B8,SUM('Video Data'!$E$5:$E$204)) -> 0 | E6: =IF(N('Monthly Trend'!C8)>0,'Monthly Trend'!C8,SUM('Video Data'!$J$5:$J$204)) -> 0 | H6: =IF(N('Monthly Trend'!D8)+N('Monthly Trend'!E8)>0,'Monthly Trend'!F8,SUM('Video Data'!$X$5:$X$204)) -> 0 | K6: =IF(N('Monthly Trend'!K8)>0,'Monthly Trend'!K8,SUM('Video Data'!$P$5:$P$204)) -> 0
B7: =IF('Monthly Trend'!B10="","Add Q1 in Monthly Trend to compare",IF('Monthly Trend'!B10>=0,"▲ ","▼ ")&TEXT(ABS('Monthly Trend'!B10),"0.0")&"% vs Q1 2026") -> Add Q1 in Monthly Trend to compare | E7: =IF('Monthly Trend'!C10="","Add Q1 in Monthly Trend to compare",IF('Monthly Trend'!C10>=0,"▲ ","▼ ")&TEXT(ABS('Monthly Trend'!C10),"0.0")&"% vs Q1 2026") -> Add Q1 in Monthly Trend to compare | H7: =IF('Monthly Trend'!F10="","Add Q1 in Monthly Trend to compare",IF('Monthly Trend'!F10>=0,"▲ ","▼ ")&TEXT(ABS('Monthly Trend'!F10),"0.0")&"% vs Q1 2026") -> Add Q1 in Monthly Trend to compare | K7: =IF('Monthly Trend'!K10="","Add Q1 in Monthly Trend to compare",IF('Monthly Trend'!K10>=0,"▲ ","▼ ")&TEXT(ABS('Monthly Trend'!K10),"0.0")&"% vs Q1 2026") -> Add Q1 in Monthly Trend to compare
B9: IMPRESSIONS | E9: IMPRESSIONS CTR (LONG-FORM) | H9: AVG % VIEWED (LONG-FORM) | K9: ENGAGEMENT RATE
B10: =IF(N('Monthly Trend'!G8)>0,'Monthly Trend'!G8,SUM('Video Data'!$F$5:$F$204)) -> 0 | E10: =IFERROR(SUMPRODUCT(('Video Data'!$Q$5:$Q$204="Long")*'Video Data'!$F$5:$F$204*'Video Data'!$G$5:$G$204)/SUMIFS('Video Data'!$F$5:$F$204,'Video Data'!$Q$5:$Q$204,"Long",'Video Data'!$G$5:$G$204,">0"),IF(N('Monthly Trend'!H8)>0,'Monthly Trend'!H8,"")) | H10: =IFERROR(SUMPRODUCT(('Video Data'!$Q$5:$Q$204="Long")*'Video Data'!$E$5:$E$204*'Video Data'!$I$5:$I$204)/SUMIFS('Video Data'!$E$5:$E$204,'Video Data'!$Q$5:$Q$204,"Long",'Video Data'!$I$5:$I$204,">0"),"") | K10: =IFERROR((SUM('Video Data'!$K$5:$K$204)+SUM('Video Data'!$L$5:$L$204))/SUM('Video Data'!$E$5:$E$204)*100,"")
B11: =IF('Monthly Trend'!G10="","Add Q1 in Monthly Trend to compare",IF('Monthly Trend'!G10>=0,"▲ ","▼ ")&TEXT(ABS('Monthly Trend'!G10),"0.0")&"% vs Q1 2026") -> Add Q1 in Monthly Trend to compare | E11: =IF(E10="","—","Grade: "&$H$27&" (typical 4–6%)") -> — | H11: =IF(H10="","—","Grade: "&$H$28&" (good ≈ 30%+)") -> — | K11: =IF(K10="","—","Grade: "&$H$30&" (median ≈ 3.5%)") -> —
B14: Key takeaways — written automatically from your numbers
B15: =IF(E10="","• PACKAGING — add impressions + CTR on the Video Data tab to unlock this insight.","• PACKAGING — Long-form CTR was "&TEXT(E10,"0.0")&"% ("&H27&"; typical channels sit around 4–6%). "&IF(OR(H27="Needs work",H27="Average"),"Biggest quick win: run Test & Compare (3 titles + 3 thumbnails) on every new upload and re-package the "&L39&" video(s) flagged Great video, weak packaging.","Packaging is a strength — keep testing bolder variants, and never let a title over-promise.")) -> • PACKAGING — add impressions + CTR on the Video Data tab to unlock this insight.
B16: =IF(H10="","• RETENTION — add Average percentage viewed on the Video Data tab to unlock this insight.","• RETENTION — Long-form viewers watched "&TEXT(H10,"0.0")&"% of each video on average ("&H28&"; ~30% is good for long-form). "&IF(OR(H28="Needs work",H28="Average"),"Deliver the promised payoff inside 30 seconds, cut set-up, and add a pattern-break every 60–90s. Study the retention graphs of the "&L40&" Click-but-leave video(s) first.","Your content holds attention — lean into the formats behind your "&L38&" WINNER video(s).")) -> • RETENTION — add Average percentage viewed on the Video Data tab to unlock this insight.
B17: =IFERROR(IF(AND(E38=0,F38=0),"• FORMAT — no videos loaded yet.",IF(F38=0,"• FORMAT — no Shorts in Q2. Test 3 Shorts a week cut from your best long-form moments, each linked to the full video.",IF(E38=0,"• FORMAT — Shorts only in Q2. Long-form earns far more per view and builds deeper loyalty; add one long-form video a week.","• FORMAT — Long-form averaged "&TEXT(E40,"#,##0")&" views/video vs "&TEXT(F40,"#,##0")&" for Shorts; net subs per 1k views: long-form "&TEXT(E46,"0.0")&" vs Shorts "&TEXT(F46,"0.0")&". "&IF(F46>E46,"Shorts are your subscriber engine — keep them, but point every Short to a long-form video.","Long-form converts viewers into subscribers better — make it the core, use Shorts as trailers.")))),"• FORMAT — add views and subscriber data for both formats to compare.") -> • FORMAT — no videos loaded yet.
B18: =IFERROR(IF('Traffic & Audience'!B18="","• DISCOVERY — fill in the Traffic & Audience tab to see where viewers find you.","• DISCOVERY — "&'Traffic & Audience'!B18&" drove "&TEXT('Traffic & Audience'!B19,"0")&"% of views; YouTube search drove "&TEXT(N('Traffic & Audience'!E7),"0")&"%. "&IF(N('Traffic & Audience'!E7)<15,"Search is under-used: title one video a week around an exact query people type (e.g. 'how to … with [AI tool]').","Search is a real asset — group tutorials into playlists so search viewers keep watching.")),"• DISCOVERY — check the Traffic & Audience tab.") -> • DISCOVERY — fill in the Traffic & Audience tab to see where viewers find you.
B19: =IF(AND(D87="",K87=""),"• TIMING & LENGTH — add publish dates and durations to unlock this insight.","• TIMING & LENGTH — "&IF(D87="","",D87&" uploads averaged the most long-form views. ")&IF(K87="","","Best long-form length bucket: "&K87&". ")&"Treat these as hypotheses (small samples) and test them on purpose next quarter.") -> • TIMING & LENGTH — add publish dates and durations to unlock this insight.
B20: =IF('Monthly Trend'!B14="","• MOMENTUM — add monthly totals on the Monthly Trend tab to see your April→June trajectory.","• MOMENTUM — Views went "&IF('Monthly Trend'!B14>=0,"up ","down ")&TEXT(ABS('Monthly Trend'!B14),"0")&"% from April to June. "&IF('Monthly Trend'!B14>=0,"Keep the cadence and topics that drove this — consistency compounds.","Check what changed in May/June (topics, cadence, length); the Diagnosis column on Video Data shows which uploads dragged.")) -> • MOMENTUM — add monthly totals on the Monthly Trend tab to see your April→June trajectory.
B21: =IF(COUNT('Video Data'!$AC$5:$AC$204)=0,"• SCORECARD — load video data to see which videos to double down on.","• SCORECARD — "&L38&" WINNER video(s) (strong clicks AND strong retention): build sequels and series from them. "&L41&" topic miss(es): retire those angles. Every video is diagnosed on the Video Data tab.") -> • SCORECARD — load video data to see which videos to double down on.
B22: • Q3/Q4 CONTEXT — From Aug 24 2026 YouTube counts a view from the first frame, so post-Q2 view counts will look inflated vs this report. Judge growth on watch hours, CTR, % viewed and subscribers, not raw views. (Source: 9to5Google, Forbes, Aug 2026.)
B25: Health check vs industry benchmarks (thresholds on the Benchmarks tab)
B26: Metric | D26: Your Q2 | E26: Average from | F26: Strong from | G26: Elite from | H26: Grade | I26: What to do next
B27: Impressions CTR (long-form) | D27: =E10 | E27: =Benchmarks!C5 -> 4 | F27: =Benchmarks!D5 -> 6 | G27: =Benchmarks!E5 -> 9 | H27: =IF(D27="","—",IF(D27>=G27,"Elite",IF(D27>=F27,"Strong",IF(D27>=E27,"Average","Needs work")))) -> — | I27: =IF(H27="—","Add data to unlock advice.",IF(H27="Needs work","Packaging is the bottleneck. Use Test & Compare on every video; one clear idea per thumbnail (face + 3 words max); make the title a specific outcome or curiosity gap.",IF(H27="Average","In the normal range. Test bolder contrast & emotion in thumbnails and sharper, more specific titles. Re-package older videos that still get impressions.",IF(H27="Strong","Above typical. Keep the packaging formula; document what your winning thumbnails share and reuse it.","Elite packaging. Make sure retention keeps up so the click isn't wasted.")))) -> Add data to unlock advice.
B28: Avg % viewed (long-form) | D28: =H10 | E28: =Benchmarks!C6 -> 25 | F28: =Benchmarks!D6 -> 35 | G28: =Benchmarks!E6 -> 50 | H28: =IF(D28="","—",IF(D28>=G28,"Elite",IF(D28>=F28,"Strong",IF(D28>=E28,"Average","Needs work")))) -> — | I28: =IF(H28="—","Add data to unlock advice.",IF(H28="Needs work","Viewers leave early. Open with the payoff/result, cut intros & channel plugs, show-don't-tell demos, pattern-break every 60–90s.",IF(H28="Average","Normal. Find the biggest drop in each retention graph and fix that moment type in future scripts.",IF(H28="Strong","Strong. Test slightly longer, deeper videos — satisfied viewers watch more.","Elite. Your structure works — templatise it and scale output.")))) -> Add data to unlock advice.
B29: Avg % viewed (Shorts) | D29: =IFERROR(SUMPRODUCT(('Video Data'!$Q$5:$Q$204="Short")*'Video Data'!$E$5:$E$204*'Video Data'!$I$5:$I$204)/SUMIFS('Video Data'!$E$5:$E$204,'Video Data'!$Q$5:$Q$204,"Short",'Video Data'!$I$5:$I$204,">0"),"") | E29: =Benchmarks!C7 -> 50 | F29: =Benchmarks!D7 -> 70 | G29: =Benchmarks!E7 -> 90 | H29: =IF(D29="","—",IF(D29>=G29,"Elite",IF(D29>=F29,"Strong",IF(D29>=E29,"Average","Needs work")))) -> — | I29: =IF(H29="—","Add data to unlock advice.",IF(H29="Needs work","Shorts lose viewers fast. First frame = the most interesting moment; no intro; under 35s until retention improves.",IF(H29="Average","Normal. Tighten pacing and end on a loop that sends viewers back to the start.",IF(H29="Strong","Strong. Post more Shorts in this style and link them to related long-form.","Elite. Turn your best Shorts into full long-form deep-dives.")))) -> Add data to unlock advice.
B30: Engagement rate | D30: =K10 | E30: =Benchmarks!C8 -> 2.5 | F30: =Benchmarks!D8 -> 3.5 | G30: =Benchmarks!E8 -> 5 | H30: =IF(D30="","—",IF(D30>=G30,"Elite",IF(D30>=F30,"Strong",IF(D30>=E30,"Average","Needs work")))) -> — | I30: =IF(H30="—","Add data to unlock advice.",IF(H30="Needs work","Low reaction. Ask one specific question on screen, take a clear stance, pin a comment, and reply to the first hour of comments.",IF(H30="Average","Normal. Add a mid-video prompt ('which tool would you pick?') and reply to comments to seed discussion.",IF(H30="Strong","Strong. Mine comments for next video ideas and feature viewers in videos.","Elite. Your community is an asset — consider memberships, a Discord or a newsletter.")))) -> Add data to unlock advice.
B31: Comments per 1,000 views | D31: =IFERROR(SUM('Video Data'!$L$5:$L$204)/SUM('Video Data'!$E$5:$E$204)*1000,"") | E31: =Benchmarks!C9 -> 1 | F31: =Benchmarks!D9 -> 3 | G31: =Benchmarks!E9 -> 6 | H31: =IF(D31="","—",IF(D31>=G31,"Elite",IF(D31>=F31,"Strong",IF(D31>=E31,"Average","Needs work")))) -> — | I31: =IF(H31="—","Add data to unlock advice.",IF(H31="Needs work","Very few comments. End with a direct question, and use polls/community posts to warm up the audience.",IF(H31="Average","Normal. Run comment-driven segments ('you asked, I tested').",IF(H31="Strong","Strong. Turn top comments into Shorts and follow-ups.","Elite. Make community a pillar (live Q&As, viewer challenges).")))) -> Add data to unlock advice.
B32: Net subs per 1,000 views | D32: =IFERROR(H6/B6*1000,"") | E32: =Benchmarks!C10 -> 2 | F32: =Benchmarks!D10 -> 5 | G32: =Benchmarks!E10 -> 10 | H32: =IF(D32="","—",IF(D32>=G32,"Elite",IF(D32>=F32,"Strong",IF(D32>=E32,"Average","Needs work")))) -> — | I32: =IF(H32="—","Add data to unlock advice.",IF(H32="Needs work","Views aren't converting. Give a reason to subscribe (a series promise), use end screens to a playlist, and make channel-specific content, not one-offs.",IF(H32="Average","Normal. Add a mid-video 'this is part of a series' cue and a strong channel trailer.",IF(H32="Strong","Strong. Keep series formats; promote your best 'binge' playlist.","Elite. Your audience fit is excellent — scale frequency.")))) -> Add data to unlock advice.
B33: Returning viewers share | D33: ='Traffic & Audience'!B26 | E33: =Benchmarks!C11 -> 20 | F33: =Benchmarks!D11 -> 35 | G33: =Benchmarks!E11 -> 50 | H33: =IF(D33="","—",IF(D33>=G33,"Elite",IF(D33>=F33,"Strong",IF(D33>=E33,"Average","Needs work")))) -> — | I33: =IF(H33="—","Add data to unlock advice.",IF(H33="Needs work","Mostly one-time viewers. Build recurring series, a consistent upload day and community posts between uploads.",IF(H33="Average","Normal. Create a weekly signature format viewers can expect.",IF(H33="Strong","Strong loyalty. Use Hype, premieres and memberships to activate it.","Elite loyalty. Monetise depth: memberships, products, sponsorships.")))) -> Add data to unlock advice.
B36: Long-form vs Shorts | I36: Video scorecard mix (from Diagnosis column)
B37: Metric | E37: Long-form | F37: Shorts | G37: Edge | I37: Diagnosis | L37: Videos | M37: Next step
B38: Videos | E38: =COUNTIF('Video Data'!$Q$5:$Q$204,"Long") -> 0 | F38: =COUNTIF('Video Data'!$Q$5:$Q$204,"Short") -> 0 | G38: — | I38: WINNER | L38: =COUNTIF('Video Data'!$AD$5:$AD$204,"WINNER*") -> 0 | M38: Make sequels, a series, and Shorts from these.
B39: Total views | E39: =SUMIFS('Video Data'!$E$5:$E$204,'Video Data'!$Q$5:$Q$204,"Long") -> 0 | F39: =SUMIFS('Video Data'!$E$5:$E$204,'Video Data'!$Q$5:$Q$204,"Short") -> 0 | G39: =IF(OR(N(E39)=0,N(F39)=0),"",IF(E39>F39,"Long-form",IF(F39>E39,"Shorts","Tie"))) | I39: Great video, weak packaging | L39: =COUNTIF('Video Data'!$AD$5:$AD$204,"Great video*") -> 0 | M39: Fastest win: re-test title + thumbnail now.
B40: Avg views per video | E40: =IFERROR(E39/E38,"") | F40: =IFERROR(F39/F38,"") | G40: =IF(OR(E40="",F40=""),"",IF(E40>F40,"Long-form",IF(F40>E40,"Shorts","Tie"))) | I40: Click but leave | L40: =COUNTIF('Video Data'!$AD$5:$AD$204,"Click but leave*") -> 0 | M40: Fix the first 30s; make the title match the payoff.
B41: Watch time (hours) | E41: =SUMIFS('Video Data'!$J$5:$J$204,'Video Data'!$Q$5:$Q$204,"Long") -> 0 | F41: =SUMIFS('Video Data'!$J$5:$J$204,'Video Data'!$Q$5:$Q$204,"Short") -> 0 | G41: =IF(OR(N(E41)=0,N(F41)=0),"",IF(E41>F41,"Long-form",IF(F41>E41,"Shorts","Tie"))) | I41: Topic miss | L41: =COUNTIF('Video Data'!$AD$5:$AD$204,"Topic miss*") -> 0 | M41: Retire the angle; don't remake it.
B42: Avg % viewed (view-weighted) | E42: =IFERROR(SUMPRODUCT(('Video Data'!$Q$5:$Q$204="Long")*'Video Data'!$E$5:$E$204*'Video Data'!$I$5:$I$204)/SUMIFS('Video Data'!$E$5:$E$204,'Video Data'!$Q$5:$Q$204,"Long",'Video Data'!$I$5:$I$204,">0"),"") | F42: =IFERROR(SUMPRODUCT(('Video Data'!$Q$5:$Q$204="Short")*'Video Data'!$E$5:$E$204*'Video Data'!$I$5:$I$204)/SUMIFS('Video Data'!$E$5:$E$204,'Video Data'!$Q$5:$Q$204,"Short",'Video Data'!$I$5:$I$204,">0"),"") | G42: — | I42: Average (long-form) | L42: =COUNTIF('Video Data'!$AD$5:$AD$204,"Average*") -> 0 | M42: Sharpen hooks and titles.
B43: Engagement rate | E43: =IFERROR((SUMIFS('Video Data'!$K$5:$K$204,'Video Data'!$Q$5:$Q$204,"Long")+SUMIFS('Video Data'!$L$5:$L$204,'Video Data'!$Q$5:$Q$204,"Long"))/SUMIFS('Video Data'!$E$5:$E$204,'Video Data'!$Q$5:$Q$204,"Long")*100,"") | F43: =IFERROR((SUMIFS('Video Data'!$K$5:$K$204,'Video Data'!$Q$5:$Q$204,"Short")+SUMIFS('Video Data'!$L$5:$L$204,'Video Data'!$Q$5:$Q$204,"Short"))/SUMIFS('Video Data'!$E$5:$E$204,'Video Data'!$Q$5:$Q$204,"Short")*100,"") | G43: =IF(OR(E43="",F43=""),"",IF(E43>F43,"Long-form",IF(F43>E43,"Shorts","Tie"))) | I43: Winner Short | L43: =COUNTIF('Video Data'!$AD$5:$AD$204,"Winner Short*") -> 0 | M43: Expand into a long-form video.
B44: Comments per 1k views | E44: =IFERROR(SUMIFS('Video Data'!$L$5:$L$204,'Video Data'!$Q$5:$Q$204,"Long")/SUMIFS('Video Data'!$E$5:$E$204,'Video Data'!$Q$5:$Q$204,"Long")*1000,"") | F44: =IFERROR(SUMIFS('Video Data'!$L$5:$L$204,'Video Data'!$Q$5:$Q$204,"Short")/SUMIFS('Video Data'!$E$5:$E$204,'Video Data'!$Q$5:$Q$204,"Short")*1000,"") | G44: =IF(OR(E44="",F44=""),"",IF(E44>F44,"Long-form",IF(F44>E44,"Shorts","Tie"))) | I44: Hook problem (Short) | L44: =COUNTIF('Video Data'!$AD$5:$AD$204,"Hook problem*") -> 0 | M44: Start on the payoff; no intro.
B45: Net subscribers | E45: =SUMIFS('Video Data'!$X$5:$X$204,'Video Data'!$Q$5:$Q$204,"Long") -> 0 | F45: =SUMIFS('Video Data'!$X$5:$X$204,'Video Data'!$Q$5:$Q$204,"Short") -> 0 | G45: =IF(OR(N(E45)=0,N(F45)=0),"",IF(E45>F45,"Long-form",IF(F45>E45,"Shorts","Tie"))) | I45: Watched but no reaction (Short) | L45: =COUNTIF('Video Data'!$AD$5:$AD$204,"Watched but no reaction*") -> 0 | M45: End on a question or hot take.
B46: Net subs per 1k views | E46: =IFERROR(E45/E39*1000,"") | F46: =IFERROR(F45/F39*1000,"") | G46: =IF(OR(E46="",F46=""),"",IF(E46>F46,"Long-form",IF(F46>E46,"Shorts","Tie")))
B47: Revenue per 1k views (USD) | E47: =IFERROR(SUMIFS('Video Data'!$P$5:$P$204,'Video Data'!$Q$5:$Q$204,"Long")/SUMIFS('Video Data'!$E$5:$E$204,'Video Data'!$Q$5:$Q$204,"Long")*1000,"") | F47: =IFERROR(SUMIFS('Video Data'!$P$5:$P$204,'Video Data'!$Q$5:$Q$204,"Short")/SUMIFS('Video Data'!$E$5:$E$204,'Video Data'!$Q$5:$Q$204,"Short")*1000,"") | G47: =IF(OR(E47="",F47=""),"",IF(E47>F47,"Long-form",IF(F47>E47,"Shorts","Tie")))
B48: Avg % viewed isn't comparable across formats (Shorts loop). Shorts typically earn far less per view than long-form.
...

Sheet Video Data
A1: Video Data — one row per video (Q2 2026: Apr 1 – Jun 30)
A2: Paste/type into the yellow columns A–P (YouTube Studio → Analytics → Advanced mode → Content, date range Apr 1 – Jun 30 2026). Grey columns Q onward calculate automatically. Percentages as shown in Studio (5.8 = 5.8%).
A3: YOUR INPUTS (from YouTube Studio) | Q3: AUTO-CALCULATED (do not edit)
A4: Video title | B4: Video publish time | C4: Format (Long / Short) | D4: Duration (sec) | E4: Views | F4: Impressions | G4: Impressions click-through rate (%) | H4: Average view duration | I4: Average percentage viewed (%) | J4: Watch time (hours) | K4: Likes | L4: Comments added | M4: Shares | N4: Subscribers gained | O4: Subscribers lost | P4: Estimated revenue (USD) | Q4: Format used | R4: Length (min) | S4: Published in Q2? | T4: Publish day | U4: Long-form length bucket | V4: Engagement rate (%) | W4: Comments per 1k views | X4: Net subscribers | Y4: Net subs per 1k views | Z4: CTR grade | AA4: Retention grade | AB4: Engagement grade | AC4: Video score (1–4) | AD4: Diagnosis — what to do | AE4: Rank within format | AF4: CTR (eligible long-form) | AG4: CTR pts | AH4: Ret pts | AI4: Eng pts
Q5: =IF(A5="","",IF(C5<>"",C5,IF(AND(D5<>"",D5<=180),"Short","Long"))) | R5: =IF(OR(A5="",D5=""),"",D5/60) | S5: =IF(OR(A5="",B5=""),"",IF(AND(B5>=DATE(2026,4,1),B5<=DATE(2026,6,30)),"Yes","No")) | T5: =IF(OR(A5="",B5=""),"",CHOOSE(WEEKDAY(B5),"Sun","Mon","Tue","Wed","Thu","Fri","Sat")) | U5: =IF(OR(Q5<>"Long",D5=""),"",IF(D5<480,"Under 8 min",IF(D5<900,"8–15 min",IF(D5<1500,"15–25 min","25+ min")))) | V5: =IF(OR(A5="",N(E5)=0),"",(N(K5)+N(L5))/E5*100) | W5: =IF(OR(A5="",N(E5)=0),"",N(L5)/E5*1000) | X5: =IF(A5="","",N(N5)-N(O5)) | Y5: =IF(OR(A5="",N(E5)=0),"",X5/E5*1000) | Z5: =IF(OR(A5="",G5=""),"",IF(Q5="Short","n/a (Short)",IF(G5>=Benchmarks!$E$5,"Elite",IF(G5>=Benchmarks!$D$5,"Strong",IF(G5>=Benchmarks!$C$5,"Average","Needs work"))))) | AA5: =IF(OR(A5="",I5=""),"",IF(Q5="Short",IF(I5>=Benchmarks!$E$7,"Elite",IF(I5>=Benchmarks!$D$7,"Strong",IF(I5>=Benchmarks!$C$7,"Average","Needs work"))),IF(I5>=Benchmarks!$E$6,"Elite",IF(I5>=Benchmarks!$D$6,"Strong",IF(I5>=Benchmarks!$C$6,"Average","Needs work"))))) | AB5: =IF(V5="","",IF(V5>=Benchmarks!$E$8,"Elite",IF(V5>=Benchmarks!$D$8,"Strong",IF(V5>=Benchmarks!$C$8,"Average","Needs work")))) | AC5: =IF(COUNT(AG5:AI5)=0,"",AVERAGE(AG5:AI5)) | AD5: =IF(A5="","",IF(Q5="Short",IF(AH5="","Add % viewed to diagnose",IF(AND(AH5>=3,N(AI5)>=3),"Winner Short — expand it into a long-form video",IF(AH5<=1,"Hook problem — viewers swipe away in the first seconds",IF(AI5=1,"Watched but no reaction — end on a question or opinion","Solid Short — keep iterating")))),IF(OR(AG5="",AH5=""),"Add CTR & % viewed to diagnose",IF(AND(AG5>=3,AH5>=3),"WINNER — make a sequel, series or Shorts from it",IF(AND(AG5>=3,AH5<=2),"Click but leave — intro too slow or title over-promises",IF(AND(AG5<=2,AH5>=3),"Great video, weak packaging — A/B test title + thumbnail",IF(AND(AG5=1,AH5=1),"Topic miss — don't repeat this angle","Average — sharpen the hook and the title"))))))) | AE5: =IF(OR(A5="",N(E5)=0),"",Q5&"-"&(COUNTIFS($Q$5:$Q$204,Q5,$E$5:$E$204,">"&E5)+COUNTIFS($Q$5:Q5,Q5,$E$5:E5,E5))) | AF5: =IF(AND(Q5="Long",N(F5)>=Benchmarks!$C$15,G5<>""),G5,"") | AG5: =IF(Z5="Elite",4,IF(Z5="Strong",3,IF(Z5="Average",2,IF(Z5="Needs work",1,"")))) | AH5: =IF(AA5="Elite",4,IF(AA5="Strong",3,IF(AA5="Average",2,IF(AA5="Needs work",1,"")))) | AI5: =IF(AB5="Elite",4,IF(AB5="Strong",3,IF(AB5="Average",2,IF(AB5="Needs work",1,""))))
Q6: =IF(A6="","",IF(C6<>"",C6,IF(AND(D6<>"",D6<=180),"Short","Long"))) | R6: =IF(OR(A6="",D6=""),"",D6/60) | S6: =IF(OR(A6="",B6=""),"",IF(AND(B6>=DATE(2026,4,1),B6<=DATE(2026,6,30)),"Yes","No")) | T6: =IF(OR(A6="",B6=""),"",CHOOSE(WEEKDAY(B6),"Sun","Mon","Tue","Wed","Thu","Fri","Sat")) | U6: =IF(OR(Q6<>"Long",D6=""),"",IF(D6<480,"Under 8 min",IF(D6<900,"8–15 min",IF(D6<1500,"15–25 min","25+ min")))) | V6: =IF(OR(A6="",N(E6)=0),"",(N(K6)+N(L6))/E6*100) | W6: =IF(OR(A6="",N(E6)=0),"",N(L6)/E6*1000) | X6: =IF(A6="","",N(N6)-N(O6)) | Y6: =IF(OR(A6="",N(E6)=0),"",X6/E6*1000) | Z6: =IF(OR(A6="",G6=""),"",IF(Q6="Short","n/a (Short)",IF(G6>=Benchmarks!$E$5,"Elite",IF(G6>=Benchmarks!$D$5,"Strong",IF(G6>=Benchmarks!$C$5,"Average","Needs work"))))) | AA6: =IF(OR(A6="",I6=""),"",IF(Q6="Short",IF(I6>=Benchmarks!$E$7,"Elite",IF(I6>=Benchmarks!$D$7,"Strong",IF(I6>=Benchmarks!$C$7,"Average","Needs work"))),IF(I6>=Benchmarks!$E$6,"Elite",IF(I6>=Benchmarks!$D$6,"Strong",IF(I6>=Benchmarks!$C$6,"Average","Needs work"))))) | AB6: =IF(V6="","",IF(V6>=Benchmarks!$E$8,"Elite",IF(V6>=Benchmarks!$D$8,"Strong",IF(V6>=Benchmarks!$C$8,"Average","Needs work")))) | AC6: =IF(COUNT(AG6:AI6)=0,"",AVERAGE(AG6:AI6)) | AD6: =IF(A6="","",IF(Q6="Short",IF(AH6="","Add % viewed to diagnose",IF(AND(AH6>=3,N(AI6)>=3),"Winner Short — expand it into a long-form video",IF(AH6<=1,"Hook problem — viewers swipe away in the first seconds",IF(AI6=1,"Watched but no reaction — end on a question or opinion","Solid Short — keep iterating")))),IF(OR(AG6="",AH6=""),"Add CTR & % viewed to diagnose",IF(AND(AG6>=3,AH6>=3),"WINNER — make a sequel, series or Shorts from it",IF(AND(AG6>=3,AH6<=2),"Click but leave — intro too slow or title over-promises",IF(AND(AG6<=2,AH6>=3),"Great video, weak packaging — A/B test title + thumbnail",IF(AND(AG6=1,AH6=1),"Topic miss — don't repeat this angle","Average — sharpen the hook and the title"))))))) | AE6: =IF(OR(A6="",N(E6)=0),"",Q6&"-"&(COUNTIFS($Q$5:$Q$204,Q6,$E$5:$E$204,">"&E6)+COUNTIFS($Q$5:Q6,Q6,$E$5:E6,E6))) | AF6: =IF(AND(Q6="Long",N(F6)>=Benchmarks!$C$15,G6<>""),G6,"") | AG6: =IF(Z6="Elite",4,IF(Z6="Strong",3,IF(Z6="Average",2,IF(Z6="Needs work",1,"")))) | AH6: =IF(AA6="Elite",4,IF(AA6="Strong",3,IF(AA6="Average",2,IF(AA6="Needs work",1,"")))) | AI6: =IF(AB6="Elite",4,IF(AB6="Strong",3,IF(AB6="Average",2,IF(AB6="Needs work",1,""))))
Q7: =IF(A7="","",IF(C7<>"",C7,IF(AND(D7<>"",D7<=180),"Short","Long"))) | R7: =IF(OR(A7="",D7=""),"",D7/60) | S7: =IF(OR(A7="",B7=""),"",IF(AND(B7>=DATE(2026,4,1),B7<=DATE(2026,6,30)),"Yes","No")) | T7: =IF(OR(A7="",B7=""),"",CHOOSE(WEEKDAY(B7),"Sun","Mon","Tue","Wed","Thu","Fri","Sat")) | U7: =IF(OR(Q7<>"Long",D7=""),"",IF(D7<480,"Under 8 min",IF(D7<900,"8–15 min",IF(D7<1500,"15–25 min","25+ min")))) | V7: =IF(OR(A7="",N(E7)=0),"",(N(K7)+N(L7))/E7*100) | W7: =IF(OR(A7="",N(E7)=0),"",N(L7)/E7*1000) | X7: =IF(A7="","",N(N7)-N(O7)) | Y7: =IF(OR(A7="",N(E7)=0),"",X7/E7*1000) | Z7: =IF(OR(A7="",G7=""),"",IF(Q7="Short","n/a (Short)",IF(G7>=Benchmarks!$E$5,"Elite",IF(G7>=Benchmarks!$D$5,"Strong",IF(G7>=Benchmarks!$C$5,"Average","Needs work"))))) | AA7: =IF(OR(A7="",I7=""),"",IF(Q7="Short",IF(I7>=Benchmarks!$E$7,"Elite",IF(I7>=Benchmarks!$D$7,"Strong",IF(I7>=Benchmarks!$C$7,"Average","Needs work"))),IF(I7>=Benchmarks!$E$6,"Elite",IF(I7>=Benchmarks!$D$6,"Strong",IF(I7>=Benchmarks!$C$6,"Average","Needs work"))))) | AB7: =IF(V7="","",IF(V7>=Benchmarks!$E$8,"Elite",IF(V7>=Benchmarks!$D$8,"Strong",IF(V7>=Benchmarks!$C$8,"Average","Needs work")))) | AC7: =IF(COUNT(AG7:AI7)=0,"",AVERAGE(AG7:AI7)) | AD7: =IF(A7="","",IF(Q7="Short",IF(AH7="","Add % viewed to diagnose",IF(AND(AH7>=3,N(AI7)>=3),"Winner Short — expand it into a long-form video",IF(AH7<=1,"Hook problem — viewers swipe away in the first seconds",IF(AI7=1,"Watched but no reaction — end on a question or opinion","Solid Short — keep iterating")))),IF(OR(AG7="",AH7=""),"Add CTR & % viewed to diagnose",IF(AND(AG7>=3,AH7>=3),"WINNER — make a sequel, series or Shorts from it",IF(AND(AG7>=3,AH7<=2),"Click but leave — intro too slow or title over-promises",IF(AND(AG7<=2,AH7>=3),"Great video, weak packaging — A/B test title + thumbnail",IF(AND(AG7=1,AH7=1),"Topic miss — don't repeat this angle","Average — sharpen the hook and the title"))))))) | AE7: =IF(OR(A7="",N(E7)=0),"",Q7&"-"&(COUNTIFS($Q$5:$Q$204,Q7,$E$5:$E$204,">"&E7)+COUNTIFS($Q$5:Q7,Q7,$E$5:E7,E7))) | AF7: =IF(AND(Q7="Long",N(F7)>=Benchmarks!$C$15,G7<>""),G7,"") | AG7: =IF(Z7="Elite",4,IF(Z7="Strong",3,IF(Z7="Average",2,IF(Z7="Needs work",1,"")))) | AH7: =IF(AA7="Elite",4,IF(AA7="Strong",3,IF(AA7="Average",2,IF(AA7="Needs work",1,"")))) | AI7: =IF(AB7="Elite",4,IF(AB7="Strong",3,IF(AB7="Average",2,IF(AB7="Needs work",1,""))))
Q8: =IF(A8="","",IF(C8<>"",C8,IF(AND(D8<>"",D8<=180),"Short","Long"))) | R8: =IF(OR(A8="",D8=""),"",D8/60) | S8: =IF(OR(A8="",B8=""),"",IF(AND(B8>=DATE(2026,4,1),B8<=DATE(2026,6,30)),"Yes","No")) | T8: =IF(OR(A8="",B8=""),"",CHOOSE(WEEKDAY(B8),"Sun","Mon","Tue","Wed","Thu","Fri","Sat")) | U8: =IF(OR(Q8<>"Long",D8=""),"",IF(D8<480,"Under 8 min",IF(D8<900,"8–15 min",IF(D8<1500,"15–25 min","25+ min")))) | V8: =IF(OR(A8="",N(E8)=0),"",(N(K8)+N(L8))/E8*100) | W8: =IF(OR(A8="",N(E8)=0),"",N(L8)/E8*1000) | X8: =IF(A8="","",N(N8)-N(O8)) | Y8: =IF(OR(A8="",N(E8)=0),"",X8/E8*1000) | Z8: =IF(OR(A8="",G8=""),"",IF(Q8="Short","n/a (Short)",IF(G8>=Benchmarks!$E$5,"Elite",IF(G8>=Benchmarks!$D$5,"Strong",IF(G8>=Benchmarks!$C$5,"Average","Needs work"))))) | AA8: =IF(OR(A8="",I8=""),"",IF(Q8="Short",IF(I8>=Benchmarks!$E$7,"Elite",IF(I8>=Benchmarks!$D$7,"Strong",IF(I8>=Benchmarks!$C$7,"Average","Needs work"))),IF(I8>=Benchmarks!$E$6,"Elite",IF(I8>=Benchmarks!$D$6,"Strong",IF(I8>=Benchmarks!$C$6,"Average","Needs work"))))) | AB8: =IF(V8="","",IF(V8>=Benchmarks!$E$8,"Elite",IF(V8>=Benchmarks!$D$8,"Strong",IF(V8>=Benchmarks!$C$8,"Average","Needs work")))) | AC8: =IF(COUNT(AG8:AI8)=0,"",AVERAGE(AG8:AI8)) | AD8: =IF(A8="","",IF(Q8="Short",IF(AH8="","Add % viewed to diagnose",IF(AND(AH8>=3,N(AI8)>=3),"Winner Short — expand it into a long-form video",IF(AH8<=1,"Hook problem — viewers swipe away in the first seconds",IF(AI8=1,"Watched but no reaction — end on a question or opinion","Solid Short — keep iterating")))),IF(OR(AG8="",AH8=""),"Add CTR & % viewed to diagnose",IF(AND(AG8>=3,AH8>=3),"WINNER — make a sequel, series or Shorts from it",IF(AND(AG8>=3,AH8<=2),"Click but leave — intro too slow or title over-promises",IF(AND(AG8<=2,AH8>=3),"Great video, weak packaging — A/B test title + thumbnail",IF(AND(AG8=1,AH8=1),"Topic miss — don't repeat this angle","Average — sharpen the hook and the title"))))))) | AE8: =IF(OR(A8="",N(E8)=0),"",Q8&"-"&(COUNTIFS($Q$5:$Q$204,Q8,$E$5:$E$204,">"&E8)+COUNTIFS($Q$5:Q8,Q8,$E$5:E8,E8))) | AF8: =IF(AND(Q8="Long",N(F8)>=Benchmarks!$C$15,G8<>""),G8,"") | AG8: =IF(Z8="Elite",4,IF(Z8="Strong",3,IF(Z8="Average",2,IF(Z8="Needs work",1,"")))) | AH8: =IF(AA8="Elite",4,IF(AA8="Strong",3,IF(AA8="Average",2,IF(AA8="Needs work",1,"")))) | AI8: =IF(AB8="Elite",4,IF(AB8="Strong",3,IF(AB8="Average",2,IF(AB8="Needs work",1,""))))
Q9: =IF(A9="","",IF(C9<>"",C9,IF(AND(D9<>"",D9<=180),"Short","Long"))) | R9: =IF(OR(A9="",D9=""),"",D9/60) | S9: =IF(OR(A9="",B9=""),"",IF(AND(B9>=DATE(2026,4,1),B9<=DATE(2026,6,30)),"Yes","No")) | T9: =IF(OR(A9="",B9=""),"",CHOOSE(WEEKDAY(B9),"Sun","Mon","Tue","Wed","Thu","Fri","Sat")) | U9: =IF(OR(Q9<>"Long",D9=""),"",IF(D9<480,"Under 8 min",IF(D9<900,"8–15 min",IF(D9<1500,"15–25 min","25+ min")))) | V9: =IF(OR(A9="",N(E9)=0),"",(N(K9)+N(L9))/E9*100) | W9: =IF(OR(A9="",N(E9)=0),"",N(L9)/E9*1000) | X9: =IF(A9="","",N(N9)-N(O9)) | Y9: =IF(OR(A9="",N(E9)=0),"",X9/E9*1000) | Z9: =IF(OR(A9="",G9=""),"",IF(Q9="Short","n/a (Short)",IF(G9>=Benchmarks!$E$5,"Elite",IF(G9>=Benchmarks!$D$5,"Strong",IF(G9>=Benchmarks!$C$5,"Average","Needs work"))))) | AA9: =IF(OR(A9="",I9=""),"",IF(Q9="Short",IF(I9>=Benchmarks!$E$7,"Elite",IF(I9>=Benchmarks!$D$7,"Strong",IF(I9>=Benchmarks!$C$7,"Average","Needs work"))),IF(I9>=Benchmarks!$E$6,"Elite",IF(I9>=Benchmarks!$D$6,"Strong",IF(I9>=Benchmarks!$C$6,"Average","Needs work"))))) | AB9: =IF(V9="","",IF(V9>=Benchmarks!$E$8,"Elite",IF(V9>=Benchmarks!$D$8,"Strong",IF(V9>=Benchmarks!$C$8,"Average","Needs work")))) | AC9: =IF(COUNT(AG9:AI9)=0,"",AVERAGE(AG9:AI9)) | AD9: =IF(A9="","",IF(Q9="Short",IF(AH9="","Add % viewed to diagnose",IF(AND(AH9>=3,N(AI9)>=3),"Winner Short — expand it into a long-form video",IF(AH9<=1,"Hook problem — viewers swipe away in the first seconds",IF(AI9=1,"Watched but no reaction — end on a question or opinion","Solid Short — keep iterating")))),IF(OR(AG9="",AH9=""),"Add CTR & % viewed to diagnose",IF(AND(AG9>=3,AH9>=3),"WINNER — make a sequel, series or Shorts from it",IF(AND(AG9>=3,AH9<=2),"Click but leave — intro too slow or title over-promises",IF(AND(AG9<=2,AH9>=3),"Great video, weak packaging — A/B test title + thumbnail",IF(AND(AG9=1,AH9=1),"Topic miss — don't repeat this angle","Average — sharpen the hook and the title"))))))) | AE9: =IF(OR(A9="",N(E9)=0),"",Q9&"-"&(COUNTIFS($Q$5:$Q$204,Q9,$E$5:$E$204,">"&E9)+COUNTIFS($Q$5:Q9,Q9,$E$5:E9,E9))) | AF9: =IF(AND(Q9="Long",N(F9)>=Benchmarks!$C$15,G9<>""),G9,"") | AG9: =IF(Z9="Elite",4,IF(Z9="Strong",3,IF(Z9="Average",2,IF(Z9="Needs work",1,"")))) | AH9: =IF(AA9="Elite",4,IF(AA9="Strong",3,IF(AA9="Average",2,IF(AA9="Needs work",1,"")))) | AI9: =IF(AB9="Elite",4,IF(AB9="Strong",3,IF(AB9="Average",2,IF(AB9="Needs work",1,""))))
Q10: =IF(A10="","",IF(C10<>"",C10,IF(AND(D10<>"",D10<=180),"Short","Long"))) | R10: =IF(OR(A10="",D10=""),"",D10/60) | S10: =IF(OR(A10="",B10=""),"",IF(AND(B10>=DATE(2026,4,1),B10<=DATE(2026,6,30)),"Yes","No")) | T10: =IF(OR(A10="",B10=""),"",CHOOSE(WEEKDAY(B10),"Sun","Mon","Tue","Wed","Thu","Fri","Sat")) | U10: =IF(OR(Q10<>"Long",D10=""),"",IF(D10<480,"Under 8 min",IF(D10<900,"8–15 min",IF(D10<1500,"15–25 min","25+ min")))) | V10: =IF(OR(A10="",N(E10)=0),"",(N(K10)+N(L10))/E10*100) | W10: =IF(OR(A10="",N(E10)=0),"",N(L10)/E10*1000) | X10: =IF(A10="","",N(N10)-N(O10)) | Y10: =IF(OR(A10="",N(E10)=0),"",X10/E10*1000) | Z10: =IF(OR(A10="",G10=""),"",IF(Q10="Short","n/a (Short)",IF(G10>=Benchmarks!$E$5,"Elite",IF(G10>=Benchmarks!$D$5,"Strong",IF(G10>=Benchmarks!$C$5,"Average","Needs work"))))) | AA10: =IF(OR(A10="",I10=""),"",IF(Q10="Short",IF(I10>=Benchmarks!$E$7,"Elite",IF(I10>=Benchmarks!$D$7,"Strong",IF(I10>=Benchmarks!$C$7,"Average","Needs work"))),IF(I10>=Benchmarks!$E$6,"Elite",IF(I10>=Benchmarks!$D$6,"Strong",IF(I10>=Benchmarks!$C$6,"Average","Needs work"))))) | AB10: =IF(V10="","",IF(V10>=Benchmarks!$E$8,"Elite",IF(V10>=Benchmarks!$D$8,"Strong",IF(V10>=Benchmarks!$C$8,"Average","Needs work")))) | AC10: =IF(COUNT(AG10:AI10)=0,"",AVERAGE(AG10:AI10)) | AD10: =IF(A10="","",IF(Q10="Short",IF(AH10="","Add % viewed to diagnose",IF(AND(AH10>=3,N(AI10)>=3),"Winner Short — expand it into a long-form video",IF(AH10<=1,"Hook problem — viewers swipe away in the first seconds",IF(AI10=1,"Watched but no reaction — end on a question or opinion","Solid Short — keep iterating")))),IF(OR(AG10="",AH10=""),"Add CTR & % viewed to diagnose",IF(AND(AG10>=3,AH10>=3),"WINNER — make a sequel, series or Shorts from it",IF(AND(AG10>=3,AH10<=2),"Click but leave — intro too slow or title over-promises",IF(AND(AG10<=2,AH10>=3),"Great video, weak packaging — A/B test title + thumbnail",IF(AND(AG10=1,AH10=1),"Topic miss — don't repeat this angle","Average — sharpen the hook and the title"))))))) | AE10: =IF(OR(A10="",N(E10)=0),"",Q10&"-"&(COUNTIFS($Q$5:$Q$204,Q10,$E$5:$E$204,">"&E10)+COUNTIFS($Q$5:Q10,Q10,$E$5:E10,E10))) | AF10: =IF(AND(Q10="Long",N(F10)>=Benchmarks!$C$15,G10<>""),G10,"") | AG10: =IF(Z10="Elite",4,IF(Z10="Strong",3,IF(Z10="Average",2,IF(Z10="Needs work",1,"")))) | AH10: =IF(AA10="Elite",4,IF(AA10="Strong",3,IF(AA10="Average",2,IF(AA10="Needs work",1,"")))) | AI10: =IF(AB10="Elite",4,IF(AB10="Strong",3,IF(AB10="Average",2,IF(AB10="Needs work",1,""))))
Q11: =IF(A11="","",IF(C11<>"",C11,IF(AND(D11<>"",D11<=180),"Short","Long"))) | R11: =IF(OR(A11="",D11=""),"",D11/60) | S11: =IF(OR(A11="",B11=""),"",IF(AND(B11>=DATE(2026,4,1),B11<=DATE(2026,6,30)),"Yes","No")) | T11: =IF(OR(A11="",B11=""),"",CHOOSE(WEEKDAY(B11),"Sun","Mon","Tue","Wed","Thu","Fri","Sat")) | U11: =IF(OR(Q11<>"Long",D11=""),"",IF(D11<480,"Under 8 min",IF(D11<900,"8–15 min",IF(D11<1500,"15–25 min","25+ min")))) | V11: =IF(OR(A11="",N(E11)=0),"",(N(K11)+N(L11))/E11*100) | W11: =IF(OR(A11="",N(E11)=0),"",N(L11)/E11*1000) | X11: =IF(A11="","",N(N11)-N(O11)) | Y11: =IF(OR(A11="",N(E11)=0),"",X11/E11*1000) | Z11: =IF(OR(A11="",G11=""),"",IF(Q11="Short","n/a (Short)",IF(G11>=Benchmarks!$E$5,"Elite",IF(G11>=Benchmarks!$D$5,"Strong",IF(G11>=Benchmarks!$C$5,"Average","Needs work"))))) | AA11: =IF(OR(A11="",I11=""),"",IF(Q11="Short",IF(I11>=Benchmarks!$E$7,"Elite",IF(I11>=Benchmarks!$D$7,"Strong",IF(I11>=Benchmarks!$C$7,"Average","Needs work"))),IF(I11>=Benchmarks!$E$6,"Elite",IF(I11>=Benchmarks!$D$6,"Strong",IF(I11>=Benchmarks!$C$6,"Average","Needs work"))))) | AB11: =IF(V11="","",IF(V11>=Benchmarks!$E$8,"Elite",IF(V11>=Benchmarks!$D$8,"Strong",IF(V11>=Benchmarks!$C$8,"Average","Needs work")))) | AC11: =IF(COUNT(AG11:AI11)=0,"",AVERAGE(AG11:AI11)) | AD11: =IF(A11="","",IF(Q11="Short",IF(AH11="","Add % viewed to diagnose",IF(AND(AH11>=3,N(AI11)>=3),"Winner Short — expand it into a long-form video",IF(AH11<=1,"Hook problem — viewers swipe away in the first seconds",IF(AI11=1,"Watched but no reaction — end on a question or opinion","Solid Short — keep iterating")))),IF(OR(AG11="",AH11=""),"Add CTR & % viewed to diagnose",IF(AND(AG11>=3,AH11>=3),"WINNER — make a sequel, series or Shorts from it",IF(AND(AG11>=3,AH11<=2),"Click but leave — intro too slow or title over-promises",IF(AND(AG11<=2,AH11>=3),"Great video, weak packaging — A/B test title + thumbnail",IF(AND(AG11=1,AH11=1),"Topic miss — don't repeat this angle","Average — sharpen the hook and the title"))))))) | AE11: =IF(OR(A11="",N(E11)=0),"",Q11&"-"&(COUNTIFS($Q$5:$Q$204,Q11,$E$5:$E$204,">"&E11)+COUNTIFS($Q$5:Q11,Q11,$E$5:E11,E11))) | AF11: =IF(AND(Q11="Long",N(F11)>=Benchmarks!$C$15,G11<>""),G11,"") | AG11: =IF(Z11="Elite",4,IF(Z11="Strong",3,IF(Z11="Average",2,IF(Z11="Needs work",1,"")))) | AH11: =IF(AA11="Elite",4,IF(AA11="Strong",3,IF(AA11="Average",2,IF(AA11="Needs work",1,"")))) | AI11: =IF(AB11="Elite",4,IF(AB11="Strong",3,IF(AB11="Average",2,IF(AB11="Needs work",1,""))))
Q12: =IF(A12="","",IF(C12<>"",C12,IF(AND(D12<>"",D12<=180),"Short","Long"))) | R12: =IF(OR(A12="",D12=""),"",D12/60) | S12: =IF(OR(A12="",B12=""),"",IF(AND(B12>=DATE(2026,4,1),B12<=DATE(2026,6,30)),"Yes","No")) | T12: =IF(OR(A12="",B12=""),"",CHOOSE(WEEKDAY(B12),"Sun","Mon","Tue","Wed","Thu","Fri","Sat")) | U12: =IF(OR(Q12<>"Long",D12=""),"",IF(D12<480,"Under 8 min",IF(D12<900,"8–15 min",IF(D12<1500,"15–25 min","25+ min")))) | V12: =IF(OR(A12="",N(E12)=0),"",(N(K12)+N(L12))/E12*100) | W12: =IF(OR(A12="",N(E12)=0),"",N(L12)/E12*1000) | X12: =IF(A12="","",N(N12)-N(O12)) | Y12: =IF(OR(A12="",N(E12)=0),"",X12/E12*1000) | Z12: =IF(OR(A12="",G12=""),"",IF(Q12="Short","n/a (Short)",IF(G12>=Benchmarks!$E$5,"Elite",IF(G12>=Benchmarks!$D$5,"Strong",IF(G12>=Benchmarks!$C$5,"Average","Needs work"))))) | AA12: =IF(OR(A12="",I12=""),"",IF(Q12="Short",IF(I12>=Benchmarks!$E$7,"Elite",IF(I12>=Benchmarks!$D$7,"Strong",IF(I12>=Benchmarks!$C$7,"Average","Needs work"))),IF(I12>=Benchmarks!$E$6,"Elite",IF(I12>=Benchmarks!$D$6,"Strong",IF(I12>=Benchmarks!$C$6,"Average","Needs work"))))) | AB12: =IF(V12="","",IF(V12>=Benchmarks!$E$8,"Elite",IF(V12>=Benchmarks!$D$8,"Strong",IF(V12>=Benchmarks!$C$8,"Average","Needs work")))) | AC12: =IF(COUNT(AG12:AI12)=0,"",AVERAGE(AG12:AI12)) | AD12: =IF(A12="","",IF(Q12="Short",IF(AH12="","Add % viewed to diagnose",IF(AND(AH12>=3,N(AI12)>=3),"Winner Short — expand it into a long-form video",IF(AH12<=1,"Hook problem — viewers swipe away in the first seconds",IF(AI12=1,"Watched but no reaction — end on a question or opinion","Solid Short — keep iterating")))),IF(OR(AG12="",AH12=""),"Add CTR & % viewed to diagnose",IF(AND(AG12>=3,AH12>=3),"WINNER — make a sequel, series or Shorts from it",IF(AND(AG12>=3,AH12<=2),"Click but leave — intro too slow or title over-promises",IF(AND(AG12<=2,AH12>=3),"Great video, weak packaging — A/B test title + thumbnail",IF(AND(AG12=1,AH12=1),"Topic miss — don't repeat this angle","Average — sharpen the hook and the title"))))))) | AE12: =IF(OR(A12="",N(E12)=0),"",Q12&"-"&(COUNTIFS($Q$5:$Q$204,Q12,$E$5:$E$204,">"&E12)+COUNTIFS($Q$5:Q12,Q12,$E$5:E12,E12))) | AF12: =IF(AND(Q12="Long",N(F12)>=Benchmarks!$C$15,G12<>""),G12,"") | AG12: =IF(Z12="Elite",4,IF(Z12="Strong",3,IF(Z12="Average",2,IF(Z12="Needs work",1,"")))) | AH12: =IF(AA12="Elite",4,IF(AA12="Strong",3,IF(AA12="Average",2,IF(AA12="Needs work",1,"")))) | AI12: =IF(AB12="Elite",4,IF(AB12="Strong",3,IF(AB12="Average",2,IF(AB12="Needs work",1,""))))
Q13: =IF(A13="","",IF(C13<>"",C13,IF(AND(D13<>"",D13<=180),"Short","Long"))) | R13: =IF(OR(A13="",D13=""),"",D13/60) | S13: =IF(OR(A13="",B13=""),"",IF(AND(B13>=DATE(2026,4,1),B13<=DATE(2026,6,30)),"Yes","No")) | T13: =IF(OR(A13="",B13=""),"",CHOOSE(WEEKDAY(B13),"Sun","Mon","Tue","Wed","Thu","Fri","Sat")) | U13: =IF(OR(Q13<>"Long",D13=""),"",IF(D13<480,"Under 8 min",IF(D13<900,"8–15 min",IF(D13<1500,"15–25 min","25+ min")))) | V13: =IF(OR(A13="",N(E13)=0),"",(N(K13)+N(L13))/E13*100) | W13: =IF(OR(A13="",N(E13)=0),"",N(L13)/E13*1000) | X13: =IF(A13="","",N(N13)-N(O13)) | Y13: =IF(OR(A13="",N(E13)=0),"",X13/E13*1000) | Z13: =IF(OR(A13="",G13=""),"",IF(Q13="Short","n/a (Short)",IF(G13>=Benchmarks!$E$5,"Elite",IF(G13>=Benchmarks!$D$5,"Strong",IF(G13>=Benchmarks!$C$5,"Average","Needs work"))))) | AA13: =IF(OR(A13="",I13=""),"",IF(Q13="Short",IF(I13>=Benchmarks!$E$7,"Elite",IF(I13>=Benchmarks!$D$7,"Strong",IF(I13>=Benchmarks!$C$7,"Average","Needs work"))),IF(I13>=Benchmarks!$E$6,"Elite",IF(I13>=Benchmarks!$D$6,"Strong",IF(I13>=Benchmarks!$C$6,"Average","Needs work"))))) | AB13: =IF(V13="","",IF(V13>=Benchmarks!$E$8,"Elite",IF(V13>=Benchmarks!$D$8,"Strong",IF(V13>=Benchmarks!$C$8,"Average","Needs work")))) | AC13: =IF(COUNT(AG13:AI13)=0,"",AVERAGE(AG13:AI13)) | AD13: =IF(A13="","",IF(Q13="Short",IF(AH13="","Add % viewed to diagnose",IF(AND(AH13>=3,N(AI13)>=3),"Winner Short — expand it into a long-form video",IF(AH13<=1,"Hook problem — viewers swipe away in the first seconds",IF(AI13=1,"Watched but no reaction — end on a question or opinion","Solid Short — keep iterating")))),IF(OR(AG13="",AH13=""),"Add CTR & % viewed to diagnose",IF(AND(AG13>=3,AH13>=3),"WINNER — make a sequel, series or Shorts from it",IF(AND(AG13>=3,AH13<=2),"Click but leave — intro too slow or title over-promises",IF(AND(AG13<=2,AH13>=3),"Great video, weak packaging — A/B test title + thumbnail",IF(AND(AG13=1,AH13=1),"Topic miss — don't repeat this angle","Average — sharpen the hook and the title"))))))) | AE13: =IF(OR(A13="",N(E13)=0),"",Q13&"-"&(COUNTIFS($Q$5:$Q$204,Q13,$E$5:$E$204,">"&E13)+COUNTIFS($Q$5:Q13,Q13,$E$5:E13,E13))) | AF13: =IF(AND(Q13="Long",N(F13)>=Benchmarks!$C$15,G13<>""),G13,"") | AG13: =IF(Z13="Elite",4,IF(Z13="Strong",3,IF(Z13="Average",2,IF(Z13="Needs work",1,"")))) | AH13: =IF(AA13="Elite",4,IF(AA13="Strong",3,IF(AA13="Average",2,IF(AA13="Needs work",1,"")))) | AI13: =IF(AB13="Elite",4,IF(AB13="Strong",3,IF(AB13="Average",2,IF(AB13="Needs work",1,""))))
Q14: =IF(A14="","",IF(C14<>"",C14,IF(AND(D14<>"",D14<=180),"Short","Long"))) | R14: =IF(OR(A14="",D14=""),"",D14/60) | S14: =IF(OR(A14="",B14=""),"",IF(AND(B14>=DATE(2026,4,1),B14<=DATE(2026,6,30)),"Yes","No")) | T14: =IF(OR(A14="",B14=""),"",CHOOSE(WEEKDAY(B14),"Sun","Mon","Tue","Wed","Thu","Fri","Sat")) | U14: =IF(OR(Q14<>"Long",D14=""),"",IF(D14<480,"Under 8 min",IF(D14<900,"8–15 min",IF(D14<1500,"15–25 min","25+ min")))) | V14: =IF(OR(A14="",N(E14)=0),"",(N(K14)+N(L14))/E14*100) | W14: =IF(OR(A14="",N(E14)=0),"",N(L14)/E14*1000) | X14: =IF(A14="","",N(N14)-N(O14)) | Y14: =IF(OR(A14="",N(E14)=0),"",X14/E14*1000) | Z14: =IF(OR(A14="",G14=""),"",IF(Q14="Short","n/a (Short)",IF(G14>=Benchmarks!$E$5,"Elite",IF(G14>=Benchmarks!$D$5,"Strong",IF(G14>=Benchmarks!$C$5,"Average","Needs work"))))) | AA14: =IF(OR(A14="",I14=""),"",IF(Q14="Short",IF(I14>=Benchmarks!$E$7,"Elite",IF(I14>=Benchmarks!$D$7,"Strong",IF(I14>=Benchmarks!$C$7,"Average","Needs work"))),IF(I14>=Benchmarks!$E$6,"Elite",IF(I14>=Benchmarks!$D$6,"Strong",IF(I14>=Benchmarks!$C$6,"Average","Needs work"))))) | AB14: =IF(V14="","",IF(V14>=Benchmarks!$E$8,"Elite",IF(V14>=Benchmarks!$D$8,"Strong",IF(V14>=Benchmarks!$C$8,"Average","Needs work")))) | AC14: =IF(COUNT(AG14:AI14)=0,"",AVERAGE(AG14:AI14)) | AD14: =IF(A14="","",IF(Q14="Short",IF(AH14="","Add % viewed to diagnose",IF(AND(AH14>=3,N(AI14)>=3),"Winner Short — expand it into a long-form video",IF(AH14<=1,"Hook problem — viewers swipe away in the first seconds",IF(AI14=1,"Watched but no reaction — end on a question or opinion","Solid Short — keep iterating")))),IF(OR(AG14="",AH14=""),"Add CTR & % viewed to diagnose",IF(AND(AG14>=3,AH14>=3),"WINNER — make a sequel, series or Shorts from it",IF(AND(AG14>=3,AH14<=2),"Click but leave — intro too slow or title over-promises",IF(AND(AG14<=2,AH14>=3),"Great video, weak packaging — A/B test title + thumbnail",IF(AND(AG14=1,AH14=1),"Topic miss — don't repeat this angle","Average — sharpen the hook and the title"))))))) | AE14: =IF(OR(A14="",N(E14)=0),"",Q14&"-"&(COUNTIFS($Q$5:$Q$204,Q14,$E$5:$E$204,">"&E14)+COUNTIFS($Q$5:Q14,Q14,$E$5:E14,E14))) | AF14: =IF(AND(Q14="Long",N(F14)>=Benchmarks!$C$15,G14<>""),G14,"") | AG14: =IF(Z14="Elite",4,IF(Z14="Strong",3,IF(Z14="Average",2,IF(Z14="Needs work",1,"")))) | AH14: =IF(AA14="Elite",4,IF(AA14="Strong",3,IF(AA14="Average",2,IF(AA14="Needs work",1,"")))) | AI14: =IF(AB14="Elite",4,IF(AB14="Strong",3,IF(AB14="Average",2,IF(AB14="Needs work",1,""))))
Q15: =IF(A15="","",IF(C15<>"",C15,IF(AND(D15<>"",D15<=180),"Short","Long"))) | R15: =IF(OR(A15="",D15=""),"",D15/60) | S15: =IF(OR(A15="",B15=""),"",IF(AND(B15>=DATE(2026,4,1),B15<=DATE(2026,6,30)),"Yes","No")) | T15: =IF(OR(A15="",B15=""),"",CHOOSE(WEEKDAY(B15),"Sun","Mon","Tue","Wed","Thu","Fri","Sat")) | U15: =IF(OR(Q15<>"Long",D15=""),"",IF(D15<480,"Under 8 min",IF(D15<900,"8–15 min",IF(D15<1500,"15–25 min","25+ min")))) | V15: =IF(OR(A15="",N(E15)=0),"",(N(K15)+N(L15))/E15*100) | W15: =IF(OR(A15="",N(E15)=0),"",N(L15)/E15*1000) | X15: =IF(A15="","",N(N15)-N(O15)) | Y15: =IF(OR(A15="",N(E15)=0),"",X15/E15*1000) | Z15: =IF(OR(A15="",G15=""),"",IF(Q15="Short","n/a (Short)",IF(G15>=Benchmarks!$E$5,"Elite",IF(G15>=Benchmarks!$D$5,"Strong",IF(G15>=Benchmarks!$C$5,"Average","Needs work"))))) | AA15: =IF(OR(A15="",I15=""),"",IF(Q15="Short",IF(I15>=Benchmarks!$E$7,"Elite",IF(I15>=Benchmarks!$D$7,"Strong",IF(I15>=Benchmarks!$C$7,"Average","Needs work"))),IF(I15>=Benchmarks!$E$6,"Elite",IF(I15>=Benchmarks!$D$6,"Strong",IF(I15>=Benchmarks!$C$6,"Average","Needs work"))))) | AB15: =IF(V15="","",IF(V15>=Benchmarks!$E$8,"Elite",IF(V15>=Benchmarks!$D$8,"Strong",IF(V15>=Benchmarks!$C$8,"Average","Needs work")))) | AC15: =IF(COUNT(AG15:AI15)=0,"",AVERAGE(AG15:AI15)) | AD15: =IF(A15="","",IF(Q15="Short",IF(AH15="","Add % viewed to diagnose",IF(AND(AH15>=3,N(AI15)>=3),"Winner Short — expand it into a long-form video",IF(AH15<=1,"Hook problem — viewers swipe away in the first seconds",IF(AI15=1,"Watched but no reaction — end on a question or opinion","Solid Short — keep iterating")))),IF(OR(AG15="",AH15=""),"Add CTR & % viewed to diagnose",IF(AND(AG15>=3,AH15>=3),"WINNER — make a sequel, series or Shorts from it",IF(AND(AG15>=3,AH15<=2),"Click but leave — intro too slow or title over-promises",IF(AND(AG15<=2,AH15>=3),"Great video, weak packaging — A/B test title + thumbnail",IF(AND(AG15=1,AH15=1),"Topic miss — don't repeat this angle","Average — sharpen the hook and the title"))))))) | AE15: =IF(OR(A15="",N(E15)=0),"",Q15&"-"&(COUNTIFS($Q$5:$Q$204,Q15,$E$5:$E$204,">"&E15)+COUNTIFS($Q$5:Q15,Q15,$E$5:E15,E15))) | AF15: =IF(AND(Q15="Long",N(F15)>=Benchmarks!$C$15,G15<>""),G15,"") | AG15: =IF(Z15="Elite",4,IF(Z15="Strong",3,IF(Z15="Average",2,IF(Z15="Needs work",1,"")))) | AH15: =IF(AA15="Elite",4,IF(AA15="Strong",3,IF(AA15="Average",2,IF(AA15="Needs work",1,"")))) | AI15: =IF(AB15="Elite",4,IF(AB15="Strong",3,IF(AB15="Average",2,IF(AB15="Needs work",1,""))))
Q16: =IF(A16="","",IF(C16<>"",C16,IF(AND(D16<>"",D16<=180),"Short","Long"))) | R16: =IF(OR(A16="",D16=""),"",D16/60) | S16: =IF(OR(A16="",B16=""),"",IF(AND(B16>=DATE(2026,4,1),B16<=DATE(2026,6,30)),"Yes","No")) | T16: =IF(OR(A16="",B16=""),"",CHOOSE(WEEKDAY(B16),"Sun","Mon","Tue","Wed","Thu","Fri","Sat")) | U16: =IF(OR(Q16<>"Long",D16=""),"",IF(D16<480,"Under 8 min",IF(D16<900,"8–15 min",IF(D16<1500,"15–25 min","25+ min")))) | V16: =IF(OR(A16="",N(E16)=0),"",(N(K16)+N(L16))/E16*100) | W16: =IF(OR(A16="",N(E16)=0),"",N(L16)/E16*1000) | X16: =IF(A16="","",N(N16)-N(O16)) | Y16: =IF(OR(A16="",N(E16)=0),"",X16/E16*1000) | Z16: =IF(OR(A16="",G16=""),"",IF(Q16="Short","n/a (Short)",IF(G16>=Benchmarks!$E$5,"Elite",IF(G16>=Benchmarks!$D$5,"Strong",IF(G16>=Benchmarks!$C$5,"Average","Needs work"))))) | AA16: =IF(OR(A16="",I16=""),"",IF(Q16="Short",IF(I16>=Benchmarks!$E$7,"Elite",IF(I16>=Benchmarks!$D$7,"Strong",IF(I16>=Benchmarks!$C$7,"Average","Needs work"))),IF(I16>=Benchmarks!$E$6,"Elite",IF(I16>=Benchmarks!$D$6,"Strong",IF(I16>=Benchmarks!$C$6,"Average","Needs work"))))) | AB16: =IF(V16="","",IF(V16>=Benchmarks!$E$8,"Elite",IF(V16>=Benchmarks!$D$8,"Strong",IF(V16>=Benchmarks!$C$8,"Average","Needs work")))) | AC16: =IF(COUNT(AG16:AI16)=0,"",AVERAGE(AG16:AI16)) | AD16: =IF(A16="","",IF(Q16="Short",IF(AH16="","Add % viewed to diagnose",IF(AND(AH16>=3,N(AI16)>=3),"Winner Short — expand it into a long-form video",IF(AH16<=1,"Hook problem — viewers swipe away in the first seconds",IF(AI16=1,"Watched but no reaction — end on a question or opinion","Solid Short — keep iterating")))),IF(OR(AG16="",AH16=""),"Add CTR & % viewed to diagnose",IF(AND(AG16>=3,AH16>=3),"WINNER — make a sequel, series or Shorts from it",IF(AND(AG16>=3,AH16<=2),"Click but leave — intro too slow or title over-promises",IF(AND(AG16<=2,AH16>=3),"Great video, weak packaging — A/B test title + thumbnail",IF(AND(AG16=1,AH16=1),"Topic miss — don't repeat this angle","Average — sharpen the hook and the title"))))))) | AE16: =IF(OR(A16="",N(E16)=0),"",Q16&"-"&(COUNTIFS($Q$5:$Q$204,Q16,$E$5:$E$204,">"&E16)+COUNTIFS($Q$5:Q16,Q16,$E$5:E16,E16))) | AF16: =IF(AND(Q16="Long",N(F16)>=Benchmarks!$C$15,G16<>""),G16,"") | AG16: =IF(Z16="Elite",4,IF(Z16="Strong",3,IF(Z16="Average",2,IF(Z16="Needs work",1,"")))) | AH16: =IF(AA16="Elite",4,IF(AA16="Strong",3,IF(AA16="Average",2,IF(AA16="Needs work",1,"")))) | AI16: =IF(AB16="Elite",4,IF(AB16="Strong",3,IF(AB16="Average",2,IF(AB16="Needs work",1,""))))
... Q204: =IF(A204="","",IF(C204<>"",C204,IF(AND(D204<>"",D204<=180),"Short","Long"))) | R204: =IF(OR(A204="",D204=""),"",D204/60) | S204: =IF(OR(A204="",B204=""),"",IF(AND(B204>=DATE(2026,4,1),B204<=DATE(2026,6,30)),"Yes","No")) | T204: =IF(OR(A204="",B204=""),"",CHOOSE(WEEKDAY(B204),"Sun","Mon","Tue","Wed","Thu","Fri","Sat")) | U204: =IF(OR(Q204<>"Long",D204=""),"",IF(D204<480,"Under 8 min",IF(D204<900,"8–15 min",IF(D204<1500,"15–25 min","25+ min")))) | V204: =IF(OR(A204="",N(E204)=0),"",(N(K204)+N(L204))/E204*100) | W204: =IF(OR(A204="",N(E204)=0),"",N(L204)/E204*1000) | X204: =IF(A204="","",N(N204)-N(O204)) | Y204: =IF(OR(A204="",N(E204)=0),"",X204/E204*1000) | Z204: =IF(OR(A204="",G204=""),"",IF(Q204="Short","n/a (Short)",IF(G204>=Benchmarks!$E$5,"Elite",IF(G204>=Benchmarks!$D$5,"Strong",IF(G204>=Benchmarks!$C$5,"Average","Needs work"))))) | AA204: =IF(OR(A204="",I204=""),"",IF(Q204="Short",IF(I204>=Benchmarks!$E$7,"Elite",IF(I204>=Benchmarks!$D$7,"Strong",IF(I204>=Benchmarks!$C$7,"Average","Needs work"))),IF(I204>=Benchmarks!$E$6,"Elite",IF(I204>=Benchmarks!$D$6,"Strong",IF(I204>=Benchmarks!$C$6,"Average","Needs work"))))) | AB204: =IF(V204="","",IF(V204>=Benchmarks!$E$8,"Elite",IF(V204>=Benchmarks!$D$8,"Strong",IF(V204>=Benchmarks!$C$8,"Average","Needs work")))) | AC204: =IF(COUNT(AG204:AI204)=0,"",AVERAGE(AG204:AI204)) | AD204: =IF(A204="","",IF(Q204="Short",IF(AH204="","Add % viewed to diagnose",IF(AND(AH204>=3,N(AI204)>=3),"Winner Short — expand it into a long-form video",IF(AH204<=1,"Hook problem — viewers swipe away in the first seconds",IF(AI204=1,"Watched but no reaction — end on a question or opinion","Solid Short — keep iterating")))),IF(OR(AG204="",AH204=""),"Add CTR & % viewed to diagnose",IF(AND(AG204>=3,AH204>=3),"WINNER — make a sequel, series or Shorts from it",IF(AND(AG204>=3,AH204<=2),"Click but leave — intro too slow or title over-promises",IF(AND(AG204<=2,AH204>=3),"Great video, weak packaging — A/B test title + thumbnail",IF(AND(AG204=1,AH204=1),"Topic miss — don't repeat this angle","Average — sharpen the hook and the title"))))))) | AE204: =IF(OR(A204="",N(E204)=0),"",Q204&"-"&(COUNTIFS($Q$5:$Q$204,Q204,$E$5:$E$204,">"&E204)+COUNTIFS($Q$5:Q204,Q204,$E$5:E204,E204))) | AF204: =IF(AND(Q204="Long",N(F204)>=Benchmarks!$C$15,G204<>""),G204,"") | AG204: =IF(Z204="Elite",4,IF(Z204="Strong",3,IF(Z204="Average",2,IF(Z204="Needs work",1,"")))) | AH204: =IF(AA204="Elite",4,IF(AA204="Strong",3,IF(AA204="Average",2,IF(AA204="Needs work",1,"")))) | AI204: =IF(AB204="Elite",4,IF(AB204="Strong",3,IF(AB204="Average",2,IF(AB204="Needs work",1,""))))

Sheet Monthly Trend
A1: Monthly Trend — channel totals (YouTube Studio → Analytics → Overview)
A2: Enter April, May, June (and optionally Q1 2026) channel totals in the yellow cells. Q2 totals, growth and video counts are calculated.
A4: Period | B4: Views | C4: Watch time (hours) | D4: Subscribers gained | E4: Subscribers lost | F4: Net subscribers | G4: Impressions | H4: Impressions CTR (%) | I4: Average view duration | J4: Unique viewers | K4: Estimated revenue (USD) | L4: Long-form videos published | M4: Shorts published
A5: April 2026 | F5: =IF(AND(D5="",E5=""),"",N(D5)-N(E5)) | L5: =COUNTIFS('Video Data'!$B$5:$B$204,">="&DATE(2026,4,1),'Video Data'!$B$5:$B$204,"<"&DATE(2026,5,1),'Video Data'!$Q$5:$Q$204,"<>Short") -> 0 | M5: =COUNTIFS('Video Data'!$B$5:$B$204,">="&DATE(2026,4,1),'Video Data'!$B$5:$B$204,"<"&DATE(2026,5,1),'Video Data'!$Q$5:$Q$204,"Short") -> 0
A6: May 2026 | F6: =IF(AND(D6="",E6=""),"",N(D6)-N(E6)) | L6: =COUNTIFS('Video Data'!$B$5:$B$204,">="&DATE(2026,5,1),'Video Data'!$B$5:$B$204,"<"&DATE(2026,6,1),'Video Data'!$Q$5:$Q$204,"<>Short") -> 0 | M6: =COUNTIFS('Video Data'!$B$5:$B$204,">="&DATE(2026,5,1),'Video Data'!$B$5:$B$204,"<"&DATE(2026,6,1),'Video Data'!$Q$5:$Q$204,"Short") -> 0
A7: June 2026 | F7: =IF(AND(D7="",E7=""),"",N(D7)-N(E7)) | L7: =COUNTIFS('Video Data'!$B$5:$B$204,">="&DATE(2026,6,1),'Video Data'!$B$5:$B$204,"<"&DATE(2026,7,1),'Video Data'!$Q$5:$Q$204,"<>Short") -> 0 | M7: =COUNTIFS('Video Data'!$B$5:$B$204,">="&DATE(2026,6,1),'Video Data'!$B$5:$B$204,"<"&DATE(2026,7,1),'Video Data'!$Q$5:$Q$204,"Short") -> 0
A8: Q2 2026 TOTAL | B8: =SUM(B5:B7) -> 0 | C8: =SUM(C5:C7) -> 0 | D8: =SUM(D5:D7) -> 0 | E8: =SUM(E5:E7) -> 0 | F8: =SUM(F5:F7) -> 0 | G8: =SUM(G5:G7) -> 0 | H8: =IF(SUM(G5:G7)=0,"",SUMPRODUCT(G5:G7,H5:H7)/SUM(G5:G7)) | I8: =IF(SUMPRODUCT(B5:B7,I5:I7)=0,"",SUMPRODUCT(B5:B7,I5:I7)/SUM(B5:B7)) | J8: =SUM(J5:J7) -> 0 | K8: =SUM(K5:K7) -> 0 | L8: =SUM(L5:L7) -> 0 | M8: =SUM(M5:M7) -> 0
A9: Q1 2026 (Jan–Mar) — optional | F9: =IF(AND(D9="",E9=""),"",N(D9)-N(E9))
A10: Q2 vs Q1 change (%) | B10: =IF(OR(N(B9)=0,B8=""),"",(B8-B9)/ABS(B9)*100) | C10: =IF(OR(N(C9)=0,C8=""),"",(C8-C9)/ABS(C9)*100) | D10: =IF(OR(N(D9)=0,D8=""),"",(D8-D9)/ABS(D9)*100) | E10: =IF(OR(N(E9)=0,E8=""),"",(E8-E9)/ABS(E9)*100) | F10: =IF(OR(N(F9)=0,F8=""),"",(F8-F9)/ABS(F9)*100) | G10: =IF(OR(N(G9)=0,G8=""),"",(G8-G9)/ABS(G9)*100) | H10: =IF(OR(N(H9)=0,H8=""),"",(H8-H9)/ABS(H9)*100) | I10: =IF(OR(N(I9)=0,I8=""),"",(I8-I9)/ABS(I9)*100) | ... M10: =IF(OR(N(M9)=0,M8=""),"",(M8-M9)/ABS(M9)*100)
A12: May vs April (%) | B12: =IF(OR(N(B5)=0,B6=""),"",(B6-B5)/ABS(B5)*100) | C12: =IF(OR(N(C5)=0,C6=""),"",(C6-C5)/ABS(C5)*100) | D12: =IF(OR(N(D5)=0,D6=""),"",(D6-D5)/ABS(D5)*100) | E12: =IF(OR(N(E5)=0,E6=""),"",(E6-E5)/ABS(E5)*100) | F12: =IF(OR(N(F5)=0,F6=""),"",(F6-F5)/ABS(F5)*100) | G12: =IF(OR(N(G5)=0,G6=""),"",(G6-G5)/ABS(G5)*100) | H12: =IF(OR(N(H5)=0,H6=""),"",(H6-H5)/ABS(H5)*100) | I12: =IF(OR(N(I5)=0,I6=""),"",(I6-I5)/ABS(I5)*100) | ... M12: =IF(OR(N(M5)=0,M6=""),"",(M6-M5)/ABS(M5)*100)
A13: June vs May (%) | B13: =IF(OR(N(B6)=0,B7=""),"",(B7-B6)/ABS(B6)*100) | C13: =IF(OR(N(C6)=0,C7=""),"",(C7-C6)/ABS(C6)*100) | D13: =IF(OR(N(D6)=0,D7=""),"",(D7-D6)/ABS(D6)*100) | E13: =IF(OR(N(E6)=0,E7=""),"",(E7-E6)/ABS(E6)*100) | F13: =IF(OR(N(F6)=0,F7=""),"",(F7-F6)/ABS(F6)*100) | G13: =IF(OR(N(G6)=0,G7=""),"",(G7-G6)/ABS(G6)*100) | H13: =IF(OR(N(H6)=0,H7=""),"",(H7-H6)/ABS(H6)*100) | I13: =IF(OR(N(I6)=0,I7=""),"",(I7-I6)/ABS(I6)*100) | ... M13: =IF(OR(N(M6)=0,M7=""),"",(M7-M6)/ABS(M6)*100)
A14: June vs April (%) | B14: =IF(OR(N(B5)=0,B7=""),"",(B7-B5)/ABS(B5)*100) | C14: =IF(OR(N(C5)=0,C7=""),"",(C7-C5)/ABS(C5)*100) | D14: =IF(OR(N(D5)=0,D7=""),"",(D7-D5)/ABS(D5)*100) | E14: =IF(OR(N(E5)=0,E7=""),"",(E7-E5)/ABS(E5)*100) | F14: =IF(OR(N(F5)=0,F7=""),"",(F7-F5)/ABS(F5)*100) | G14: =IF(OR(N(G5)=0,G7=""),"",(G7-G5)/ABS(G5)*100) | H14: =IF(OR(N(H5)=0,H7=""),"",(H7-H5)/ABS(H5)*100) | I14: =IF(OR(N(I5)=0,I7=""),"",(I7-I5)/ABS(I5)*100) | ... M14: =IF(OR(N(M5)=0,M7=""),"",(M7-M5)/ABS(M5)*100)
A16: Green = growth, red = decline. Note: from Aug 24 2026 YouTube counts a view from the first frame, so compare Q3+ views with care (see Insights).

Sheet Traffic & Audience
A1: Traffic & Audience — Q2 2026
A2: Studio → Analytics → Advanced mode, Apr 1 – Jun 30 2026. Enter views per row in the yellow cells; shares and changes calculate.
A4: Traffic source | B4: Q2 views | C4: Q2 watch time (hours) | D4: Q1 views (optional) | E4: Share of views | F4: Change vs Q1 | G4: What this source tells you
A5: Browse features | E5: =IF(OR(B5="",SUM($B$5:$B$16)=0),"",B5/SUM($B$5:$B$16)*100) | F5: =IF(OR(N(D5)=0,B5=""),"",(B5-D5)/D5*100) | G5: Home feed & subscriptions. Grows when viewers are satisfied — the algorithm trusts you.
A6: Suggested videos | E6: =IF(OR(B6="",SUM($B$5:$B$16)=0),"",B6/SUM($B$5:$B$16)*100) | F6: =IF(OR(N(D6)=0,B6=""),"",(B6-D6)/D6*100) | G6: Shown next to/after other videos. Grows when you make content adjacent to bigger videos.
